Workbook

Sheet JAN
A1: DATA PELAYANAN RI RSD Dr.SOEBANDI JEMBER
A2: BULAN : JANUARI 2026 | V2: s/e | W2: v/f*100 | X2: S/L+M | Y2: ((F-V)*E)/(LM) | Z2: L+M/F
A3: NO | B3: PELAYANAN | C3: RAWAT INAP | D3: KLAS PERAWATAN | E3: PERIODE | F3: TT (T) | G3: PX AWAL | H3: PX MASUK | I3: PX PINDAHAN | J3: JUMLAH (1+2+3) | K3: PX DI PINDAHKAN | L3: PX KELUAR HIDUP | M3: PX MATI | N3: KURANG 48 JAM | O3: LEBIH 48 JAM | P3: JUMLAH (5+6+7) | Q3: LAMA DI RAWAT | R3: PX KELUAR/MASUK HR SAMA | S3: HARI PERAWATAN | T3: Px AKHIR | U3: KUNJUNGN | V3: O | W3: BOR (O/T) | X3: LOS | Y3: TOI | Z3: BTO
V4: (TT terpakai) | W4: (75%-85%) | X4: (3-12 hari) | Y4: (1-3 hr) | Z4: (30 px)
G6: 1 | H6: 2 | I6: 3 | J6: 4 | K6: 5 | L6: 6 | M6: 7 | N6: 8 | O6: 9 | P6: 10 | Q6: 11 | R6: 12 | S6: 13 | T6: 14 | V6: 15 | W6: 16 | X6: 17 | Y6: 18 | Z6: 19
A7: 1 | B7: RAWAT INAP UMUM | C7: ADENIUM | D7: III | E7: 31 | F7: 20 | G7: 22 | H7: 98 | I7: 16 | J7: 136 | K7: 7 | L7: 88 | M7: 18 | N7: 9 | O7: 9 | P7: 113 | Q7: 405 | R7: 1 | S7: 652 | T7: 23 | U7: 106 | V7: 21.032258 | W7: 105.16129 | X7: 6.1509434 | Y7: -0.30188679 | Z7: 5.3
C8: ADENIUM | E8: 31 | F8: 20 | G8: 22 | H8: 98 | I8: 16 | J8: 136 | K8: 7 | L8: 88 | M8: 18 | N8: 9 | O8: 9 | P8: 113 | Q8: 405 | R8: 1 | S8: 652 | T8: 23 | U8: 106 | V8: 21.032258 | W8: 105.16129 | X8: 6.1509434 | Y8: -0.30188679 | Z8: 5.3
A9: 2 | C9: ANTURIUM | D9: III | E9: 31 | F9: 16 | G9: 14 | H9: 90 | I9: 40 | J9: 144 | K9: 6 | L9: 106 | M9: 18 | N9: 7 | O9: 11 | P9: 130 | Q9: 438 | R9: 2 | S9: 460 | T9: 14 | U9: 124 | V9: 14.83871 | W9: 92.741935 | X9: 3.7096774 | Y9: 0.29032258 | Z9: 7.75
C10: ANTURIUM | E10: 31 | F10: 16 | G10: 14 | H10: 90 | I10: 40 | J10: 144 | K10: 6 | L10: 106 | M10: 18 | N10: 7 | O10: 11 | P10: 130 | Q10: 438 | R10: 2 | S10: 460 | T10: 14 | U10: 124 | V10: 14.83871 | W10: 92.741935 | X10: 3.7096774 | Y10: 0.29032258 | Z10: 7.75
A11: 3 | D11: II | E11: 31 | G11: 0 | H11: 0 | I11: 0 | J11: 0 | K11: 0 | L11: 0 | M11: 0 | N11: 0 | O11: 0 | P11: 0 | Q11: 0 | R11: 0 | S11: 0 | T11: 0 | U11: 0 | V11: #DIV/0! | W11: #DIV/0! | X11: #DIV/0! | Y11: #DIV/0! | Z11: #DIV/0!
C12: TULIP | D12: III | E12: 31 | F12: 12 | G12: 10 | H12: 88 | I12: 6 | J12: 104 | K12: 11 | L12: 82 | M12: 3 | N12: 2 | O12: 1 | P12: 96 | Q12: 307 | R12: 1 | S12: 299 | T12: 8 | U12: 85 | V12: 9.6451613 | W12: 80.376344 | X12: 3.5176471 | Y12: 0.85882353 | Z12: 7.0833333
C13: TULIP | E13: 31 | F13: 12 | G13: 10 | H13: 88 | I13: 6 | J13: 104 | K13: 11 | L13: 82 | M13: 3 | N13: 2 | O13: 1 | P13: 96 | Q13: 307 | R13: 1 | S13: 299 | T13: 8 | U13: 85 | V13: 9.6451613 | W13: 80.376344 | X13: 3.5176471 | Y13: 0.85882353 | Z13: 7.0833333
A14: 4 | C14: ASTER | D14: II | E14: 31 | F14: 2 | G14: 2 | H14: 13 | I14: 7 | J14: 22 | K14: 8 | L14: 13 | M14: 0 | N14: 0 | O14: 0 | P14: 21 | Q14: 40 | R14: 0 | S14: 41 | T14: 1 | U14: 13 | V14: 1.3225806 | W14: 66.129032 | X14: 3.1538462 | Y14: 1.6153846 | Z14: 6.5
C15: ASTER | D15: III | E15: 31 | F15: 17 | G15: 15 | H15: 127 | I15: 17 | J15: 159 | K15: 12 | L15: 129 | M15: 5 | N15: 4 | O15: 1 | P15: 146 | Q15: 448 | R15: 4 | S15: 449 | T15: 13 | U15: 134 | V15: 14.483871 | W15: 85.199241 | X15: 3.3507463 | Y15: 0.58208955 | Z15: 7.8823529
C16: ASTER | D16: ISOLASI | E16: 31 | F16: 5 | G16: 4 | H16: 20 | I16: 6 | J16: 30 | K16: 4 | L16: 24 | M16: 0 | N16: 0 | O16: 0 | P16: 28 | Q16: 89 | R16: 0 | S16: 86 | T16: 2 | U16: 24 | V16: 2.7741935 | W16: 55.483871 | X16: 3.5833333 | Y16: 2.875 | Z16: 4.8
C17: ASTER | E17: 31 | F17: 24 | G17: 21 | H17: 160 | I17: 30 | J17: 211 | K17: 24 | L17: 166 | M17: 5 | N17: 4 | O17: 1 | P17: 195 | Q17: 577 | R17: 4 | S17: 576 | T17: 16 | U17: 171 | V17: 18.580645 | W17: 77.419355 | X17: 3.3684211 | Y17: 0.98245614 | Z17: 7.125
C18: MELATI | D18: ATAS ISOLASI | E18: 31 | F18: 4 | G18: 0 | H18: 0 | I18: 0 | J18: 0 | K18: 0 | L18: 0 | N18: 0 | O18: 0 | P18: 0 | Q18: 0 | R18: 0 | S18: 0 | T18: 0 | U18: 0 | V18: 0 | W18: 0 | X18: #DIV/0! | Y18: #DIV/0! | Z18: 0
A19: 5 | C19: MELATI | D19: ATAS III | E19: 31 | F19: 15 | G19: 21 | H19: 136 | I19: 12 | J19: 169 | K19: 17 | L19: 111 | M19: 21 | N19: 11 | O19: 10 | P19: 149 | Q19: 504 | R19: 2 | S19: 566 | T19: 20 | U19: 132 | V19: 18.258065 | W19: 121.72043 | X19: 4.2878788 | Y19: -0.76515152 | Z19: 8.8
C20: MELATI | D20: BAWAH III | E20: 31 | F20: 12 | G20: 12 | H20: 81 | I20: 31 | J20: 124 | K20: 22 | L20: 71 | M20: 19 | N20: 11 | O20: 8 | P20: 112 | Q20: 314 | R20: 0 | S20: 367 | T20: 12 | U20: 90 | V20: 11.83871 | W20: 98.655914 | X20: 4.0777778 | Y20: 0.055555556 | Z20: 7.5
C21: MELATI | E21: 31 | F21: 31 | G21: 33 | H21: 217 | I21: 43 | J21: 293 | K21: 39 | L21: 182 | M21: 40 | N21: 22 | O21: 18 | P21: 261 | Q21: 818 | R21: 2 | S21: 933 | T21: 32 | U21: 222 | V21: 30.096774 | W21: 111.46953 | X21: 4.2027027 | Y21: -0.43243243 | Z21: 16.3
A22: 6 | C22: SERUNI | D22: III | E22: 31 | F22: 18 | G22: 18 | H22: 157 | I22: 19 | J22: 194 | K22: 10 | L22: 169 | M22: 1 | N22: 0 | O22: 1 | P22: 180 | Q22: 499 | R22: 3 | S22: 523 | T22: 14 | U22: 170 | V22: 16.870968 | W22: 93.727599 | X22: 3.0764706 | Y22: 0.20588235 | Z22: 9.4444444
C23: SERUNI | E23: 31 | F23: 18 | G23: 18 | H23: 157 | I23: 19 | J23: 194 | K23: 10 | L23: 169 | M23: 1 | N23: 0 | O23: 1 | P23: 180 | Q23: 499 | R23: 3 | S23: 523 | T23: 14 | U23: 170 | V23: 16.870968 | W23: 93.727599 | X23: 3.0764706 | Y23: 0.20588235 | Z23: 9.4444444
C24: MAWAR | D24: ISOLASI | E24: 31 | F24: 4 | G24: 0 | H24: 0 | I24: 0 | J24: 0 | K24: 0 | L24: 0 | N24: 0 | O24: 0 | P24: 0 | Q24: 0 | R24: 0 | S24: 0 | T24: 0 | U24: 0 | V24: 0 | W24: 0 | X24: #DIV/0! | Y24: #DIV/0! | Z24: 0
A25: 7 | C25: MAWAR | D25: III | E25: 31 | F25: 16 | G25: 17 | H25: 129 | I25: 9 | J25: 155 | K25: 9 | L25: 129 | M25: 3 | N25: 1 | O25: 2 | P25: 141 | Q25: 479 | R25: 0 | S25: 504 | T25: 14 | U25: 132 | V25: 16.258065 | W25: 101.6129 | X25: 3.8181818 | Y25: -0.060606061 | Z25: 8.25
C26: MAWAR | E26: 31 | F26: 20 | G26: 17 | H26: 129 | I26: 9 | J26: 155 | K26: 9 | L26: 129 | M26: 3 | N26: 1 | O26: 2 | P26: 141 | Q26: 479 | R26: 0 | S26: 504 | T26: 14 | U26: 132 | V26: 16.258065 | W26: 81.290323 | X26: 3.8181818 | Y26: 0.87878788 | Z26: 6.6
A27: 8 | C27: GARDENA | D27: III | E27: 31 | F27: 20 | G27: 17 | H27: 157 | I27: 4 | J27: 178 | K27: 8 | L27: 146 | M27: 10 | N27: 6 | O27: 4 | P27: 164 | Q27: 500 | R27: 2 | S27: 517 | T27: 14 | U27: 156 | V27: 16.677419 | W27: 83.387097 | X27: 3.3141026 | Y27: 0.66025641 | Z27: 7.8
C28: GARDENA | E28: 31 | F28: 20 | G28: 17 | H28: 157 | I28: 4 | J28: 178 | K28: 8 | L28: 146 | M28: 10 | N28: 6 | O28: 4 | P28: 164 | Q28: 500 | R28: 2 | S28: 517 | T28: 14 | U28: 156 | V28: 16.677419 | W28: 83.387097 | X28: 3.3141026 | Y28: 0.66025641 | Z28: 7.8
C29: BOGENVILE | D29: ISOLASI | E29: 31 | F29: 1 | G29: 0 | H29: 0 | I29: 0 | J29: 0 | K29: 0 | L29: 0 | N29: 0 | O29: 0 | P29: 0 | Q29: 0 | R29: 0 | S29: 0 | T29: 0 | U29: 0 | V29: 0 | W29: 0 | X29: #DIV/0! | Y29: #DIV/0! | Z29: 0
A30: 9 | C30: BOGENVILE | D30: I | E30: 31 | F30: 3 | G30: 4 | H30: 37 | I30: 5 | J30: 46 | K30: 8 | L30: 33 | M30: 3 | N30: 2 | O30: 1 | P30: 44 | Q30: 115 | R30: 1 | S30: 114 | T30: 2 | U30: 36 | V30: 3.6774194 | W30: 122.58065 | X30: 3.1666667 | Y30: -0.58333333 | Z30: 12
C31: BOGENVILE | D31: PAV | E31: 31 | F31: 8 | G31: 6 | H31: 26 | I31: 16 | J31: 48 | K31: 7 | L31: 32 | M31: 5 | N31: 2 | O31: 3 | P31: 44 | Q31: 137 | R31: 0 | S31: 131 | T31: 4 | U31: 37 | V31: 4.2258065 | W31: 52.822581 | X31: 3.5405405 | Y31: 3.1621622 | Z31: 4.625
C32: BOGENVILE | E32: 31 | F32: 12 | G32: 10 | H32: 63 | I32: 21 | J32: 94 | K32: 15 | L32: 65 | M32: 8 | N32: 4 | O32: 4 | P32: 88 | Q32: 252 | R32: 1 | S32: 245 | T32: 6 | U32: 73 | V32: 7.9032258 | W32: 65.860215 | X32: 3.3561644 | Y32: 1.739726 | Z32: 6.0833333
C33: ALAMANDA | D33: ISOLASI | E33: 31 | F33: 1 | G33: 0 | H33: 0 | I33: 0 | J33: 0 | K33: 0 | L33: 0 | N33: 0 | O33: 0 | P33: 0 | Q33: 0 | R33: 0 | S33: 0 | T33: 0 | U33: 0 | V33: 0 | W33: 0 | X33: #DIV/0! | Y33: #DIV/0! | Z33: 0
A34: 10 | C34: ALAMANDA | D34: I | E34: 31 | F34: 2 | G34: 3 | H34: 13 | I34: 2 | J34: 18 | K34: 2 | L34: 12 | M34: 1 | N34: 1 | O34: 0 | P34: 15 | Q34: 42 | R34: 0 | S34: 70 | T34: 3 | U34: 13 | V34: 2.2580645 | W34: 112.90323 | X34: 5.3846154 | Y34: -0.61538462 | Z34: 6.5
C35: ALAMANDA | D35: II | E35: 31 | F35: 4 | G35: 4 | H35: 21 | I35: 4 | J35: 29 | K35: 1 | L35: 22 | M35: 2 | N35: 2 | O35: 0 | P35: 25 | Q35: 99 | R35: 2 | S35: 108 | T35: 4 | U35: 24 | V35: 3.483871 | W35: 87.096774 | X35: 4.5 | Y35: 0.66666667 | Z35: 6
C36: ALAMANDA | D36: III | E36: 31 | F36: 12 | G36: 7 | H36: 70 | I36: 9 | J36: 86 | K36: 2 | L36: 68 | M36: 4 | N36: 3 | O36: 1 | P36: 74 | Q36: 257 | R36: 1 | S36: 306 | T36: 12 | U36: 72 | V36: 9.8709677 | W36: 82.258065 | X36: 4.25 | Y36: 0.91666667 | Z36: 6
C37: ALAMANDA | E37: 31 | F37: 19 | G37: 14 | H37: 104 | I37: 15 | J37: 133 | K37: 5 | L37: 102 | M37: 7 | N37: 6 | O37: 1 | P37: 114 | Q37: 398 | R37: 3 | S37: 484 | T37: 19 | U37: 109 | V37: 15.612903 | W37: 82.173175 | X37: 4.440367 | Y37: 0.96330275 | Z37: 5.7368421
A38: 11 | C38: CATHALIA | D38: CA ISOLASI | E38: 31 | F38: 6 | G38: 4 | H38: 47 | I38: 10 | J38: 61 | K38: 13 | L38: 37 | M38: 3 | N38: 1 | O38: 2 | P38: 53 | Q38: 115 | R38: 0 | S38: 179 | T38: 8 | U38: 40 | V38: 5.7741935 | W38: 96.236559 | X38: 4.475 | Y38: 0.175 | Z38: 6.6666667
C39: CATHALIA | D39: CATALYA ATAS | E39: 31 | F39: 8 | G39: 4 | H39: 51 | I39: 5 | J39: 60 | K39: 10 | L39: 44 | M39: 2 | N39: 0 | O39: 2 | P39: 56 | Q39: 144 | R39: 2 | S39: 120 | T39: 4 | U39: 46 | V39: 3.8709677 | W39: 48.387097 | X39: 2.6086957 | Y39: 2.7826087 | Z39: 5.75
C40: CATHALIA | D40: CATALYA BAWAH | E40: 31 | F40: 14 | G40: 8 | H40: 75 | I40: 9 | J40: 92 | K40: 13 | L40: 74 | M40: 3 | N40: 2 | O40: 1 | P40: 90 | Q40: 296 | R40: 1 | S40: 264 | T40: 2 | U40: 77 | V40: 8.516129 | W40: 60.829493 | X40: 3.4285714 | Y40: 2.2077922 | Z40: 5.5
E41: 31 | J41: 0 | M41: 0 | P41: 0 | T41: 0 | U41: 0 | V41: #DIV/0! | W41: #DIV/0! | X41: #DIV/0! | Y41: #DIV/0! | Z41: #DIV/0!
...

Sheet FEBRUARI
A1: DATA PELAYANAN RI RSD Dr.SOEBANDI JEMBER
A2: BULAN : FEBRUARI 2026 | V2: s/e | W2: v/f*100 | X2: S/L+M | Y2: ((F-V)*E)/(LM) | Z2: L+M/F
A3: NO | B3: PELAYANAN | C3: RAWAT INAP | D3: KLAS PERAWATAN | E3: PERIODE | F3: TT (T) | G3: PX AWAL | H3: PX MASUK | I3: PX PINDAHAN | J3: JUMLAH (1+2+3) | K3: PX DI PINDAHKAN | L3: PX KELUAR HIDUP | M3: PX MATI | N3: KURANG 48 JAM | O3: LEBIH 48 JAM | P3: JUMLAH (5+6+7) | Q3: LAMA DI RAWAT | R3: PX KELUAR/MASUK HR SAMA | S3: HARI PERAWATAN | T3: Px AKHIR | U3: KUNJUNGN | V3: O | W3: BOR (O/T) | X3: LOS | Y3: TOI | Z3: BTO
V4: (TT terpakai) | W4: (75%-85%) | X4: (3-12 hari) | Y4: (1-3 hr) | Z4: (30 px)
G6: 1 | H6: 2 | I6: 3 | J6: 4 | K6: 5 | L6: 6 | M6: 7 | N6: 8 | O6: 9 | P6: 10 | Q6: 11 | R6: 12 | S6: 13 | T6: 14 | V6: 15 | W6: 16 | X6: 17 | Y6: 18 | Z6: 19
A7: 1 | B7: RAWAT INAP UMUM | C7: ADENIUM | D7: III | E7: 28 | F7: 20 | G7: 14 | H7: 135 | I7: 15 | J7: 164 | K7: 11 | L7: 122 | M7: 18 | N7: 10 | O7: 8 | P7: 151 | Q7: 491 | R7: 5 | S7: 466 | T7: 13 | U7: 140 | V7: 16.642857 | W7: 83.214286 | X7: 3.3285714 | Y7: 0.67142857 | Z7: 7
C8: ADENIUM | E8: 28 | F8: 20 | G8: 14 | H8: 135 | I8: 15 | J8: 164 | K8: 11 | L8: 122 | M8: 18 | N8: 10 | O8: 8 | P8: 151 | Q8: 491 | R8: 5 | S8: 466 | T8: 13 | U8: 140 | V8: 16.642857 | W8: 83.214286 | X8: 3.3285714 | Y8: 0.67142857 | Z8: 7
A9: 2 | C9: ANTURIUM | D9: III | E9: 28 | F9: 16 | G9: 14 | H9: 81 | I9: 41 | J9: 136 | K9: 1 | L9: 112 | M9: 13 | N9: 7 | O9: 6 | P9: 126 | Q9: 493 | R9: 2 | S9: 411 | T9: 10 | U9: 125 | V9: 14.678571 | W9: 91.741071 | X9: 3.288 | Y9: 0.296 | Z9: 7.8125
C10: ANTURIUM | E10: 28 | F10: 16 | G10: 14 | H10: 81 | I10: 41 | J10: 136 | K10: 1 | L10: 112 | M10: 13 | N10: 7 | O10: 6 | P10: 126 | Q10: 493 | R10: 2 | S10: 411 | T10: 10 | U10: 125 | V10: 14.678571 | W10: 91.741071 | X10: 3.288 | Y10: 0.296 | Z10: 7.8125
A11: 3 | D11: II | G11: 0 | H11: 0 | I11: 0 | J11: 0 | K11: 0 | L11: 0 | M11: 0 | N11: 0 | O11: 0 | P11: 0 | Q11: 0 | R11: 0 | S11: 0 | T11: 0 | U11: 0 | V11: #DIV/0! | W11: #DIV/0! | X11: #DIV/0! | Y11: #DIV/0! | Z11: #DIV/0!
C12: TULIP | D12: III | E12: 28 | F12: 12 | G12: 8 | H12: 81 | I12: 4 | J12: 93 | K12: 3 | L12: 81 | M12: 6 | N12: 5 | O12: 1 | P12: 90 | Q12: 289 | R12: 2 | S12: 247 | T12: 3 | U12: 87 | V12: 8.8214286 | W12: 73.511905 | X12: 2.8390805 | Y12: 1.0229885 | Z12: 7.25
C13: TULIP | E13: 28 | F13: 12 | G13: 8 | H13: 81 | I13: 4 | J13: 93 | K13: 3 | L13: 81 | M13: 6 | N13: 5 | O13: 1 | P13: 90 | Q13: 289 | R13: 2 | S13: 247 | T13: 3 | U13: 87 | V13: 8.8214286 | W13: 73.511905 | X13: 2.8390805 | Y13: 1.0229885 | Z13: 7.25
A14: 4 | C14: ASTER | D14: II | E14: 28 | F14: 2 | G14: 1 | H14: 18 | I14: 6 | J14: 25 | K14: 14 | L14: 10 | M14: 0 | N14: 0 | O14: 0 | P14: 24 | Q14: 31 | R14: 0 | S14: 34 | T14: 1 | U14: 10 | V14: 1.2142857 | W14: 60.714286 | X14: 3.4 | Y14: 2.2 | Z14: 5
D15: III | E15: 28 | F15: 17 | G15: 13 | H15: 120 | I15: 15 | J15: 148 | K15: 27 | L15: 104 | M15: 2 | N15: 2 | O15: 0 | P15: 133 | Q15: 366 | R15: 0 | S15: 415 | T15: 15 | U15: 106 | V15: 14.821429 | W15: 87.184874 | X15: 3.9150943 | Y15: 0.5754717 | Z15: 6.2352941
D16: ISOLASI | E16: 28 | F16: 5 | G16: 2 | H16: 9 | I16: 25 | J16: 36 | K16: 6 | L16: 25 | M16: 0 | N16: 0 | O16: 0 | P16: 31 | Q16: 80 | R16: 1 | S16: 104 | T16: 5 | U16: 25 | V16: 3.7142857 | W16: 74.285714 | X16: 4.16 | Y16: 1.44 | Z16: 5
C17: ASTER | E17: 28 | F17: 24 | G17: 16 | H17: 147 | I17: 46 | J17: 209 | K17: 47 | L17: 139 | M17: 2 | N17: 2 | O17: 0 | P17: 188 | Q17: 477 | R17: 1 | S17: 553 | T17: 21 | U17: 141 | V17: 19.75 | W17: 82.291667 | X17: 3.9219858 | Y17: 0.84397163 | Z17: 5.875
A18: 5 | C18: MELATI | D18: ATAS ISOLASI | E18: 28 | F18: 4 | G18: 0 | H18: 0 | I18: 0 | J18: 0 | K18: 0 | L18: 0 | N18: 0 | O18: 0 | P18: 0 | Q18: 0 | R18: 0 | S18: 0 | T18: 0 | U18: 0 | V18: 0 | W18: 0 | X18: #DIV/0! | Y18: #DIV/0! | Z18: 0
D19: ATAS III | E19: 28 | F19: 15 | G19: 20 | H19: 114 | I19: 6 | J19: 140 | K19: 10 | L19: 99 | M19: 18 | N19: 11 | O19: 7 | P19: 127 | Q19: 478 | R19: 3 | S19: 489 | T19: 13 | U19: 117 | V19: 17.464286 | W19: 116.42857 | X19: 4.1794872 | Y19: -0.58974359 | Z19: 7.8
D20: BAWAH III | E20: 28 | F20: 12 | G20: 12 | H20: 65 | I20: 28 | J20: 105 | K20: 18 | L20: 68 | M20: 11 | N20: 9 | O20: 2 | P20: 97 | Q20: 307 | R20: 4 | S20: 345 | T20: 8 | U20: 79 | V20: 12.321429 | W20: 102.67857 | X20: 4.3670886 | Y20: -0.11392405 | Z20: 6.5833333
C21: MELATI | E21: 28 | F21: 31 | G21: 32 | H21: 179 | I21: 34 | J21: 245 | K21: 28 | L21: 167 | M21: 29 | N21: 20 | O21: 9 | P21: 224 | Q21: 785 | R21: 7 | S21: 834 | T21: 21 | U21: 196 | V21: 29.785714 | W21: 110.31746 | X21: 4.255102 | Y21: -0.39795918 | Z21: 14.383333
A22: 6 | C22: SERUNI | D22: III | E22: 28 | F22: 18 | G22: 14 | H22: 139 | I22: 10 | J22: 163 | K22: 13 | L22: 127 | M22: 7 | N22: 4 | O22: 3 | P22: 147 | Q22: 440 | R22: 1 | S22: 511 | T22: 16 | U22: 134 | V22: 18.25 | W22: 101.38889 | X22: 3.8134328 | Y22: -0.052238806 | Z22: 7.4444444
C23: SERUNI | E23: 28 | F23: 18 | G23: 14 | H23: 139 | I23: 10 | J23: 163 | K23: 13 | L23: 127 | M23: 7 | N23: 4 | O23: 3 | P23: 147 | Q23: 440 | R23: 1 | S23: 511 | T23: 16 | U23: 134 | V23: 18.25 | W23: 101.38889 | X23: 3.8134328 | Y23: -0.052238806 | Z23: 7.4444444
A24: 7 | C24: MAWAR | D24: ISOLASI | E24: 28 | F24: 4 | G24: 0 | H24: 0 | I24: 0 | J24: 0 | K24: 0 | L24: 0 | N24: 0 | O24: 0 | P24: 0 | Q24: 0 | R24: 0 | S24: 0 | T24: 0 | U24: 0 | V24: 0 | W24: 0 | X24: #DIV/0! | Y24: #DIV/0! | Z24: 0
D25: III | E25: 28 | F25: 16 | G25: 14 | H25: 116 | I25: 16 | J25: 146 | K25: 10 | L25: 116 | M25: 6 | N25: 3 | O25: 3 | P25: 132 | Q25: 420 | R25: 1 | S25: 423 | T25: 14 | U25: 122 | V25: 15.107143 | W25: 94.419643 | X25: 3.4672131 | Y25: 0.20491803 | Z25: 7.625
C26: MAWAR | E26: 28 | F26: 20 | G26: 14 | H26: 116 | I26: 16 | J26: 146 | K26: 10 | L26: 116 | M26: 6 | N26: 3 | O26: 3 | P26: 132 | Q26: 420 | R26: 1 | S26: 423 | T26: 14 | U26: 122 | V26: 15.107143 | W26: 75.535714 | X26: 3.4672131 | Y26: 1.1229508 | Z26: 6.1
A27: 8 | C27: GARDENA | D27: III | E27: 28 | F27: 20 | G27: 14 | H27: 150 | I27: 10 | J27: 174 | K27: 13 | L27: 143 | M27: 8 | N27: 6 | O27: 2 | P27: 164 | Q27: 467 | R27: 2 | S27: 431 | T27: 10 | U27: 151 | V27: 15.392857 | W27: 76.964286 | X27: 2.8543046 | Y27: 0.85430464 | Z27: 7.55
C28: GARDENA | E28: 28 | F28: 20 | G28: 14 | H28: 150 | I28: 10 | J28: 174 | K28: 13 | L28: 143 | M28: 8 | N28: 6 | O28: 2 | P28: 164 | Q28: 467 | R28: 2 | S28: 431 | T28: 10 | U28: 151 | V28: 15.392857 | W28: 76.964286 | X28: 2.8543046 | Y28: 0.85430464 | Z28: 7.55
C29: BOGENVILE | D29: ISOLASI | E29: 28 | F29: 1 | G29: 0 | H29: 0 | I29: 0 | J29: 0 | K29: 0 | L29: 0 | N29: 0 | O29: 0 | P29: 0 | Q29: 0 | R29: 0 | S29: 0 | T29: 0 | U29: 0 | V29: 0 | W29: 0 | X29: #DIV/0! | Y29: #DIV/0! | Z29: 0
A30: 9 | C30: BOGENVILE | D30: I | E30: 28 | F30: 3 | G30: 2 | H30: 28 | I30: 12 | J30: 42 | K30: 7 | L30: 32 | M30: 0 | N30: 0 | O30: 0 | P30: 39 | Q30: 89 | R30: 1 | S30: 99 | T30: 3 | U30: 32 | V30: 3.5357143 | W30: 117.85714 | X30: 3.09375 | Y30: -0.46875 | Z30: 10.666667
C31: BOGENVILE | D31: PAV | E31: 28 | F31: 8 | G31: 4 | H31: 35 | I31: 10 | J31: 49 | K31: 11 | L31: 34 | M31: 2 | N31: 1 | O31: 1 | P31: 47 | Q31: 126 | R31: 1 | S31: 123 | T31: 2 | U31: 36 | V31: 4.3928571 | W31: 54.910714 | X31: 3.4166667 | Y31: 2.8055556 | Z31: 4.5
C32: BOGENVILE | E32: 28 | F32: 12 | G32: 6 | H32: 63 | I32: 22 | J32: 91 | K32: 18 | L32: 66 | M32: 2 | N32: 1 | O32: 1 | P32: 86 | Q32: 215 | R32: 2 | S32: 222 | T32: 5 | U32: 68 | V32: 7.9285714 | W32: 66.071429 | X32: 3.2647059 | Y32: 1.6764706 | Z32: 5.6666667
A33: 10 | C33: ALAMANDA | D33: ISOLASI | E33: 28 | F33: 1 | G33: 0 | H33: 0 | I33: 0 | J33: 0 | K33: 0 | L33: 0 | N33: 0 | O33: 0 | P33: 0 | Q33: 0 | R33: 0 | S33: 0 | T33: 0 | U33: 0 | V33: 0 | W33: 0 | X33: #DIV/0! | Y33: #DIV/0! | Z33: 0
C34: ALAMANDA | D34: I | E34: 28 | F34: 2 | G34: 3 | H34: 14 | I34: 4 | J34: 21 | K34: 2 | L34: 15 | M34: 2 | N34: 0 | O34: 2 | P34: 19 | Q34: 56 | R34: 0 | S34: 65 | T34: 2 | U34: 17 | V34: 2.3214286 | W34: 116.07143 | X34: 3.8235294 | Y34: -0.52941176 | Z34: 8.5
C35: ALAMANDA | D35: II | E35: 28 | F35: 4 | G35: 4 | H35: 24 | I35: 3 | J35: 31 | K35: 1 | L35: 25 | M35: 1 | N35: 1 | O35: 0 | P35: 27 | Q35: 82 | R35: 0 | S35: 90 | T35: 4 | U35: 26 | V35: 3.2142857 | W35: 80.357143 | X35: 3.4615385 | Y35: 0.84615385 | Z35: 6.5
C36: ALAMANDA | D36: III | E36: 28 | F36: 12 | G36: 9 | H36: 75 | I36: 8 | J36: 92 | K36: 2 | L36: 74 | M36: 7 | N36: 4 | O36: 3 | P36: 83 | Q36: 288 | R36: 1 | S36: 273 | T36: 9 | U36: 81 | V36: 9.75 | W36: 81.25 | X36: 3.3703704 | Y36: 0.77777778 | Z36: 6.75
C37: ALAMANDA | E37: 28 | F37: =SUM(F33:F36) -> 19 | G37: 16 | H37: 113 | I37: 15 | J37: 144 | K37: 5 | L37: 114 | M37: 10 | N37: 5 | O37: 5 | P37: 129 | Q37: 426 | R37: 1 | S37: 428 | T37: 15 | U37: 124 | V37: 15.285714 | W37: 80.451128 | X37: 3.4516129 | Y37: 0.83870968 | Z37: 6.5263158
A38: 11 | C38: CATHALIA | D38: CA ISOLASI | E38: 28 | F38: 6 | G38: 8 | H38: 46 | I38: 8 | J38: 62 | K38: 3 | L38: 45 | M38: 7 | N38: 2 | O38: 5 | P38: 55 | Q38: 141 | R38: 0 | S38: 177 | T38: 7 | U38: 52 | V38: 6.3214286 | W38: 105.35714 | X38: 3.4038462 | Y38: -0.17307692 | Z38: 8.6666667
C39: CATHALIA | D39: CATALYA ATAS | E39: 28 | F39: 8 | G39: 4 | H39: 34 | I39: 10 | J39: 48 | K39: 5 | L39: 39 | M39: 1 | N39: 1 | O39: 0 | P39: 45 | Q39: 120 | R39: 1 | S39: 115 | T39: 3 | U39: 40 | V39: 4.1071429 | W39: 51.339286 | X39: 2.875 | Y39: 2.725 | Z39: 5
C40: CATHALIA | D40: CATALYA BAWAH | E40: 28 | F40: 14 | G40: 2 | H40: 63 | I40: 12 | J40: 77 | K40: 10 | L40: 54 | M40: 5 | N40: 5 | O40: 0 | P40: 69 | Q40: 157 | R40: 3 | S40: 200 | T40: 8 | U40: 59 | V40: 7.1428571 | W40: 51.020408 | X40: 3.3898305 | Y40: 3.2542373 | Z40: 4.2142857
J41: 0 | M41: 0 | P41: 0 | T41: 0 | U41: 0 | V41: #DIV/0! | W41: #DIV/0! | X41: #DIV/0! | Y41: #DIV/0! | Z41: #DIV/0!
...

Sheet MARET
A1: DATA PELAYANAN RI RSD Dr.SOEBANDI JEMBER
A2: BULAN : MARET 2026 | V2: s/e | W2: v/f*100 | X2: S/L+M | Y2: ((F-V)*E)/(LM) | Z2: L+M/F
A3: NO | B3: PELAYANAN | C3: RAWAT INAP | D3: KLAS PERAWATAN | E3: PERIODE | F3: TT (T) | G3: PX AWAL | H3: PX MASUK | I3: PX PINDAHAN | J3: JUMLAH (1+2+3) | K3: PX DI PINDAHKAN | L3: PX KELUAR HIDUP | M3: PX MATI | N3: KURANG 48 JAM | O3: LEBIH 48 JAM | P3: JUMLAH (5+6+7) | Q3: LAMA DI RAWAT | R3: PX KELUAR/MASUK HR SAMA | S3: HARI PERAWATAN | T3: Px AKHIR | U3: KUNJUNGN | V3: O | W3: BOR (O/T) | X3: LOS | Y3: TOI | Z3: BTO
V4: (TT terpakai) | W4: (75%-85%) | X4: (3-12 hari) | Y4: (1-3 hr) | Z4: (30 px)
G6: 1 | H6: 2 | I6: 3 | J6: 4 | K6: 5 | L6: 6 | M6: 7 | N6: 8 | O6: 9 | P6: 10 | Q6: 11 | R6: 12 | S6: 13 | T6: 14 | V6: 15 | W6: 16 | X6: 17 | Y6: 18 | Z6: 19 | AA6: I | AB6: II | AC6: III
A7: 1 | B7: RAWAT INAP UMUM | C7: ADENIUM | D7: III | E7: 31 | F7: 20 | G7: 13 | H7: 123 | I7: 28 | J7: 164 | K7: 7 | L7: 117 | M7: 17 | N7: 6 | O7: 11 | P7: 141 | Q7: 496 | R7: 1 | S7: 463 | T7: 23 | U7: 134 | V7: 14.935484 | W7: 74.677419 | X7: 3.4552239 | Y7: 1.1716418 | Z7: 6.7 | AA7: =+S30+S34+S40+S44 -> 706 | AB7: =+S35+S38+S39+S47+S49+S110 -> 542 | AC7: =+S8+S10+S13+S21+S23+S26+S28+S36+S48+S50+S56 -> 4329
C8: ADENIUM | E8: 31 | F8: 20 | G8: 13 | H8: 123 | I8: 28 | J8: 164 | K8: 7 | L8: 117 | M8: 17 | N8: 6 | O8: 11 | P8: 141 | Q8: 496 | R8: 1 | S8: 463 | T8: 23 | U8: 134 | V8: 14.935484 | W8: 74.677419 | X8: 3.4552239 | Y8: 1.1716418 | Z8: 6.7
A9: 2 | C9: ANTURIUM | D9: III | E9: 31 | F9: 16 | G9: 10 | H9: 101 | I9: 27 | J9: 138 | K9: 2 | L9: 102 | M9: 18 | N9: 6 | O9: 12 | P9: 122 | Q9: 449 | R9: 0 | S9: 411 | T9: 16 | U9: 120 | V9: 13.258065 | W9: 82.862903 | X9: 3.425 | Y9: 0.70833333 | Z9: 7.5
C10: ANTURIUM | E10: 31 | F10: 16 | G10: 10 | H10: 101 | I10: 27 | J10: 138 | K10: 2 | L10: 102 | M10: 18 | N10: 6 | O10: 12 | P10: 122 | Q10: 449 | R10: 0 | S10: 411 | T10: 16 | U10: 120 | V10: 13.258065 | W10: 82.862903 | X10: 3.425 | Y10: 0.70833333 | Z10: 7.5
A11: 3 | D11: II | E11: 31 | G11: 0 | H11: 0 | I11: 0 | J11: 0 | K11: 0 | L11: 0 | M11: 0 | N11: 0 | O11: 0 | P11: 0 | Q11: 0 | R11: 0 | S11: 0 | T11: 0 | U11: 0 | V11: 0 | W11: #DIV/0! | X11: #DIV/0! | Y11: #DIV/0! | Z11: #DIV/0!
C12: TULIP | D12: III | E12: 31 | F12: 12 | G12: 3 | H12: 90 | I12: 2 | J12: 95 | K12: 2 | L12: 73 | M12: 8 | N12: 1 | O12: 7 | P12: 83 | Q12: 251 | R12: 0 | S12: 262 | T12: 12 | U12: 81 | V12: 8.4516129 | W12: 70.430108 | X12: 3.2345679 | Y12: 1.3580247 | Z12: 6.75
C13: TULIP | E13: 31 | F13: 12 | G13: 3 | H13: 90 | I13: 2 | J13: 95 | K13: 2 | L13: 73 | M13: 8 | N13: 1 | O13: 7 | P13: 83 | Q13: 251 | R13: 0 | S13: 262 | T13: 12 | U13: 81 | V13: 8.4516129 | W13: 70.430108 | X13: 3.2345679 | Y13: 1.3580247 | Z13: 6.75
A14: 4 | C14: ASTER | D14: II | E14: 31 | F14: 2 | G14: 1 | H14: 12 | I14: 4 | J14: 17 | K14: 7 | L14: 9 | M14: 0 | N14: 0 | O14: 0 | P14: 16 | Q14: 35 | R14: 0 | S14: 36 | T14: 1 | U14: 9 | V14: 1.1612903 | W14: 58.064516 | X14: 4 | Y14: 2.8888889 | Z14: 4.5
C15: ASTER | D15: III | E15: 31 | F15: 17 | G15: 15 | H15: 106 | I15: 14 | J15: 135 | K15: 21 | L15: 97 | M15: 4 | N15: 0 | O15: 4 | P15: 122 | Q15: 438 | R15: 0 | S15: 393 | T15: 13 | U15: 101 | V15: 12.677419 | W15: 74.573055 | X15: 3.8910891 | Y15: 1.3267327 | Z15: 5.9411765
C16: ASTER | D16: ISOLASI | E16: 31 | F16: 5 | G16: 5 | H16: 14 | I16: 20 | J16: 39 | K16: 2 | L16: 31 | M16: 1 | N16: 0 | O16: 1 | P16: 34 | Q16: 133 | R16: 1 | S16: 105 | T16: 5 | U16: 32 | V16: 3.3870968 | W16: 67.741935 | X16: 3.28125 | Y16: 1.5625 | Z16: 6.4
C17: ASTER | E17: 31 | F17: 24 | G17: 21 | H17: 132 | I17: 38 | J17: 191 | K17: 30 | L17: 137 | M17: 5 | N17: 0 | O17: 5 | P17: 172 | Q17: 606 | R17: 1 | S17: 534 | T17: 19 | U17: 142 | V17: 17.225806 | W17: 71.774194 | X17: 3.7605634 | Y17: 1.4788732 | Z17: 5.9166667
A18: 5 | C18: MELATI | D18: ATAS ISOLASI | E18: 31 | F18: 4 | G18: 0 | H18: 0 | I18: 0 | J18: 0 | K18: 0 | L18: 0 | N18: 0 | O18: 0 | P18: 0 | Q18: 0 | R18: 0 | S18: 0 | T18: 0 | U18: 0 | V18: 0 | W18: 0 | X18: #DIV/0! | Y18: #DIV/0! | Z18: 0
C19: MELATI | D19: ATAS III | E19: 31 | F19: 15 | G19: 13 | H19: 137 | I19: 5 | J19: 155 | K19: 11 | L19: 89 | M19: 38 | N19: 21 | O19: 17 | P19: 138 | Q19: 546 | R19: 2 | S19: 518 | T19: 17 | U19: 127 | V19: 16.709677 | W19: 111.39785 | X19: 4.0787402 | Y19: -0.41732283 | Z19: 8.4666667
C20: MELATI | D20: BAWAH III | E20: 31 | F20: 15 | G20: 8 | H20: 81 | I20: 27 | J20: 116 | K20: 18 | L20: 69 | M20: 15 | N20: 7 | O20: 8 | P20: 102 | Q20: 437 | R20: 2 | S20: 375 | T20: 14 | U20: 84 | V20: 12.096774 | W20: 80.645161 | X20: 4.4642857 | Y20: 1.0714286 | Z20: 5.6
C21: MELATI | E21: 31 | F21: 34 | G21: 21 | H21: 218 | I21: 32 | J21: 271 | K21: 29 | L21: 158 | M21: 53 | N21: 28 | O21: 25 | P21: 240 | Q21: 983 | R21: 4 | S21: 893 | T21: 31 | U21: 211 | V21: 28.806452 | W21: 96.021505 | X21: 4.2322275 | Y21: 0.17535545 | Z21: 14.066667
A22: 6 | C22: SERUNI | D22: III | E22: 31 | F22: 24 | G22: 16 | H22: 160 | I22: 3 | J22: 179 | K22: 8 | L22: 140 | M22: 7 | N22: 3 | O22: 4 | P22: 155 | Q22: 491 | R22: 0 | S22: 490 | T22: 24 | U22: 147 | V22: 15.806452 | W22: 65.860215 | X22: 3.3333333 | Y22: 1.7278912 | Z22: 6.125
C23: SERUNI | E23: 31 | F23: 24 | G23: 16 | H23: 160 | I23: 3 | J23: 179 | K23: 8 | L23: 140 | M23: 7 | N23: 3 | O23: 4 | P23: 155 | Q23: 491 | R23: 0 | S23: 490 | T23: 24 | U23: 147 | V23: 15.806452 | W23: 65.860215 | X23: 3.3333333 | Y23: 1.7278912 | Z23: 6.125
A24: 7 | C24: MAWAR | D24: ISOLASI | E24: 31 | F24: 4 | G24: 0 | H24: 0 | I24: 0 | J24: 0 | K24: 0 | L24: 0 | N24: 0 | O24: 0 | P24: 0 | Q24: 0 | R24: 0 | S24: 0 | T24: 0 | U24: 0 | V24: 0 | W24: 0 | X24: #DIV/0! | Y24: #DIV/0! | Z24: 0
C25: MAWAR | D25: III | E25: 31 | F25: 16 | G25: 14 | H25: 134 | I25: 12 | J25: 160 | K25: 5 | L25: 122 | M25: 15 | N25: 6 | O25: 9 | P25: 142 | Q25: 500 | R25: 2 | S25: 478 | T25: 18 | U25: 137 | V25: 15.419355 | W25: 96.370968 | X25: 3.4890511 | Y25: 0.13138686 | Z25: 8.5625
C26: MAWAR | E26: 31 | F26: 20 | G26: 14 | H26: 134 | I26: 12 | J26: 160 | K26: 5 | L26: 122 | M26: 15 | N26: 6 | O26: 9 | P26: 142 | Q26: 500 | R26: 2 | S26: 478 | T26: 18 | U26: 137 | V26: 15.419355 | W26: 77.096774 | X26: 3.4890511 | Y26: 1.0364964 | Z26: 6.85
A27: 8 | C27: GARDENA | D27: III | E27: 31 | F27: 20 | G27: 10 | H27: 147 | I27: 4 | J27: 161 | K27: 10 | L27: 128 | M27: 3 | N27: 3 | O27: 0 | P27: 141 | Q27: 423 | R27: 1 | S27: 449 | T27: 20 | U27: 131 | V27: 14.483871 | W27: 72.419355 | X27: 3.4274809 | Y27: 1.3053435 | Z27: 6.55
C28: GARDENA | E28: 31 | F28: 20 | G28: 10 | H28: 147 | I28: 4 | J28: 161 | K28: 10 | L28: 128 | M28: 3 | N28: 3 | O28: 0 | P28: 141 | Q28: 423 | R28: 1 | S28: 449 | T28: 20 | U28: 131 | V28: 14.483871 | W28: 72.419355 | X28: 3.4274809 | Y28: 1.3053435 | Z28: 6.55
C29: BOGENVILE | D29: ISOLASI | E29: 31 | F29: 1 | G29: 0 | H29: 0 | I29: 0 | J29: 0 | K29: 0 | L29: 0 | N29: 0 | O29: 0 | P29: 0 | Q29: 0 | R29: 0 | S29: 0 | T29: 0 | U29: 0 | V29: 0 | W29: 0 | X29: #DIV/0! | Y29: #DIV/0! | Z29: 0
A30: 9 | C30: BOGENVILE | D30: I | E30: 31 | F30: 3 | G30: 3 | H30: 18 | I30: 14 | J30: 35 | K30: 4 | L30: 29 | M30: 0 | N30: 0 | O30: 0 | P30: 33 | Q30: 115 | R30: 0 | S30: 107 | T30: 2 | U30: 29 | V30: 3.4516129 | W30: 115.05376 | X30: 3.6896552 | Y30: -0.48275862 | Z30: 9.6666667
C31: BOGENVILE | D31: PAV | E31: 31 | F31: 8 | G31: 2 | H31: 38 | I31: 3 | J31: 43 | K31: 14 | L31: 23 | M31: 2 | N31: 1 | O31: 1 | P31: 39 | Q31: 84 | R31: 0 | S31: 83 | T31: 4 | U31: 25 | V31: 2.6774194 | W31: 33.467742 | X31: 3.32 | Y31: 6.6 | Z31: 3.125
C32: BOGENVILE | E32: 31 | F32: 12 | G32: 5 | H32: 56 | I32: 17 | J32: 78 | K32: 18 | L32: 52 | M32: 2 | N32: 1 | O32: 1 | P32: 72 | Q32: 199 | R32: 0 | S32: 190 | T32: 6 | U32: 54 | V32: 6.1290323 | W32: 51.075269 | X32: 3.5185185 | Y32: 3.3703704 | Z32: 4.5
A33: 10 | C33: ALAMANDA | D33: ISOLASI | E33: 31 | F33: 1 | G33: 0 | H33: 9 | I33: 1 | J33: 10 | K33: 2 | L33: 7 | N33: 0 | O33: 0 | P33: 9 | Q33: 21 | R33: 0 | S33: 21 | T33: 1 | U33: 7 | V33: 0.67741935 | W33: 67.741935 | X33: 3 | Y33: 1.4285714 | Z33: 7
C34: ALAMANDA | D34: I | E34: 31 | F34: 2 | G34: 2 | H34: 10 | I34: 3 | J34: 15 | K34: 0 | L34: 13 | M34: 0 | N34: 0 | O34: 0 | P34: 13 | Q34: 67 | R34: 0 | S34: 50 | T34: 2 | U34: 13 | V34: 1.6129032 | W34: 80.645161 | X34: 3.8461538 | Y34: 0.92307692 | Z34: 6.5
C35: ALAMANDA | D35: II | E35: 31 | F35: 4 | G35: 4 | H35: 18 | I35: 2 | J35: 24 | K35: 1 | L35: 18 | M35: 1 | N35: 0 | O35: 1 | P35: 20 | Q35: 95 | R35: 0 | S35: 97 | T35: 4 | U35: 19 | V35: 3.1290323 | W35: 78.225806 | X35: 5.1052632 | Y35: 1.4210526 | Z35: 4.75
C36: ALAMANDA | D36: III | E36: 31 | F36: 12 | G36: 9 | H36: 67 | I36: 8 | J36: 84 | K36: 2 | L36: 64 | M36: 6 | N36: 0 | O36: 6 | P36: 72 | Q36: 297 | R36: 0 | S36: 280 | T36: 12 | U36: 70 | V36: 9.0322581 | W36: 75.268817 | X36: 4 | Y36: 1.3142857 | Z36: 5.8333333
C37: ALAMANDA | E37: 31 | F37: 19 | G37: 15 | H37: 104 | I37: 14 | J37: 133 | K37: 5 | L37: 102 | M37: 7 | N37: 0 | O37: 7 | P37: 114 | Q37: 480 | R37: 0 | S37: 448 | T37: 19 | U37: 109 | V37: 14.451613 | W37: 76.061121 | X37: 4.1100917 | Y37: 1.293578 | Z37: 5.7368421
A38: 11 | C38: CATHALIA | D38: CA ISOLASI | E38: 31 | F38: 6 | G38: 7 | H38: 21 | I38: 4 | J38: 32 | K38: 13 | L38: 19 | M38: 0 | N38: 0 | O38: 0 | P38: 32 | Q38: 60 | R38: 0 | S38: 102 | T38: 0 | U38: 19 | V38: 3.2903226 | W38: 54.83871 | X38: 5.3684211 | Y38: 4.4210526 | Z38: 3.1666667
C39: CATHALIA | D39: CATALYA ATAS | E39: 31 | F39: 8 | G39: 3 | H39: 61 | I39: 24 | J39: 88 | K39: 5 | L39: 62 | M39: 8 | N39: 2 | O39: 6 | P39: 75 | Q39: 215 | R39: 0 | S39: 185 | T39: 13 | U39: 70 | V39: 5.9677419 | W39: 74.596774 | X39: 2.6428571 | Y39: 0.9 | Z39: 8.75
C40: CATHALIA | D40: CATALYA BAWAH | E40: 31 | F40: 14 | G40: 8 | H40: 68 | I40: 7 | J40: 83 | K40: 7 | L40: 55 | M40: 7 | N40: 3 | O40: 4 | P40: 69 | Q40: 219 | R40: 0 | S40: 208 | T40: 14 | U40: 62 | V40: 6.7096774 | W40: 47.926267 | X40: 3.3548387 | Y40: 3.6451613 | Z40: 4.4285714
J41: 0 | M41: 0 | P41: 0 | T41: 0 | U41: 0 | V41: #DIV/0! | W41: #DIV/0! | X41: #DIV/0! | Y41: #DIV/0! | Z41: #DIV/0!
...

Sheet JAN - MAR 2026
A1: DATA PELAYANAN RI RSD Dr.SOEBANDI JEMBER
A2: BULAN : JANUARI - MARET 2026 | V2: s/e | W2: v/f*100 | X2: S/L+M | Y2: ((F-V)*E)/(LM) | Z2: L+M/F
A3: NO | B3: PELAYANAN | C3: RAWAT INAP | D3: KLAS PERAWATAN | E3: PERIODE | F3: TT (T) | G3: PX AWAL | H3: PX MASUK | I3: PX PINDAHAN | J3: JUMLAH (1+2+3) | K3: PX DI PINDAHKAN | L3: PX KELUAR HIDUP | M3: PX MATI | N3: KURANG 48 JAM | O3: LEBIH 48 JAM | P3: JUMLAH (5+6+7) | Q3: LAMA DI RAWAT | R3: PX KELUAR/MASUK HR SAMA | S3: HARI PERAWATAN | T3: Px AKHIR | U3: KUNJUNGN | V3: O | W3: BOR (O/T) | X3: LOS | Y3: TOI | Z3: BTO
V4: (TT terpakai) | W4: (75%-85%) | X4: (3-12 hari) | Y4: (1-3 hr) | Z4: (30 px)
G6: 1 | H6: 2 | I6: 3 | J6: 4 | K6: 5 | L6: 6 | M6: 7 | N6: 8 | O6: 9 | P6: 10 | Q6: 11 | R6: 12 | S6: 13 | T6: 14 | V6: 15 | W6: 16 | X6: 17 | Y6: 18 | Z6: 19
A7: 1 | B7: RAWAT INAP UMUM | C7: ADENIUM | D7: III | E7: =+JAN!E7+FEBRUARI!E7+MARET!E7 -> 90 | F7: 20 | G7: =JAN!G7 -> 22 | H7: =+JAN!H7+FEBRUARI!H7+MARET!H7 -> 356 | I7: =+JAN!I7+FEBRUARI!I7+MARET!I7 -> 59 | J7: =+G7+H7+I7 -> 437 | K7: =+JAN!K7+FEBRUARI!K7+MARET!K7 -> 25 | L7: =+JAN!L7+FEBRUARI!L7+MARET!L7 -> 327 | M7: =+N7+O7 -> 53 | N7: =+JAN!N7+FEBRUARI!N7+MARET!N7 -> 25 | O7: =+JAN!O7+FEBRUARI!O7+MARET!O7 -> 28 | P7: =+K7+L7+M7 -> 405 | Q7: =+JAN!Q7+FEBRUARI!Q7+MARET!Q7 -> 1392 | R7: =+JAN!R7+FEBRUARI!R7+MARET!R7 -> 7 | S7: =+JAN!S7+FEBRUARI!S7+MARET!S7 -> 1581 | T7: =J7-P7 -> 32 | U7: =L7+M7 -> 380 | V7: =$S7/$E7 -> 17.566667 | W7: =$V7/$F7*100 -> 87.833333 | X7: =$S7/($L7+$M7) -> 4.1605263 | Y7: =(($F7-$V7)*$E7)/($L7+$M7) -> 0.57631579 | Z7: =($L7+$M7)/$F7 -> 19
C8: ADENIUM | E8: =+JAN!E8+FEBRUARI!E8+MARET!E8 -> 90 | F8: 20 | G8: =JAN!G8 -> 22 | H8: =+JAN!H8+FEBRUARI!H8+MARET!H8 -> 356 | I8: =+JAN!I8+FEBRUARI!I8+MARET!I8 -> 59 | J8: =+G8+H8+I8 -> 437 | K8: =+JAN!K8+FEBRUARI!K8+MARET!K8 -> 25 | L8: =+JAN!L8+FEBRUARI!L8+MARET!L8 -> 327 | M8: =+N8+O8 -> 53 | N8: =+JAN!N8+FEBRUARI!N8+MARET!N8 -> 25 | O8: =+JAN!O8+FEBRUARI!O8+MARET!O8 -> 28 | P8: =+K8+L8+M8 -> 405 | Q8: =+JAN!Q8+FEBRUARI!Q8+MARET!Q8 -> 1392 | R8: =+JAN!R8+FEBRUARI!R8+MARET!R8 -> 7 | S8: =+JAN!S8+FEBRUARI!S8+MARET!S8 -> 1581 | T8: =J8-P8 -> 32 | U8: =L8+M8 -> 380 | V8: =$S8/$E8 -> 17.566667 | W8: =$V8/$F8*100 -> 87.833333 | X8: =$S8/($L8+$M8) -> 4.1605263 | Y8: =(($F8-$V8)*$E8)/($L8+$M8) -> 0.57631579 | Z8: =($L8+$M8)/$F8 -> 19
A9: 2 | C9: ANTURIUM | D9: III | E9: =+JAN!E9+FEBRUARI!E9+MARET!E9 -> 90 | F9: 16 | G9: =JAN!G9 -> 14 | H9: =+JAN!H9+FEBRUARI!H9+MARET!H9 -> 272 | I9: =+JAN!I9+FEBRUARI!I9+MARET!I9 -> 108 | J9: =+G9+H9+I9 -> 394 | K9: =+JAN!K9+FEBRUARI!K9+MARET!K9 -> 9 | L9: =+JAN!L9+FEBRUARI!L9+MARET!L9 -> 320 | M9: =+N9+O9 -> 49 | N9: =+JAN!N9+FEBRUARI!N9+MARET!N9 -> 20 | O9: =+JAN!O9+FEBRUARI!O9+MARET!O9 -> 29 | P9: =+K9+L9+M9 -> 378 | Q9: =+JAN!Q9+FEBRUARI!Q9+MARET!Q9 -> 1380 | R9: =+JAN!R9+FEBRUARI!R9+MARET!R9 -> 4 | S9: =+JAN!S9+FEBRUARI!S9+MARET!S9 -> 1282 | T9: =J9-P9 -> 16 | U9: =L9+M9 -> 369 | V9: =$S9/$E9 -> 14.244444 | W9: =$V9/$F9*100 -> 89.027778 | X9: =$S9/($L9+$M9) -> 3.4742547 | Y9: =(($F9-$V9)*$E9)/($L9+$M9) -> 0.42818428 | Z9: =($L9+$M9)/$F9 -> 23.0625
C10: ANTURIUM | E10: =+JAN!E10+FEBRUARI!E10+MARET!E10 -> 90 | F10: 16 | G10: =JAN!G10 -> 14 | H10: =+JAN!H10+FEBRUARI!H10+MARET!H10 -> 272 | I10: =+JAN!I10+FEBRUARI!I10+MARET!I10 -> 108 | J10: =+G10+H10+I10 -> 394 | K10: =+JAN!K10+FEBRUARI!K10+MARET!K10 -> 9 | L10: =+JAN!L10+FEBRUARI!L10+MARET!L10 -> 320 | M10: =+N10+O10 -> 49 | N10: =+JAN!N10+FEBRUARI!N10+MARET!N10 -> 20 | O10: =+JAN!O10+FEBRUARI!O10+MARET!O10 -> 29 | P10: =+K10+L10+M10 -> 378 | Q10: =+JAN!Q10+FEBRUARI!Q10+MARET!Q10 -> 1380 | R10: =+JAN!R10+FEBRUARI!R10+MARET!R10 -> 4 | S10: =+JAN!S10+FEBRUARI!S10+MARET!S10 -> 1282 | T10: =J10-P10 -> 16 | U10: =L10+M10 -> 369 | V10: =$S10/$E10 -> 14.244444 | W10: =$V10/$F10*100 -> 89.027778 | X10: =$S10/($L10+$M10) -> 3.4742547 | Y10: =(($F10-$V10)*$E10)/($L10+$M10) -> 0.42818428 | Z10: =($L10+$M10)/$F10 -> 23.0625
A11: 3 | D11: II | E11: =+JAN!E11+FEBRUARI!E11+MARET!E11 -> 62 | G11: =JAN!G11 -> 0 | H11: =+JAN!H11+FEBRUARI!H11+MARET!H11 -> 0 | I11: =+JAN!I11+FEBRUARI!I11+MARET!I11 -> 0 | J11: =+G11+H11+I11 -> 0 | K11: =+JAN!K11+FEBRUARI!K11+MARET!K11 -> 0 | L11: =+JAN!L11+FEBRUARI!L11+MARET!L11 -> 0 | M11: =+N11+O11 -> 0 | N11: =+JAN!N11+FEBRUARI!N11+MARET!N11 -> 0 | O11: =+JAN!O11+FEBRUARI!O11+MARET!O11 -> 0 | P11: =+K11+L11+M11 -> 0 | Q11: =+JAN!Q11+FEBRUARI!Q11+MARET!Q11 -> 0 | R11: =+JAN!R11+FEBRUARI!R11+MARET!R11 -> 0 | S11: =+JAN!S11+FEBRUARI!S11+MARET!S11 -> 0 | T11: =J11-P11 -> 0 | U11: =L11+M11 -> 0 | V11: =$S11/$E11 -> 0 | W11: =$V11/$F11*100 -> #DIV/0! | X11: =$S11/($L11+$M11) -> #DIV/0! | Y11: =(($F11-$V11)*$E11)/($L11+$M11) -> #DIV/0! | Z11: =($L11+$M11)/$F11 -> #DIV/0!
C12: TULIP | D12: III | E12: =+JAN!E12+FEBRUARI!E12+MARET!E12 -> 90 | F12: 12 | G12: =JAN!G12 -> 10 | H12: =+JAN!H12+FEBRUARI!H12+MARET!H12 -> 259 | I12: =+JAN!I12+FEBRUARI!I12+MARET!I12 -> 12 | J12: =+G12+H12+I12 -> 281 | K12: =+JAN!K12+FEBRUARI!K12+MARET!K12 -> 16 | L12: =+JAN!L12+FEBRUARI!L12+MARET!L12 -> 236 | M12: =+N12+O12 -> 17 | N12: =+JAN!N12+FEBRUARI!N12+MARET!N12 -> 8 | O12: =+JAN!O12+FEBRUARI!O12+MARET!O12 -> 9 | P12: =+K12+L12+M12 -> 269 | Q12: =+JAN!Q12+FEBRUARI!Q12+MARET!Q12 -> 847 | R12: =+JAN!R12+FEBRUARI!R12+MARET!R12 -> 3 | S12: =+JAN!S12+FEBRUARI!S12+MARET!S12 -> 808 | T12: =J12-P12 -> 12 | U12: =L12+M12 -> 253 | V12: =$S12/$E12 -> 8.9777778 | W12: =$V12/$F12*100 -> 74.814815 | X12: =$S12/($L12+$M12) -> 3.1936759 | Y12: =(($F12-$V12)*$E12)/($L12+$M12) -> 1.0750988 | Z12: =($L12+$M12)/$F12 -> 21.083333
C13: TULIP | E13: =+JAN!E13+FEBRUARI!E13+MARET!E13 -> 90 | F13: 12 | G13: =JAN!G13 -> 10 | H13: =+JAN!H13+FEBRUARI!H13+MARET!H13 -> 259 | I13: =+JAN!I13+FEBRUARI!I13+MARET!I13 -> 12 | J13: =+G13+H13+I13 -> 281 | K13: =+JAN!K13+FEBRUARI!K13+MARET!K13 -> 16 | L13: =+JAN!L13+FEBRUARI!L13+MARET!L13 -> 236 | M13: =+N13+O13 -> 17 | N13: =+JAN!N13+FEBRUARI!N13+MARET!N13 -> 8 | O13: =+JAN!O13+FEBRUARI!O13+MARET!O13 -> 9 | P13: =+K13+L13+M13 -> 269 | Q13: =+JAN!Q13+FEBRUARI!Q13+MARET!Q13 -> 847 | R13: =+JAN!R13+FEBRUARI!R13+MARET!R13 -> 3 | S13: =+JAN!S13+FEBRUARI!S13+MARET!S13 -> 808 | T13: =J13-P13 -> 12 | U13: =L13+M13 -> 253 | V13: =$S13/$E13 -> 8.9777778 | W13: =$V13/$F13*100 -> 74.814815 | X13: =$S13/($L13+$M13) -> 3.1936759 | Y13: =(($F13-$V13)*$E13)/($L13+$M13) -> 1.0750988 | Z13: =($L13+$M13)/$F13 -> 21.083333
A14: 4 | C14: ASTER | D14: II | E14: =+JAN!E14+FEBRUARI!E14+MARET!E14 -> 90 | F14: 2 | G14: =JAN!G14 -> 2 | H14: =+JAN!H14+FEBRUARI!H14+MARET!H14 -> 43 | I14: =+JAN!I14+FEBRUARI!I14+MARET!I14 -> 17 | J14: =+G14+H14+I14 -> 62 | K14: =+JAN!K14+FEBRUARI!K14+MARET!K14 -> 29 | L14: =+JAN!L14+FEBRUARI!L14+MARET!L14 -> 32 | M14: =+N14+O14 -> 0 | N14: =+JAN!N14+FEBRUARI!N14+MARET!N14 -> 0 | O14: =+JAN!O14+FEBRUARI!O14+MARET!O14 -> 0 | P14: =+K14+L14+M14 -> 61 | Q14: =+JAN!Q14+FEBRUARI!Q14+MARET!Q14 -> 106 | R14: =+JAN!R14+FEBRUARI!R14+MARET!R14 -> 0 | S14: =+JAN!S14+FEBRUARI!S14+MARET!S14 -> 111 | T14: =J14-P14 -> 1 | U14: =L14+M14 -> 32 | V14: =$S14/$E14 -> 1.2333333 | W14: =$V14/$F14*100 -> 61.666667 | X14: =$S14/($L14+$M14) -> 3.46875 | Y14: =(($F14-$V14)*$E14)/($L14+$M14) -> 2.15625 | Z14: =($L14+$M14)/$F14 -> 16
C15: ASTER | D15: III | E15: =+JAN!E15+FEBRUARI!E15+MARET!E15 -> 90 | F15: 17 | G15: =JAN!G15 -> 15 | H15: =+JAN!H15+FEBRUARI!H15+MARET!H15 -> 353 | I15: =+JAN!I15+FEBRUARI!I15+MARET!I15 -> 46 | J15: =+G15+H15+I15 -> 414 | K15: =+JAN!K15+FEBRUARI!K15+MARET!K15 -> 60 | L15: =+JAN!L15+FEBRUARI!L15+MARET!L15 -> 330 | M15: =+N15+O15 -> 11 | N15: =+JAN!N15+FEBRUARI!N15+MARET!N15 -> 6 | O15: =+JAN!O15+FEBRUARI!O15+MARET!O15 -> 5 | P15: =+K15+L15+M15 -> 401 | Q15: =+JAN!Q15+FEBRUARI!Q15+MARET!Q15 -> 1252 | R15: =+JAN!R15+FEBRUARI!R15+MARET!R15 -> 4 | S15: =+JAN!S15+FEBRUARI!S15+MARET!S15 -> 1257 | T15: =J15-P15 -> 13 | U15: =L15+M15 -> 341 | V15: =$S15/$E15 -> 13.966667 | W15: =$V15/$F15*100 -> 82.156863 | X15: =$S15/($L15+$M15) -> 3.686217 | Y15: =(($F15-$V15)*$E15)/($L15+$M15) -> 0.80058651 | Z15: =($L15+$M15)/$F15 -> 20.058824
C16: ASTER | D16: ISOLASI | E16: =+JAN!E16+FEBRUARI!E16+MARET!E16 -> 90 | F16: 5 | G16: =JAN!G16 -> 4 | H16: =+JAN!H16+FEBRUARI!H16+MARET!H16 -> 43 | I16: =+JAN!I16+FEBRUARI!I16+MARET!I16 -> 51 | J16: =+G16+H16+I16 -> 98 | K16: =+JAN!K16+FEBRUARI!K16+MARET!K16 -> 12 | L16: =+JAN!L16+FEBRUARI!L16+MARET!L16 -> 80 | M16: =+N16+O16 -> 1 | N16: =+JAN!N16+FEBRUARI!N16+MARET!N16 -> 0 | O16: =+JAN!O16+FEBRUARI!O16+MARET!O16 -> 1 | P16: =+K16+L16+M16 -> 93 | Q16: =+JAN!Q16+FEBRUARI!Q16+MARET!Q16 -> 302 | R16: =+JAN!R16+FEBRUARI!R16+MARET!R16 -> 2 | S16: =+JAN!S16+FEBRUARI!S16+MARET!S16 -> 295 | T16: =J16-P16 -> 5 | U16: =L16+M16 -> 81 | V16: =$S16/$E16 -> 3.2777778 | W16: =$V16/$F16*100 -> 65.555556 | X16: =$S16/($L16+$M16) -> 3.6419753 | Y16: =(($F16-$V16)*$E16)/($L16+$M16) -> 1.9135802 | Z16: =($L16+$M16)/$F16 -> 16.2
C17: ASTER | E17: =+JAN!E17+FEBRUARI!E17+MARET!E17 -> 90 | F17: 24 | G17: =JAN!G17 -> 21 | H17: =+JAN!H17+FEBRUARI!H17+MARET!H17 -> 439 | I17: =+JAN!I17+FEBRUARI!I17+MARET!I17 -> 114 | J17: =+G17+H17+I17 -> 574 | K17: =+JAN!K17+FEBRUARI!K17+MARET!K17 -> 101 | L17: =+JAN!L17+FEBRUARI!L17+MARET!L17 -> 442 | M17: =+N17+O17 -> 12 | N17: =+JAN!N17+FEBRUARI!N17+MARET!N17 -> 6 | O17: =+JAN!O17+FEBRUARI!O17+MARET!O17 -> 6 | P17: =+K17+L17+M17 -> 555 | Q17: =+JAN!Q17+FEBRUARI!Q17+MARET!Q17 -> 1660 | R17: =+JAN!R17+FEBRUARI!R17+MARET!R17 -> 6 | S17: =+JAN!S17+FEBRUARI!S17+MARET!S17 -> 1663 | T17: =J17-P17 -> 19 | U17: =L17+M17 -> 454 | V17: =$S17/$E17 -> 18.477778 | W17: =$V17/$F17*100 -> 76.990741 | X17: =$S17/($L17+$M17) -> 3.6629956 | Y17: =(($F17-$V17)*$E17)/($L17+$M17) -> 1.0947137 | Z17: =($L17+$M17)/$F17 -> 18.916667
A18: 5 | C18: MELATI | D18: ATAS ISOLASI | E18: =+JAN!E18+FEBRUARI!E18+MARET!E18 -> 90 | F18: 4 | G18: =JAN!G18 -> 0 | H18: =+JAN!H18+FEBRUARI!H18+MARET!H18 -> 0 | I18: =+JAN!I18+FEBRUARI!I18+MARET!I18 -> 0 | J18: =+G18+H18+I18 -> 0 | K18: =+JAN!K18+FEBRUARI!K18+MARET!K18 -> 0 | L18: =+JAN!L18+FEBRUARI!L18+MARET!L18 -> 0 | M18: =+N18+O18 -> 0 | N18: =+JAN!N18+FEBRUARI!N18+MARET!N18 -> 0 | O18: =+JAN!O18+FEBRUARI!O18+MARET!O18 -> 0 | P18: =+K18+L18+M18 -> 0 | Q18: =+JAN!Q18+FEBRUARI!Q18+MARET!Q18 -> 0 | R18: =+JAN!R18+FEBRUARI!R18+MARET!R18 -> 0 | S18: =+JAN!S18+FEBRUARI!S18+MARET!S18 -> 0 | T18: =J18-P18 -> 0 | U18: =L18+M18 -> 0 | V18: =$S18/$E18 -> 0 | W18: =$V18/$F18*100 -> 0 | X18: =$S18/($L18+$M18) -> #DIV/0! | Y18: =(($F18-$V18)*$E18)/($L18+$M18) -> #DIV/0! | Z18: =($L18+$M18)/$F18 -> 0
C19: MELATI | D19: ATAS III | E19: =+JAN!E19+FEBRUARI!E19+MARET!E19 -> 90 | F19: 15 | G19: =JAN!G19 -> 21 | H19: =+JAN!H19+FEBRUARI!H19+MARET!H19 -> 387 | I19: =+JAN!I19+FEBRUARI!I19+MARET!I19 -> 23 | J19: =+G19+H19+I19 -> 431 | K19: =+JAN!K19+FEBRUARI!K19+MARET!K19 -> 38 | L19: =+JAN!L19+FEBRUARI!L19+MARET!L19 -> 299 | M19: =+N19+O19 -> 77 | N19: =+JAN!N19+FEBRUARI!N19+MARET!N19 -> 43 | O19: =+JAN!O19+FEBRUARI!O19+MARET!O19 -> 34 | P19: =+K19+L19+M19 -> 414 | Q19: =+JAN!Q19+FEBRUARI!Q19+MARET!Q19 -> 1528 | R19: =+JAN!R19+FEBRUARI!R19+MARET!R19 -> 7 | S19: =+JAN!S19+FEBRUARI!S19+MARET!S19 -> 1573 | T19: =J19-P19 -> 17 | U19: =L19+M19 -> 376 | V19: =$S19/$E19 -> 17.477778 | W19: =$V19/$F19*100 -> 116.51852 | X19: =$S19/($L19+$M19) -> 4.1835106 | Y19: =(($F19-$V19)*$E19)/($L19+$M19) -> -0.59308511 | Z19: =($L19+$M19)/$F19 -> 25.066667
C20: MELATI | D20: BAWAH III | E20: =+JAN!E20+FEBRUARI!E20+MARET!E20 -> 90 | F20: 15 | G20: =JAN!G20 -> 12 | H20: =+JAN!H20+FEBRUARI!H20+MARET!H20 -> 227 | I20: =+JAN!I20+FEBRUARI!I20+MARET!I20 -> 86 | J20: =+G20+H20+I20 -> 325 | K20: =+JAN!K20+FEBRUARI!K20+MARET!K20 -> 58 | L20: =+JAN!L20+FEBRUARI!L20+MARET!L20 -> 208 | M20: =+N20+O20 -> 45 | N20: =+JAN!N20+FEBRUARI!N20+MARET!N20 -> 27 | O20: =+JAN!O20+FEBRUARI!O20+MARET!O20 -> 18 | P20: =+K20+L20+M20 -> 311 | Q20: =+JAN!Q20+FEBRUARI!Q20+MARET!Q20 -> 1058 | R20: =+JAN!R20+FEBRUARI!R20+MARET!R20 -> 6 | S20: =+JAN!S20+FEBRUARI!S20+MARET!S20 -> 1087 | T20: =J20-P20 -> 14 | U20: =L20+M20 -> 253 | V20: =$S20/$E20 -> 12.077778 | W20: =$V20/$F20*100 -> 80.518519 | X20: =$S20/($L20+$M20) -> 4.2964427 | Y20: =(($F20-$V20)*$E20)/($L20+$M20) -> 1.0395257 | Z20: =($L20+$M20)/$F20 -> 16.866667
C21: MELATI | E21: =+JAN!E21+FEBRUARI!E21+MARET!E21 -> 90 | F21: 34 | G21: =JAN!G21 -> 33 | H21: =+JAN!H21+FEBRUARI!H21+MARET!H21 -> 614 | I21: =+JAN!I21+FEBRUARI!I21+MARET!I21 -> 109 | J21: =+G21+H21+I21 -> 756 | K21: =+JAN!K21+FEBRUARI!K21+MARET!K21 -> 96 | L21: =+JAN!L21+FEBRUARI!L21+MARET!L21 -> 507 | M21: =+N21+O21 -> 122 | N21: =+JAN!N21+FEBRUARI!N21+MARET!N21 -> 70 | O21: =+JAN!O21+FEBRUARI!O21+MARET!O21 -> 52 | P21: =+K21+L21+M21 -> 725 | Q21: =+JAN!Q21+FEBRUARI!Q21+MARET!Q21 -> 2586 | R21: =+JAN!R21+FEBRUARI!R21+MARET!R21 -> 13 | S21: =+JAN!S21+FEBRUARI!S21+MARET!S21 -> 2660 | T21: =J21-P21 -> 31 | U21: =L21+M21 -> 629 | V21: =$S21/$E21 -> 29.555556 | W21: =$V21/$F21*100 -> 86.928105 | X21: =$S21/($L21+$M21) -> 4.2289348 | Y21: =(($F21-$V21)*$E21)/($L21+$M21) -> 0.63593005 | Z21: =($L21+$M21)/$F21 -> 18.5
A22: 6 | C22: SERUNI | D22: III | E22: =+JAN!E22+FEBRUARI!E22+MARET!E22 -> 90 | F22: 24 | G22: =JAN!G22 -> 18 | H22: =+JAN!H22+FEBRUARI!H22+MARET!H22 -> 456 | I22: =+JAN!I22+FEBRUARI!I22+MARET!I22 -> 32 | J22: =+G22+H22+I22 -> 506 | K22: =+JAN!K22+FEBRUARI!K22+MARET!K22 -> 31 | L22: =+JAN!L22+FEBRUARI!L22+MARET!L22 -> 436 | M22: =+N22+O22 -> 15 | N22: =+JAN!N22+FEBRUARI!N22+MARET!N22 -> 7 | O22: =+JAN!O22+FEBRUARI!O22+MARET!O22 -> 8 | P22: =+K22+L22+M22 -> 482 | Q22: =+JAN!Q22+FEBRUARI!Q22+MARET!Q22 -> 1430 | R22: =+JAN!R22+FEBRUARI!R22+MARET!R22 -> 4 | S22: =+JAN!S22+FEBRUARI!S22+MARET!S22 -> 1524 | T22: =J22-P22 -> 24 | U22: =L22+M22 -> 451 | V22: =$S22/$E22 -> 16.933333 | W22: =$V22/$F22*100 -> 70.555556 | X22: =$S22/($L22+$M22) -> 3.3791574 | Y22: =(($F22-$V22)*$E22)/($L22+$M22) -> 1.4101996 | Z22: =($L22+$M22)/$F22 -> 18.791667
C23: SERUNI | E23: =+JAN!E23+FEBRUARI!E23+MARET!E23 -> 90 | F23: 24 | G23: =JAN!G23 -> 18 | H23: =+JAN!H23+FEBRUARI!H23+MARET!H23 -> 456 | I23: =+JAN!I23+FEBRUARI!I23+MARET!I23 -> 32 | J23: =+G23+H23+I23 -> 506 | K23: =+JAN!K23+FEBRUARI!K23+MARET!K23 -> 31 | L23: =+JAN!L23+FEBRUARI!L23+MARET!L23 -> 436 | M23: =+N23+O23 -> 15 | N23: =+JAN!N23+FEBRUARI!N23+MARET!N23 -> 7 | O23: =+JAN!O23+FEBRUARI!O23+MARET!O23 -> 8 | P23: =+K23+L23+M23 -> 482 | Q23: =+JAN!Q23+FEBRUARI!Q23+MARET!Q23 -> 1430 | R23: =+JAN!R23+FEBRUARI!R23+MARET!R23 -> 4 | S23: =+JAN!S23+FEBRUARI!S23+MARET!S23 -> 1524 | T23: =J23-P23 -> 24 | U23: =L23+M23 -> 451 | V23: =$S23/$E23 -> 16.933333 | W23: =$V23/$F23*100 -> 70.555556 | X23: =$S23/($L23+$M23) -> 3.3791574 | Y23: =(($F23-$V23)*$E23)/($L23+$M23) -> 1.4101996 | Z23: =($L23+$M23)/$F23 -> 18.791667
A24: 7 | C24: MAWAR | D24: ISOLASI | E24: =+JAN!E24+FEBRUARI!E24+MARET!E24 -> 90 | F24: 4 | G24: =JAN!G24 -> 0 | H24: =+JAN!H24+FEBRUARI!H24+MARET!H24 -> 0 | I24: =+JAN!I24+FEBRUARI!I24+MARET!I24 -> 0 | J24: =+G24+H24+I24 -> 0 | K24: =+JAN!K24+FEBRUARI!K24+MARET!K24 -> 0 | L24: =+JAN!L24+FEBRUARI!L24+MARET!L24 -> 0 | M24: =+N24+O24 -> 0 | N24: =+JAN!N24+FEBRUARI!N24+MARET!N24 -> 0 | O24: =+JAN!O24+FEBRUARI!O24+MARET!O24 -> 0 | P24: =+K24+L24+M24 -> 0 | Q24: =+JAN!Q24+FEBRUARI!Q24+MARET!Q24 -> 0 | R24: =+JAN!R24+FEBRUARI!R24+MARET!R24 -> 0 | S24: =+JAN!S24+FEBRUARI!S24+MARET!S24 -> 0 | T24: =J24-P24 -> 0 | U24: =L24+M24 -> 0 | V24: =$S24/$E24 -> 0 | W24: =$V24/$F24*100 -> 0 | X24: =$S24/($L24+$M24) -> #DIV/0! | Y24: =(($F24-$V24)*$E24)/($L24+$M24) -> #DIV/0! | Z24: =($L24+$M24)/$F24 -> 0
C25: MAWAR | D25: III | E25: =+JAN!E25+FEBRUARI!E25+MARET!E25 -> 90 | F25: 16 | G25: =JAN!G25 -> 17 | H25: =+JAN!H25+FEBRUARI!H25+MARET!H25 -> 379 | I25: =+JAN!I25+FEBRUARI!I25+MARET!I25 -> 37 | J25: =+G25+H25+I25 -> 433 | K25: =+JAN!K25+FEBRUARI!K25+MARET!K25 -> 24 | L25: =+JAN!L25+FEBRUARI!L25+MARET!L25 -> 367 | M25: =+N25+O25 -> 24 | N25: =+JAN!N25+FEBRUARI!N25+MARET!N25 -> 10 | O25: =+JAN!O25+FEBRUARI!O25+MARET!O25 -> 14 | P25: =+K25+L25+M25 -> 415 | Q25: =+JAN!Q25+FEBRUARI!Q25+MARET!Q25 -> 1399 | R25: =+JAN!R25+FEBRUARI!R25+MARET!R25 -> 3 | S25: =+JAN!S25+FEBRUARI!S25+MARET!S25 -> 1405 | T25: =J25-P25 -> 18 | U25: =L25+M25 -> 391 | V25: =$S25/$E25 -> 15.611111 | W25: =$V25/$F25*100 -> 97.569444 | X25: =$S25/($L25+$M25) -> 3.5933504 | Y25: =(($F25-$V25)*$E25)/($L25+$M25) -> 0.089514066 | Z25: =($L25+$M25)/$F25 -> 24.4375
C26: MAWAR | E26: =+JAN!E26+FEBRUARI!E26+MARET!E26 -> 90 | F26: 20 | G26: =JAN!G26 -> 17 | H26: =+JAN!H26+FEBRUARI!H26+MARET!H26 -> 379 | I26: =+JAN!I26+FEBRUARI!I26+MARET!I26 -> 37 | J26: =+G26+H26+I26 -> 433 | K26: =+JAN!K26+FEBRUARI!K26+MARET!K26 -> 24 | L26: =+JAN!L26+FEBRUARI!L26+MARET!L26 -> 367 | M26: =+N26+O26 -> 24 | N26: =+JAN!N26+FEBRUARI!N26+MARET!N26 -> 10 | O26: =+JAN!O26+FEBRUARI!O26+MARET!O26 -> 14 | P26: =+K26+L26+M26 -> 415 | Q26: =+JAN!Q26+FEBRUARI!Q26+MARET!Q26 -> 1399 | R26: =+JAN!R26+FEBRUARI!R26+MARET!R26 -> 3 | S26: =+JAN!S26+FEBRUARI!S26+MARET!S26 -> 1405 | T26: =J26-P26 -> 18 | U26: =L26+M26 -> 391 | V26: =$S26/$E26 -> 15.611111 | W26: =$V26/$F26*100 -> 78.055556 | X26: =$S26/($L26+$M26) -> 3.5933504 | Y26: =(($F26-$V26)*$E26)/($L26+$M26) -> 1.0102302 | Z26: =($L26+$M26)/$F26 -> 19.55
A27: 8 | C27: GARDENA | D27: III | E27: =+JAN!E27+FEBRUARI!E27+MARET!E27 -> 90 | F27: 20 | G27: =JAN!G27 -> 17 | H27: =+JAN!H27+FEBRUARI!H27+MARET!H27 -> 454 | I27: =+JAN!I27+FEBRUARI!I27+MARET!I27 -> 18 | J27: =+G27+H27+I27 -> 489 | K27: =+JAN!K27+FEBRUARI!K27+MARET!K27 -> 31 | L27: =+JAN!L27+FEBRUARI!L27+MARET!L27 -> 417 | M27: =+N27+O27 -> 21 | N27: =+JAN!N27+FEBRUARI!N27+MARET!N27 -> 15 | O27: =+JAN!O27+FEBRUARI!O27+MARET!O27 -> 6 | P27: =+K27+L27+M27 -> 469 | Q27: =+JAN!Q27+FEBRUARI!Q27+MARET!Q27 -> 1390 | R27: =+JAN!R27+FEBRUARI!R27+MARET!R27 -> 5 | S27: =+JAN!S27+FEBRUARI!S27+MARET!S27 -> 1397 | T27: =J27-P27 -> 20 | U27: =L27+M27 -> 438 | V27: =$S27/$E27 -> 15.522222 | W27: =$V27/$F27*100 -> 77.611111 | X27: =$S27/($L27+$M27) -> 3.1894977 | Y27: =(($F27-$V27)*$E27)/($L27+$M27) -> 0.92009132 | Z27: =($L27+$M27)/$F27 -> 21.9
C28: GARDENA | E28: =+JAN!E28+FEBRUARI!E28+MARET!E28 -> 90 | F28: 20 | G28: =JAN!G28 -> 17 | H28: =+JAN!H28+FEBRUARI!H28+MARET!H28 -> 454 | I28: =+JAN!I28+FEBRUARI!I28+MARET!I28 -> 18 | J28: =+G28+H28+I28 -> 489 | K28: =+JAN!K28+FEBRUARI!K28+MARET!K28 -> 31 | L28: =+JAN!L28+FEBRUARI!L28+MARET!L28 -> 417 | M28: =+N28+O28 -> 21 | N28: =+JAN!N28+FEBRUARI!N28+MARET!N28 -> 15 | O28: =+JAN!O28+FEBRUARI!O28+MARET!O28 -> 6 | P28: =+K28+L28+M28 -> 469 | Q28: =+JAN!Q28+FEBRUARI!Q28+MARET!Q28 -> 1390 | R28: =+JAN!R28+FEBRUARI!R28+MARET!R28 -> 5 | S28: =+JAN!S28+FEBRUARI!S28+MARET!S28 -> 1397 | T28: =J28-P28 -> 20 | U28: =L28+M28 -> 438 | V28: =$S28/$E28 -> 15.522222 | W28: =$V28/$F28*100 -> 77.611111 | X28: =$S28/($L28+$M28) -> 3.1894977 | Y28: =(($F28-$V28)*$E28)/($L28+$M28) -> 0.92009132 | Z28: =($L28+$M28)/$F28 -> 21.9
C29: BOGENVILE | D29: ISOLASI | E29: =+JAN!E29+FEBRUARI!E29+MARET!E29 -> 90 | F29: 1 | G29: =JAN!G29 -> 0 | H29: =+JAN!H29+FEBRUARI!H29+MARET!H29 -> 0 | I29: =+JAN!I29+FEBRUARI!I29+MARET!I29 -> 0 | J29: =+G29+H29+I29 -> 0 | K29: =+JAN!K29+FEBRUARI!K29+MARET!K29 -> 0 | L29: =+JAN!L29+FEBRUARI!L29+MARET!L29 -> 0 | M29: =+N29+O29 -> 0 | N29: =+JAN!N29+FEBRUARI!N29+MARET!N29 -> 0 | O29: =+JAN!O29+FEBRUARI!O29+MARET!O29 -> 0 | P29: =+K29+L29+M29 -> 0 | Q29: =+JAN!Q29+FEBRUARI!Q29+MARET!Q29 -> 0 | R29: =+JAN!R29+FEBRUARI!R29+MARET!R29 -> 0 | S29: =+JAN!S29+FEBRUARI!S29+MARET!S29 -> 0 | T29: =J29-P29 -> 0 | U29: =L29+M29 -> 0 | V29: =$S29/$E29 -> 0 | W29: =$V29/$F29*100 -> 0 | X29: =$S29/($L29+$M29) -> #DIV/0! | Y29: =(($F29-$V29)*$E29)/($L29+$M29) -> #DIV/0! | Z29: =($L29+$M29)/$F29 -> 0
A30: 9 | C30: BOGENVILE | D30: I | E30: =+JAN!E30+FEBRUARI!E30+MARET!E30 -> 90 | F30: 3 | G30: =JAN!G30 -> 4 | H30: =+JAN!H30+FEBRUARI!H30+MARET!H30 -> 83 | I30: =+JAN!I30+FEBRUARI!I30+MARET!I30 -> 31 | J30: =+G30+H30+I30 -> 118 | K30: =+JAN!K30+FEBRUARI!K30+MARET!K30 -> 19 | L30: =+JAN!L30+FEBRUARI!L30+MARET!L30 -> 94 | M30: =+N30+O30 -> 3 | N30: =+JAN!N30+FEBRUARI!N30+MARET!N30 -> 2 | O30: =+JAN!O30+FEBRUARI!O30+MARET!O30 -> 1 | P30: =+K30+L30+M30 -> 116 | Q30: =+JAN!Q30+FEBRUARI!Q30+MARET!Q30 -> 319 | R30: =+JAN!R30+FEBRUARI!R30+MARET!R30 -> 2 | S30: =+JAN!S30+FEBRUARI!S30+MARET!S30 -> 320 | T30: =J30-P30 -> 2 | U30: =L30+M30 -> 97 | V30: =$S30/$E30 -> 3.5555556 | W30: =$V30/$F30*100 -> 118.51852 | X30: =$S30/($L30+$M30) -> 3.2989691 | Y30: =(($F30-$V30)*$E30)/($L30+$M30) -> -0.51546392 | Z30: =($L30+$M30)/$F30 -> 32.333333
C31: BOGENVILE | D31: PAV | E31: =+JAN!E31+FEBRUARI!E31+MARET!E31 -> 90 | F31: 8 | G31: =JAN!G31 -> 6 | H31: =+JAN!H31+FEBRUARI!H31+MARET!H31 -> 99 | I31: =+JAN!I31+FEBRUARI!I31+MARET!I31 -> 29 | J31: =+G31+H31+I31 -> 134 | K31: =+JAN!K31+FEBRUARI!K31+MARET!K31 -> 32 | L31: =+JAN!L31+FEBRUARI!L31+MARET!L31 -> 89 | M31: =+N31+O31 -> 9 | N31: =+JAN!N31+FEBRUARI!N31+MARET!N31 -> 4 | O31: =+JAN!O31+FEBRUARI!O31+MARET!O31 -> 5 | P31: =+K31+L31+M31 -> 130 | Q31: =+JAN!Q31+FEBRUARI!Q31+MARET!Q31 -> 347 | R31: =+JAN!R31+FEBRUARI!R31+MARET!R31 -> 1 | S31: =+JAN!S31+FEBRUARI!S31+MARET!S31 -> 337 | T31: =J31-P31 -> 4 | U31: =L31+M31 -> 98 | V31: =$S31/$E31 -> 3.7444444 | W31: =$V31/$F31*100 -> 46.805556 | X31: =$S31/($L31+$M31) -> 3.4387755 | Y31: =(($F31-$V31)*$E31)/($L31+$M31) -> 3.9081633 | Z31: =($L31+$M31)/$F31 -> 12.25
C32: BOGENVILE | E32: =+JAN!E32+FEBRUARI!E32+MARET!E32 -> 90 | F32: 12 | G32: =JAN!G32 -> 10 | H32: =+JAN!H32+FEBRUARI!H32+MARET!H32 -> 182 | I32: =+JAN!I32+FEBRUARI!I32+MARET!I32 -> 60 | J32: =+G32+H32+I32 -> 252 | K32: =+JAN!K32+FEBRUARI!K32+MARET!K32 -> 51 | L32: =+JAN!L32+FEBRUARI!L32+MARET!L32 -> 183 | M32: =+N32+O32 -> 12 | N32: =+JAN!N32+FEBRUARI!N32+MARET!N32 -> 6 | O32: =+JAN!O32+FEBRUARI!O32+MARET!O32 -> 6 | P32: =+K32+L32+M32 -> 246 | Q32: =+JAN!Q32+FEBRUARI!Q32+MARET!Q32 -> 666 | R32: =+JAN!R32+FEBRUARI!R32+MARET!R32 -> 3 | S32: =+JAN!S32+FEBRUARI!S32+MARET!S32 -> 657 | T32: =J32-P32 -> 6 | U32: =L32+M32 -> 195 | V32: =$S32/$E32 -> 7.3 | W32: =$V32/$F32*100 -> 60.833333 | X32: =$S32/($L32+$M32) -> 3.3692308 | Y32: =(($F32-$V32)*$E32)/($L32+$M32) -> 2.1692308 | Z32: =($L32+$M32)/$F32 -> 16.25
A33: 10 | C33: ALAMANDA | D33: ISOLASI | E33: =+JAN!E33+FEBRUARI!E33+MARET!E33 -> 90 | F33: 1 | G33: =JAN!G33 -> 0 | H33: =+JAN!H33+FEBRUARI!H33+MARET!H33 -> 9 | I33: =+JAN!I33+FEBRUARI!I33+MARET!I33 -> 1 | J33: =+G33+H33+I33 -> 10 | K33: =+JAN!K33+FEBRUARI!K33+MARET!K33 -> 2 | L33: =+JAN!L33+FEBRUARI!L33+MARET!L33 -> 7 | M33: =+N33+O33 -> 0 | N33: =+JAN!N33+FEBRUARI!N33+MARET!N33 -> 0 | O33: =+JAN!O33+FEBRUARI!O33+MARET!O33 -> 0 | P33: =+K33+L33+M33 -> 9 | Q33: =+JAN!Q33+FEBRUARI!Q33+MARET!Q33 -> 21 | R33: =+JAN!R33+FEBRUARI!R33+MARET!R33 -> 0 | S33: =+JAN!S33+FEBRUARI!S33+MARET!S33 -> 21 | T33: =J33-P33 -> 1 | U33: =L33+M33 -> 7 | V33: =$S33/$E33 -> 0.23333333 | W33: =$V33/$F33*100 -> 23.333333 | X33: =$S33/($L33+$M33) -> 3 | Y33: =(($F33-$V33)*$E33)/($L33+$M33) -> 9.8571429 | Z33: =($L33+$M33)/$F33 -> 7
C34: ALAMANDA | D34: I | E34: =+JAN!E34+FEBRUARI!E34+MARET!E34 -> 90 | F34: 2 | G34: =JAN!G34 -> 3 | H34: =+JAN!H34+FEBRUARI!H34+MARET!H34 -> 37 | I34: =+JAN!I34+FEBRUARI!I34+MARET!I34 -> 9 | J34: =+G34+H34+I34 -> 49 | K34: =+JAN!K34+FEBRUARI!K34+MARET!K34 -> 4 | L34: =+JAN!L34+FEBRUARI!L34+MARET!L34 -> 40 | M34: =+N34+O34 -> 3 | N34: =+JAN!N34+FEBRUARI!N34+MARET!N34 -> 1 | O34: =+JAN!O34+FEBRUARI!O34+MARET!O34 -> 2 | P34: =+K34+L34+M34 -> 47 | Q34: =+JAN!Q34+FEBRUARI!Q34+MARET!Q34 -> 165 | R34: =+JAN!R34+FEBRUARI!R34+MARET!R34 -> 0 | S34: =+JAN!S34+FEBRUARI!S34+MARET!S34 -> 185 | T34: =J34-P34 -> 2 | U34: =L34+M34 -> 43 | V34: =$S34/$E34 -> 2.0555556 | W34: =$V34/$F34*100 -> 102.77778 | X34: =$S34/($L34+$M34) -> 4.3023256 | Y34: =(($F34-$V34)*$E34)/($L34+$M34) -> -0.11627907 | Z34: =($L34+$M34)/$F34 -> 21.5
C35: ALAMANDA | D35: II | E35: =+JAN!E35+FEBRUARI!E35+MARET!E35 -> 90 | F35: 4 | G35: =JAN!G35 -> 4 | H35: =+JAN!H35+FEBRUARI!H35+MARET!H35 -> 63 | I35: =+JAN!I35+FEBRUARI!I35+MARET!I35 -> 9 | J35: =+G35+H35+I35 -> 76 | K35: =+JAN!K35+FEBRUARI!K35+MARET!K35 -> 3 | L35: =+JAN!L35+FEBRUARI!L35+MARET!L35 -> 65 | M35: =+N35+O35 -> 4 | N35: =+JAN!N35+FEBRUARI!N35+MARET!N35 -> 3 | O35: =+JAN!O35+FEBRUARI!O35+MARET!O35 -> 1 | P35: =+K35+L35+M35 -> 72 | Q35: =+JAN!Q35+FEBRUARI!Q35+MARET!Q35 -> 276 | R35: =+JAN!R35+FEBRUARI!R35+MARET!R35 -> 2 | S35: =+JAN!S35+FEBRUARI!S35+MARET!S35 -> 295 | T35: =J35-P35 -> 4 | U35: =L35+M35 -> 69 | V35: =$S35/$E35 -> 3.2777778 | W35: =$V35/$F35*100 -> 81.944444 | X35: =$S35/($L35+$M35) -> 4.2753623 | Y35: =(($F35-$V35)*$E35)/($L35+$M35) -> 0.94202899 | Z35: =($L35+$M35)/$F35 -> 17.25
C36: ALAMANDA | D36: III | E36: =+JAN!E36+FEBRUARI!E36+MARET!E36 -> 90 | F36: 12 | G36: =JAN!G36 -> 7 | H36: =+JAN!H36+FEBRUARI!H36+MARET!H36 -> 212 | I36: =+JAN!I36+FEBRUARI!I36+MARET!I36 -> 25 | J36: =+G36+H36+I36 -> 244 | K36: =+JAN!K36+FEBRUARI!K36+MARET!K36 -> 6 | L36: =+JAN!L36+FEBRUARI!L36+MARET!L36 -> 206 | M36: =+N36+O36 -> 17 | N36: =+JAN!N36+FEBRUARI!N36+MARET!N36 -> 7 | O36: =+JAN!O36+FEBRUARI!O36+MARET!O36 -> 10 | P36: =+K36+L36+M36 -> 229 | Q36: =+JAN!Q36+FEBRUARI!Q36+MARET!Q36 -> 842 | R36: =+JAN!R36+FEBRUARI!R36+MARET!R36 -> 2 | S36: =+JAN!S36+FEBRUARI!S36+MARET!S36 -> 859 | T36: =J36-P36 -> 15 | U36: =L36+M36 -> 223 | V36: =$S36/$E36 -> 9.5444444 | W36: =$V36/$F36*100 -> 79.537037 | X36: =$S36/($L36+$M36) -> 3.8520179 | Y36: =(($F36-$V36)*$E36)/($L36+$M36) -> 0.99103139 | Z36: =($L36+$M36)/$F36 -> 18.583333
C37: ALAMANDA | E37: =+JAN!E37+FEBRUARI!E37+MARET!E37 -> 90 | F37: 19 | G37: =JAN!G37 -> 14 | H37: =+JAN!H37+FEBRUARI!H37+MARET!H37 -> 321 | I37: =+JAN!I37+FEBRUARI!I37+MARET!I37 -> 44 | J37: =+G37+H37+I37 -> 379 | K37: =+JAN!K37+FEBRUARI!K37+MARET!K37 -> 15 | L37: =+JAN!L37+FEBRUARI!L37+MARET!L37 -> 318 | M37: =+N37+O37 -> 24 | N37: =+JAN!N37+FEBRUARI!N37+MARET!N37 -> 11 | O37: =+JAN!O37+FEBRUARI!O37+MARET!O37 -> 13 | P37: =+K37+L37+M37 -> 357 | Q37: =+JAN!Q37+FEBRUARI!Q37+MARET!Q37 -> 1304 | R37: =+JAN!R37+FEBRUARI!R37+MARET!R37 -> 4 | S37: =+JAN!S37+FEBRUARI!S37+MARET!S37 -> 1360 | T37: =J37-P37 -> 22 | U37: =L37+M37 -> 342 | V37: =$S37/$E37 -> 15.111111 | W37: =$V37/$F37*100 -> 79.532164 | X37: =$S37/($L37+$M37) -> 3.9766082 | Y37: =(($F37-$V37)*$E37)/($L37+$M37) -> 1.0233918 | Z37: =($L37+$M37)/$F37 -> 18
A38: 11 | C38: CATHALIA | D38: CA ISOLASI | E38: =+JAN!E38+FEBRUARI!E38+MARET!E38 -> 90 | F38: 6 | G38: =JAN!G38 -> 4 | H38: =+JAN!H38+FEBRUARI!H38+MARET!H38 -> 114 | I38: =+JAN!I38+FEBRUARI!I38+MARET!I38 -> 22 | J38: =+G38+H38+I38 -> 140 | K38: =+JAN!K38+FEBRUARI!K38+MARET!K38 -> 29 | L38: =+JAN!L38+FEBRUARI!L38+MARET!L38 -> 101 | M38: =+N38+O38 -> 10 | N38: =+JAN!N38+FEBRUARI!N38+MARET!N38 -> 3 | O38: =+JAN!O38+FEBRUARI!O38+MARET!O38 -> 7 | P38: =+K38+L38+M38 -> 140 | Q38: =+JAN!Q38+FEBRUARI!Q38+MARET!Q38 -> 316 | R38: =+JAN!R38+FEBRUARI!R38+MARET!R38 -> 0 | S38: =+JAN!S38+FEBRUARI!S38+MARET!S38 -> 458 | T38: =J38-P38 -> 0 | U38: =L38+M38 -> 111 | V38: =$S38/$E38 -> 5.0888889 | W38: =$V38/$F38*100 -> 84.814815 | X38: =$S38/($L38+$M38) -> 4.1261261 | Y38: =(($F38-$V38)*$E38)/($L38+$M38) -> 0.73873874 | Z38: =($L38+$M38)/$F38 -> 18.5
C39: CATHALIA | D39: CATALYA ATAS | E39: =+JAN!E39+FEBRUARI!E39+MARET!E39 -> 90 | F39: 8 | G39: =JAN!G39 -> 4 | H39: =+JAN!H39+FEBRUARI!H39+MARET!H39 -> 146 | I39: =+JAN!I39+FEBRUARI!I39+MARET!I39 -> 39 | J39: =+G39+H39+I39 -> 189 | K39: =+JAN!K39+FEBRUARI!K39+MARET!K39 -> 20 | L39: =+JAN!L39+FEBRUARI!L39+MARET!L39 -> 145 | M39: =+N39+O39 -> 11 | N39: =+JAN!N39+FEBRUARI!N39+MARET!N39 -> 3 | O39: =+JAN!O39+FEBRUARI!O39+MARET!O39 -> 8 | P39: =+K39+L39+M39 -> 176 | Q39: =+JAN!Q39+FEBRUARI!Q39+MARET!Q39 -> 479 | R39: =+JAN!R39+FEBRUARI!R39+MARET!R39 -> 3 | S39: =+JAN!S39+FEBRUARI!S39+MARET!S39 -> 420 | T39: =J39-P39 -> 13 | U39: =L39+M39 -> 156 | V39: =$S39/$E39 -> 4.6666667 | W39: =$V39/$F39*100 -> 58.333333 | X39: =$S39/($L39+$M39) -> 2.6923077 | Y39: =(($F39-$V39)*$E39)/($L39+$M39) -> 1.9230769 | Z39: =($L39+$M39)/$F39 -> 19.5
C40: CATHALIA | D40: CATALYA BAWAH | E40: =+JAN!E40+FEBRUARI!E40+MARET!E40 -> 90 | F40: 14 | G40: =JAN!G40 -> 8 | H40: =+JAN!H40+FEBRUARI!H40+MARET!H40 -> 206 | I40: =+JAN!I40+FEBRUARI!I40+MARET!I40 -> 28 | J40: =+G40+H40+I40 -> 242 | K40: =+JAN!K40+FEBRUARI!K40+MARET!K40 -> 30 | L40: =+JAN!L40+FEBRUARI!L40+MARET!L40 -> 183 | M40: =+N40+O40 -> 15 | N40: =+JAN!N40+FEBRUARI!N40+MARET!N40 -> 10 | O40: =+JAN!O40+FEBRUARI!O40+MARET!O40 -> 5 | P40: =+K40+L40+M40 -> 228 | Q40: =+JAN!Q40+FEBRUARI!Q40+MARET!Q40 -> 672 | R40: =+JAN!R40+FEBRUARI!R40+MARET!R40 -> 4 | S40: =+JAN!S40+FEBRUARI!S40+MARET!S40 -> 672 | T40: =J40-P40 -> 14 | U40: =L40+M40 -> 198 | V40: =$S40/$E40 -> 7.4666667 | W40: =$V40/$F40*100 -> 53.333333 | X40: =$S40/($L40+$M40) -> 3.3939394 | Y40: =(($F40-$V40)*$E40)/($L40+$M40) -> 2.969697 | Z40: =($L40+$M40)/$F40 -> 14.142857
G41: =JAN!G41 -> 0 | H41: =+JAN!H41+FEBRUARI!H41+MARET!H41 -> 0 | I41: =+JAN!I41+FEBRUARI!I41+MARET!I41 -> 0 | J41: =+G41+H41+I41 -> 0 | K41: =+JAN!K41+FEBRUARI!K41+MARET!K41 -> 0 | L41: =+JAN!L41+FEBRUARI!L41+MARET!L41 -> 0 | M41: =+N41+O41 -> 0 | N41: =+JAN!N41+FEBRUARI!N41+MARET!N41 -> 0 | O41: =+JAN!O41+FEBRUARI!O41+MARET!O41 -> 0 | P41: =+K41+L41+M41 -> 0 | Q41: =+JAN!Q41+FEBRUARI!Q41+MARET!Q41 -> 0 | R41: =+JAN!R41+FEBRUARI!R41+MARET!R41 -> 0 | S41: =+JAN!S41+FEBRUARI!S41+MARET!S41 -> 0 | T41: =J41-P41 -> 0 | U41: =L41+M41 -> 0 | V41: =$S41/$E41 -> #DIV/0! | W41: =$V41/$F41*100 -> #DIV/0! | X41: =$S41/($L41+$M41) -> #DIV/0! | Y41: =(($F41-$V41)*$E41)/($L41+$M41) -> #DIV/0! | Z41: =($L41+$M41)/$F41 -> #DIV/0!
...

Sheet APRIL
A1: DATA PELAYANAN RI RSD Dr.SOEBANDI JEMBER
A2: BULAN : APRIL 2026 | V2: s/e | W2: v/f*100 | X2: S/L+M | Y2: ((F-V)*E)/(LM) | Z2: L+M/F
