Workbook

Sheet JAN
A1: DATA PELAYANAN RI RSD Dr.SOEBANDI JEMBER
A2: BULAN : JANUARI 2026
A3: NO | B3: PELAYANAN | C3: RAWAT INAP | D3: KLAS PERAWATAN | E3: PERIODE | F3: TT (T) | G3: PX AWAL | H3: PX MASUK | I3: PX PINDAHAN | J3: JUMLAH (1+2+3) | K3: PX DI PINDAHKAN | L3: PX KELUAR HIDUP | M3: PX MATI | N3: KURANG 48 JAM | O3: LEBIH 48 JAM | P3: JUMLAH (5+6+7) | Q3: LAMA DI RAWAT | R3: PX KELUAR/MASUK HR SAMA | S3: HARI PERAWATAN | T3: Px AKHIR | U3: KUNJUNGN | V3: O | W3: BOR (O/T) | X3: LOS | Y3: TOI | Z3: BTO
V4: (TT terpakai) | W4: (75%-85%) | X4: (3-12 hari) | Y4: (1-3 hr) | Z4: (30 px)
G6: 1 | H6: 2 | I6: 3 | J6: 4 | K6: 5 | L6: 6 | M6: 7 | N6: 8 | O6: 9 | P6: 10 | Q6: 11 | R6: 12 | S6: 13 | T6: 14 | V6: 15 | W6: 16 | X6: 17 | Y6: 18 | Z6: 19
A7: 1 | B7: INTENSIVE | C7: ICU | D7: I | E7: 31 | F7: 14 | G7: 17 | H7: 12 | I7: 88 | J7: 117 | K7: 93 | L7: 0 | M7: 18 | N7: 2 | O7: 16 | P7: 111 | Q7: 117 | R7: 0 | S7: 348 | T7: 6 | U7: 18 | V7: 11.225806 | W7: 80.184332 | X7: 19.333333 | Y7: 4.7777778 | Z7: 1.2857143
C8: ICU | D8: I | E8: 31 | F8: 14 | G8: 17 | H8: 12 | I8: 88 | J8: 117 | K8: 93 | L8: 0 | M8: 18 | N8: 2 | O8: 16 | P8: 111 | Q8: 117 | R8: 0 | S8: 348 | T8: 6 | U8: 18 | V8: 11.225806 | W8: 80.184332 | X8: 19.333333 | Y8: 4.7777778 | Z8: 1.2857143
A9: 2 | C9: ICCU | D9: I | E9: 31 | F9: 5 | G9: 2 | H9: 71 | I9: 10 | J9: 83 | K9: 77 | L9: 0 | M9: 1 | N9: 1 | O9: 0 | P9: 78 | Q9: 1 | R9: 1 | S9: 114 | T9: 5 | U9: 1 | V9: 3.6774194 | W9: 73.548387 | X9: 114 | Y9: 41 | Z9: 0.2
C10: ICCU | D10: I | E10: 31 | F10: 5 | G10: 2 | H10: 71 | I10: 10 | J10: 83 | K10: 77 | L10: 0 | M10: 1 | N10: 1 | O10: 0 | P10: 78 | Q10: 1 | R10: 1 | S10: 114 | T10: 5 | U10: 1 | V10: 3.6774194 | W10: 73.548387 | X10: 114 | Y10: 41 | Z10: 0.2
A11: 3 | C11: PICU | D11: I | E11: 31 | F11: 3 | G11: 2 | H11: 15 | I11: 9 | J11: 26 | K11: 19 | L11: 1 | M11: 3 | N11: 1 | O11: 2 | P11: 23 | Q11: 35 | R11: 0 | S11: 67 | T11: 3 | U11: 4 | V11: 2.1612903 | W11: 72.043011 | X11: 16.75 | Y11: 6.5 | Z11: 1.3333333
C12: PICU | D12: I | E12: 31 | F12: 3 | G12: 2 | H12: 15 | I12: 9 | J12: 26 | K12: 19 | L12: 1 | M12: 3 | N12: 1 | O12: 2 | P12: 23 | Q12: 35 | R12: 0 | S12: 67 | T12: 3 | U12: 4 | V12: 2.1612903 | W12: 72.043011 | X12: 16.75 | Y12: 6.5 | Z12: 1.3333333
A13: 4 | C13: NICU | D13: I | E13: 31 | F13: 5 | G13: 5 | H13: 13 | I13: 18 | J13: 36 | K13: 24 | L13: 0 | M13: 7 | N13: 1 | O13: 6 | P13: 31 | Q13: 50 | R13: 0 | S13: 117 | T13: 5 | U13: 7 | V13: 3.7741935 | W13: 75.483871 | X13: 16.714286 | Y13: 5.4285714 | Z13: 1.4
C14: NICU | D14: I | E14: 31 | F14: 5 | G14: 5 | H14: 13 | I14: 18 | J14: 36 | K14: 24 | L14: 0 | M14: 7 | N14: 1 | O14: 6 | P14: 31 | Q14: 50 | R14: 0 | S14: 117 | T14: 5 | U14: 7 | V14: 3.7741935 | W14: 75.483871 | X14: 16.714286 | Y14: 5.4285714 | Z14: 1.4
A15: 5 | C15: ICU MEDICAL | D15: I | E15: 31 | F15: 4 | G15: 3 | H15: 33 | I15: 15 | J15: 51 | K15: 31 | L15: 1 | M15: 16 | N15: 10 | O15: 6 | P15: 48 | Q15: 35 | R15: 4 | S15: 85 | T15: 3 | U15: 17 | V15: 2.7419355 | W15: 68.548387 | X15: 5 | Y15: 2.2941176 | Z15: 4.25
C16: ICU MEDICAL | D16: I | E16: 31 | F16: 4 | G16: 3 | H16: 33 | I16: 15 | J16: 51 | K16: 31 | L16: 1 | M16: 16 | N16: 10 | O16: 6 | P16: 48 | Q16: 35 | R16: 4 | S16: 85 | T16: 3 | U16: 17 | V16: 2.7419355 | W16: 68.548387 | X16: 5 | Y16: 2.2941176 | Z16: 4.25
A17: 6 | C17: RICU ED | D17: I | E17: 31 | F17: 2 | G17: 0 | H17: 7 | I17: 5 | J17: 12 | K17: 7 | L17: 0 | M17: 4 | N17: 2 | O17: 2 | P17: 11 | Q17: 13 | R17: 2 | S17: 40 | T17: 1 | U17: 4 | V17: 1.2903226 | W17: 64.516129 | X17: 10 | Y17: 5.5 | Z17: 2
C18: RICU ED | E18: 31 | F18: 2 | G18: 0 | H18: 7 | I18: 5 | J18: 12 | K18: 7 | L18: 0 | M18: 4 | N18: 2 | O18: 2 | P18: 11 | Q18: 13 | R18: 2 | S18: 40 | T18: 1 | U18: 4 | V18: 1.2903226 | W18: 64.516129 | X18: 10 | Y18: 5.5 | Z18: 2
A19: 7 | C19: HCU MELATI BAWAH | D19: II | E19: 31 | F19: 12 | G19: 12 | H19: 81 | I19: 31 | J19: 124 | K19: 22 | L19: 71 | M19: 19 | N19: 11 | O19: 8 | P19: 112 | Q19: 314 | R19: 0 | S19: 367 | T19: 12 | U19: 90 | V19: 11.83871 | W19: 98.655914 | X19: 4.0777778 | Y19: 0.055555556 | Z19: 7.5
C20: HCU MELATI BAWAH | D20: II | E20: 31 | F20: 12 | G20: 12 | H20: 81 | I20: 31 | J20: 124 | K20: 22 | L20: 71 | M20: 19 | N20: 11 | O20: 8 | P20: 112 | Q20: 314 | R20: 0 | S20: 367 | T20: 12 | U20: 90 | V20: 11.83871 | W20: 98.655914 | X20: 4.0777778 | Y20: 0.055555556 | Z20: 7.5
A21: TOTAL INTENSIVE | E21: 31 | F21: 45 | G21: 41 | H21: 232 | I21: 176 | J21: 449 | K21: 273 | L21: 73 | M21: 68 | N21: 28 | O21: 40 | P21: 414 | Q21: 565 | R21: 7 | S21: 1138 | T21: 35 | U21: 141 | V21: 36.709677 | W21: 81.577061 | X21: 8.070922 | Y21: 1.822695 | Z21: 3.1333333
A24: NO | B24: PELAYANAN | C24: RAWAT INAP | D24: KLAS PERAWATAN | E24: PERIODE | F24: TT (T) | G24: PX AWAL | H24: PX MASUK | I24: PX PINDAHAN | J24: JUMLAH (1+2+3) | K24: PX DI PINDAHKAN | L24: PX KELUAR HIDUP | M24: PX MATI | N24: KURANG 48 JAM | O24: LEBIH 48 JAM | P24: JUMLAH (5+6+7) | Q24: LAMA DI RAWAT | R24: PX KELUAR/MASUK HR SAMA | S24: HARI PERAWATAN | T24: Px AKHIR | U24: KUNJUNGN | V24: O | W24: BOR (O/T) | X24: LOS | Y24: TOI | Z24: BTO
V25: (TT terpakai) | W25: (75%-85%) | X25: (3-12 hari) | Y25: (1-3 hr) | Z25: (30 px)
G27: 1 | H27: 2 | I27: 3 | J27: 4 | K27: 5 | L27: 6 | M27: 7 | N27: 8 | O27: 9 | P27: 10 | Q27: 11 | R27: 12 | S27: 13 | T27: 14 | V27: 15 | W27: 16 | X27: 17 | Y27: 18 | Z27: 19
A28: 1 | B28: ISOLASI | C28: SAKURA | D28: TB MDR II | E28: 31 | F28: 2 | G28: 0 | H28: 4 | I28: 1 | J28: 5 | K28: 1 | L28: 1 | M28: 3 | N28: 2 | O28: 1 | P28: 5 | Q28: 11 | R28: 0 | S28: 6 | T28: 0 | U28: 4 | V28: 0.19354839 | W28: 9.6774194 | X28: 1.5 | Y28: 14 | Z28: 2
C29: SAKURA | D29: TB MDR III | E29: 31 | F29: 3 | G29: 1 | H29: 9 | I29: 0 | J29: 10 | K29: 0 | L29: 8 | M29: 2 | N29: 0 | O29: 2 | P29: 10 | Q29: 50 | R29: 0 | S29: 34 | T29: 0 | U29: 10 | V29: 1.0967742 | W29: 36.55914 | X29: 3.4 | Y29: 5.9 | Z29: 3.3333333
C30: SAKURA | D30: TB PARU II | E30: 31 | F30: 2 | G30: 0 | H30: 3 | I30: 2 | J30: 5 | K30: 0 | L30: 1 | M30: 4 | N30: 3 | O30: 1 | P30: 5 | Q30: 41 | R30: 0 | S30: 30 | T30: 0 | U30: 5 | V30: 0.96774194 | W30: 48.387097 | X30: 6 | Y30: 6.4 | Z30: 2.5
C31: SAKURA | D31: TB PARU III | E31: 31 | F31: 10 | G31: 2 | H31: 43 | I31: 12 | J31: 57 | K31: 3 | L31: 34 | M31: 15 | N31: 6 | O31: 9 | P31: 52 | Q31: 226 | R31: 0 | S31: 204 | T31: 5 | U31: 49 | V31: 6.5806452 | W31: 65.806452 | X31: 4.1632653 | Y31: 2.1632653 | Z31: 4.9
C32: SAKURA | E32: 31 | F32: 17 | G32: 3 | H32: 59 | I32: 15 | J32: 77 | K32: 4 | L32: 44 | M32: 24 | N32: 11 | O32: 13 | P32: 72 | Q32: 328 | R32: 0 | S32: 274 | T32: 5 | U32: 68 | V32: 8.8387097 | W32: 51.99241 | X32: 4.0294118 | Y32: 3.7205882 | Z32: 4
A33: 2 | C33: CATALYA | D33: ISOLASI | E33: 31 | F33: 6 | G33: 4 | H33: 47 | I33: 10 | J33: 61 | K33: 13 | L33: 37 | M33: 3 | N33: 1 | O33: 2 | P33: 53 | Q33: 115 | R33: 0 | S33: 179 | T33: 8 | U33: 40 | V33: 5.7741935 | W33: 96.236559 | X33: 4.475 | Y33: 0.175 | Z33: 6.6666667
C34: CATALYA | E34: 31 | F34: 6 | G34: 4 | H34: 47 | I34: 10 | J34: 61 | K34: 13 | L34: 37 | M34: 3 | N34: 1 | O34: 2 | P34: 53 | Q34: 115 | R34: 0 | S34: 179 | T34: 8 | U34: 40 | V34: 5.7741935 | W34: 96.236559 | X34: 4.475 | Y34: 0.175 | Z34: 6.6666667
A35: 3 | C35: LAVENDER | D35: III | E35: 31 | F35: 4 | G35: 0 | H35: 0 | I35: 0 | J35: 0 | K35: 0 | L35: 0 | M35: 0 | N35: 0 | O35: 0 | P35: 0 | Q35: 0 | R35: 0 | S35: 0 | T35: 0 | U35: 0 | V35: 0 | W35: 0 | X35: #DIV/0! | Y35: #DIV/0! | Z35: 0
C36: LAVENDER | E36: 31 | F36: 4 | G36: 0 | H36: 0 | I36: 0 | J36: 0 | K36: 0 | L36: 0 | M36: 0 | N36: 0 | O36: 0 | P36: 0 | Q36: 0 | R36: 0 | S36: 0 | T36: 0 | U36: 0 | V36: 0 | W36: 0 | X36: #DIV/0! | Y36: #DIV/0! | Z36: 0
A37: 4 | C37: NUSA INDAH | D37: I | E37: 31 | F37: 2 | G37: 0 | H37: 0 | I37: 0 | J37: 0 | K37: 0 | L37: 0 | M37: 0 | N37: 0 | O37: 0 | P37: 0 | Q37: 0 | R37: 0 | S37: 0 | T37: 0 | U37: 0 | V37: 0 | W37: 0 | X37: #DIV/0! | Y37: #DIV/0! | Z37: 0
C38: NUSA INDAH | E38: 31 | F38: 2 | G38: 0 | H38: 0 | I38: 0 | J38: 0 | K38: 0 | L38: 0 | M38: 0 | N38: 0 | O38: 0 | P38: 0 | Q38: 0 | R38: 0 | S38: 0 | T38: 0 | U38: 0 | V38: 0 | W38: 0 | X38: #DIV/0! | Y38: #DIV/0! | Z38: 0
A39: 5 | C39: MAWAR | D39: III | E39: 31 | F39: 4 | G39: 0 | H39: 0 | I39: 0 | J39: 0 | K39: 0 | L39: 0 | M39: 0 | N39: 0 | O39: 0 | P39: 0 | Q39: 0 | R39: 0 | S39: 0 | T39: 0 | U39: 0 | V39: 0 | W39: 0 | X39: #DIV/0! | Y39: #DIV/0! | Z39: 0
C40: MAWAR | E40: 31 | F40: 4 | G40: 0 | H40: 0 | I40: 0 | J40: 0 | K40: 0 | L40: 0 | M40: 0 | N40: 0 | O40: 0 | P40: 0 | Q40: 0 | R40: 0 | S40: 0 | T40: 0 | U40: 0 | V40: 0 | W40: 0 | X40: #DIV/0! | Y40: #DIV/0! | Z40: 0
A41: 6 | C41: BOGENVILE | D41: I | E41: 31 | F41: 1 | G41: 0 | H41: 0 | I41: 0 | J41: 0 | K41: 0 | L41: 0 | M41: 0 | N41: 0 | O41: 0 | P41: 0 | Q41: 0 | R41: 0 | S41: 0 | T41: 0 | U41: 0 | V41: 0 | W41: 0 | X41: #DIV/0! | Y41: #DIV/0! | Z41: 0
C42: BOGENVILE | E42: 31 | F42: 1 | G42: 0 | H42: 0 | I42: 0 | J42: 0 | K42: 0 | L42: 0 | M42: 0 | N42: 0 | O42: 0 | P42: 0 | Q42: 0 | R42: 0 | S42: 0 | T42: 0 | U42: 0 | V42: 0 | W42: 0 | X42: #DIV/0! | Y42: #DIV/0! | Z42: 0
A43: 7 | C43: MELATI ATAS | D43: III | E43: 31 | F43: 4 | G43: 0 | H43: 0 | I43: 0 | J43: 0 | K43: 0 | L43: 0 | M43: 0 | N43: 0 | O43: 0 | P43: 0 | Q43: 0 | R43: 0 | S43: 0 | T43: 0 | U43: 0 | V43: 0 | W43: 0 | X43: #DIV/0! | Y43: #DIV/0! | Z43: 0
C44: MELATI ATAS | E44: 31 | F44: 4 | G44: 0 | H44: 0 | I44: 0 | J44: 0 | K44: 0 | L44: 0 | M44: 0 | N44: 0 | O44: 0 | P44: 0 | Q44: 0 | R44: 0 | S44: 0 | T44: 0 | U44: 0 | V44: 0 | W44: 0 | X44: #DIV/0! | Y44: #DIV/0! | Z44: 0
...

Sheet FEB
A1: DATA PELAYANAN RI RSD Dr.SOEBANDI JEMBER
A2: BULAN : FEBRUARI 2026
A3: NO | B3: PELAYANAN | C3: RAWAT INAP | D3: KLAS PERAWATAN | E3: PERIODE | F3: TT (T) | G3: PX AWAL | H3: PX MASUK | I3: PX PINDAHAN | J3: JUMLAH (1+2+3) | K3: PX DI PINDAHKAN | L3: PX KELUAR HIDUP | M3: PX MATI | N3: KURANG 48 JAM | O3: LEBIH 48 JAM | P3: JUMLAH (5+6+7) | Q3: LAMA DI RAWAT | R3: PX KELUAR/MASUK HR SAMA | S3: HARI PERAWATAN | T3: Px AKHIR | U3: KUNJUNGN | V3: O | W3: BOR (O/T) | X3: LOS | Y3: TOI | Z3: BTO
V4: (TT terpakai) | W4: (75%-85%) | X4: (3-12 hari) | Y4: (1-3 hr) | Z4: (30 px)
G6: 1 | H6: 2 | I6: 3 | J6: 4 | K6: 5 | L6: 6 | M6: 7 | N6: 8 | O6: 9 | P6: 10 | Q6: 11 | R6: 12 | S6: 13 | T6: 14 | V6: 15 | W6: 16 | X6: 17 | Y6: 18 | Z6: 19
A7: 1 | B7: INTENSIVE | C7: ICU | D7: I | E7: 28 | F7: 14 | G7: 6 | H7: 14 | I7: 96 | J7: 116 | K7: 94 | L7: 0 | M7: 13 | N7: 2 | O7: 11 | P7: 107 | Q7: 149 | R7: 1 | S7: 255 | T7: 9 | U7: 13 | V7: 9.1071429 | W7: 65.05102 | X7: 19.615385 | Y7: 10.538462 | Z7: 0.92857143
C8: ICU | D8: I | E8: 28 | F8: 14 | G8: 6 | H8: 14 | I8: 96 | J8: 116 | K8: 94 | L8: 0 | M8: 13 | N8: 2 | O8: 11 | P8: 107 | Q8: 149 | R8: 1 | S8: 255 | T8: 9 | U8: 13 | V8: 9.1071429 | W8: 65.05102 | X8: 19.615385 | Y8: 10.538462 | Z8: 0.92857143
A9: 2 | C9: ICCU | D9: I | E9: 28 | F9: 5 | G9: 5 | H9: 69 | I9: 8 | J9: 82 | K9: 71 | L9: 1 | M9: 7 | N9: 7 | O9: 0 | P9: 79 | Q9: 8 | R9: 4 | S9: 102 | T9: 3 | U9: 8 | V9: 3.6428571 | W9: 72.857143 | X9: 12.75 | Y9: 4.75 | Z9: 1.6
C10: ICCU | D10: I | E10: 28 | F10: 5 | G10: 5 | H10: 69 | I10: 8 | J10: 82 | K10: 71 | L10: 1 | M10: 7 | N10: 7 | O10: 0 | P10: 79 | Q10: 8 | R10: 4 | S10: 102 | T10: 3 | U10: 8 | V10: 3.6428571 | W10: 72.857143 | X10: 12.75 | Y10: 4.75 | Z10: 1.6
A11: 3 | C11: PICU | D11: I | E11: 28 | F11: 3 | G11: 3 | H11: 12 | I11: 7 | J11: 22 | K11: 17 | L11: 0 | M11: 4 | N11: 1 | O11: 3 | P11: 21 | Q11: 23 | R11: 0 | S11: 48 | T11: 1 | U11: 4 | V11: 1.7142857 | W11: 57.142857 | X11: 12 | Y11: 9 | Z11: 1.3333333
C12: PICU | D12: I | E12: 28 | F12: 3 | G12: 3 | H12: 12 | I12: 7 | J12: 22 | K12: 17 | L12: 0 | M12: 4 | N12: 1 | O12: 3 | P12: 21 | Q12: 23 | R12: 0 | S12: 48 | T12: 1 | U12: 4 | V12: 1.7142857 | W12: 57.142857 | X12: 12 | Y12: 9 | Z12: 1.3333333
A13: 4 | C13: NICU | D13: I | E13: 28 | F13: 5 | G13: 5 | H13: 9 | I13: 17 | J13: 31 | K13: 16 | L13: 1 | M13: 10 | N13: 6 | O13: 4 | P13: 27 | Q13: 51 | R13: 1 | S13: 119 | T13: 4 | U13: 11 | V13: 4.25 | W13: 85 | X13: 10.818182 | Y13: 1.9090909 | Z13: 2.2
C14: NICU | D14: I | E14: 28 | F14: 5 | G14: 5 | H14: 9 | I14: 17 | J14: 31 | K14: 16 | L14: 1 | M14: 10 | N14: 6 | O14: 4 | P14: 27 | Q14: 51 | R14: 1 | S14: 119 | T14: 4 | U14: 11 | V14: 4.25 | W14: 85 | X14: 10.818182 | Y14: 1.9090909 | Z14: 2.2
A15: 5 | C15: ICU MEDICAL | D15: I | E15: 28 | F15: 4 | G15: 3 | H15: 29 | I15: 8 | J15: 40 | K15: 25 | L15: 0 | M15: 11 | N15: 9 | O15: 2 | P15: 36 | Q15: 21 | R15: 2 | S15: 67 | T15: 4 | U15: 11 | V15: 2.3928571 | W15: 59.821429 | X15: 6.0909091 | Y15: 4.0909091 | Z15: 2.75
C16: ICU MEDICAL | D16: I | E16: 28 | F16: 4 | G16: 3 | H16: 29 | I16: 8 | J16: 40 | K16: 25 | L16: 0 | M16: 11 | N16: 9 | O16: 2 | P16: 36 | Q16: 21 | R16: 2 | S16: 67 | T16: 4 | U16: 11 | V16: 2.3928571 | W16: 59.821429 | X16: 6.0909091 | Y16: 4.0909091 | Z16: 2.75
A17: 6 | C17: RICU ED | D17: I | E17: 28 | F17: 2 | G17: 1 | H17: 8 | I17: 3 | J17: 12 | K17: 7 | L17: 0 | M17: 3 | N17: 1 | O17: 2 | P17: 10 | Q17: 8 | R17: 0 | S17: 24 | T17: 2 | U17: 3 | V17: 0.85714286 | W17: 42.857143 | X17: 8 | Y17: 10.666667 | Z17: 1.5
C18: RICU ED | E18: 28 | F18: 2 | G18: 1 | H18: 8 | I18: 3 | J18: 12 | K18: 7 | L18: 0 | M18: 3 | N18: 1 | O18: 2 | P18: 10 | Q18: 8 | R18: 0 | S18: 24 | T18: 2 | U18: 3 | V18: 0.85714286 | W18: 42.857143 | X18: 8 | Y18: 10.666667 | Z18: 1.5
A19: 7 | C19: HCU MELATI BAWAH | D19: II | E19: 28 | F19: 12 | G19: 12 | H19: 65 | I19: 28 | J19: 105 | K19: 18 | L19: 68 | M19: 11 | N19: 9 | O19: 2 | P19: 97 | Q19: 307 | R19: 4 | S19: 345 | T19: 8 | U19: 79 | V19: 12.321429 | W19: 102.67857 | X19: 4.3670886 | Y19: -0.11392405 | Z19: 6.5833333
C20: HCU MELATI BAWAH | D20: II | E20: 28 | F20: 12 | G20: 12 | H20: 65 | I20: 28 | J20: 105 | K20: 18 | L20: 68 | M20: 11 | N20: 9 | O20: 2 | P20: 97 | Q20: 307 | R20: 4 | S20: 345 | T20: 8 | U20: 79 | V20: 12.321429 | W20: 102.67857 | X20: 4.3670886 | Y20: -0.11392405 | Z20: 6.5833333
A21: TOTAL INTENSIVE | E21: 28 | F21: 45 | G21: 35 | H21: 206 | I21: 167 | J21: 408 | K21: 248 | L21: 70 | M21: 59 | N21: 35 | O21: 24 | P21: 377 | Q21: 567 | R21: 12 | S21: 960 | T21: 31 | U21: 129 | V21: 34.285714 | W21: 76.190476 | X21: 7.4418605 | Y21: 2.3255814 | Z21: 2.8666667
A24: NO | B24: PELAYANAN | C24: RAWAT INAP | D24: KLAS PERAWATAN | E24: PERIODE | F24: TT (T) | G24: PX AWAL | H24: PX MASUK | I24: PX PINDAHAN | J24: JUMLAH (1+2+3) | K24: PX DI PINDAHKAN | L24: PX KELUAR HIDUP | M24: PX MATI | N24: KURANG 48 JAM | O24: LEBIH 48 JAM | P24: JUMLAH (5+6+7) | Q24: LAMA DI RAWAT | R24: PX KELUAR/MASUK HR SAMA | S24: HARI PERAWATAN | T24: Px AKHIR | U24: KUNJUNGN | V24: O | W24: BOR (O/T) | X24: LOS | Y24: TOI | Z24: BTO
V25: (TT terpakai) | W25: (75%-85%) | X25: (3-12 hari) | Y25: (1-3 hr) | Z25: (30 px)
G27: 1 | H27: 2 | I27: 3 | J27: 4 | K27: 5 | L27: 6 | M27: 7 | N27: 8 | O27: 9 | P27: 10 | Q27: 11 | R27: 12 | S27: 13 | T27: 14 | V27: 15 | W27: 16 | X27: 17 | Y27: 18 | Z27: 19
A28: 1 | B28: ISOLASI | C28: SAKURA | D28: TB MDR II | E28: 28 | F28: 2 | G28: 0 | H28: 1 | I28: 0 | J28: 1 | K28: 0 | L28: 1 | M28: 0 | N28: 0 | O28: 0 | P28: 1 | Q28: 3 | R28: 0 | S28: 3 | T28: 0 | U28: 1 | V28: 0.10714286 | W28: 5.3571429 | X28: 3 | Y28: 53 | Z28: 0.5
C29: SAKURA | D29: TB MDR III | E29: 28 | F29: 3 | G29: 0 | H29: 4 | I29: 0 | J29: 4 | K29: 0 | L29: 1 | M29: 3 | N29: 1 | O29: 2 | P29: 4 | Q29: 12 | R29: 0 | S29: 11 | T29: 0 | U29: 4 | V29: 0.39285714 | W29: 13.095238 | X29: 2.75 | Y29: 18.25 | Z29: 1.3333333
C30: SAKURA | D30: TB PARU II | E30: 28 | F30: 2 | G30: 0 | H30: 6 | I30: 4 | J30: 10 | K30: 0 | L30: 8 | M30: 0 | N30: 0 | O30: 0 | P30: 8 | Q30: 40 | R30: 0 | S30: 30 | T30: 2 | U30: 8 | V30: 1.0714286 | W30: 53.571429 | X30: 3.75 | Y30: 3.25 | Z30: 4
C31: SAKURA | D31: TB PARU III | E31: 28 | F31: 10 | G31: 5 | H31: 47 | I31: 7 | J31: 59 | K31: 2 | L31: 35 | M31: 14 | N31: 7 | O31: 7 | P31: 51 | Q31: 230 | R31: 0 | S31: 229 | T31: 8 | U31: 49 | V31: 8.1785714 | W31: 81.785714 | X31: 4.6734694 | Y31: 1.0408163 | Z31: 4.9
C32: SAKURA | E32: 28 | F32: 17 | G32: 5 | H32: 58 | I32: 11 | J32: 74 | K32: 2 | L32: 45 | M32: 17 | N32: 8 | O32: 9 | P32: 64 | Q32: 285 | R32: 0 | S32: 273 | T32: 10 | U32: 62 | V32: 9.75 | W32: 57.352941 | X32: 4.4032258 | Y32: 3.2741935 | Z32: 3.6470588
A33: 2 | C33: CATALYA | D33: ISOLASI | E33: 28 | F33: 6 | G33: 8 | H33: 46 | I33: 8 | J33: 62 | K33: 3 | L33: 45 | M33: 7 | N33: 2 | O33: 5 | P33: 55 | Q33: 141 | R33: 0 | S33: 177 | T33: 7 | U33: 52 | V33: 6.3214286 | W33: 105.35714 | X33: 3.4038462 | Y33: -0.17307692 | Z33: 8.6666667
C34: CATALYA | E34: 28 | F34: 6 | G34: 8 | H34: 46 | I34: 8 | J34: 62 | K34: 3 | L34: 45 | M34: 7 | N34: 2 | O34: 5 | P34: 55 | Q34: 141 | R34: 0 | S34: 177 | T34: 7 | U34: 52 | V34: 6.3214286 | W34: 105.35714 | X34: 3.4038462 | Y34: -0.17307692 | Z34: 8.6666667
A35: 3 | C35: LAVENDER | D35: III | E35: 28 | F35: 4 | G35: 0 | H35: 0 | I35: 0 | J35: 0 | K35: 0 | L35: 0 | M35: 0 | N35: 0 | O35: 0 | P35: 0 | Q35: 0 | R35: 0 | S35: 0 | T35: 0 | U35: 0 | V35: 0 | W35: 0 | X35: #DIV/0! | Y35: #DIV/0! | Z35: 0
C36: LAVENDER | E36: 28 | F36: 4 | G36: 0 | H36: 0 | I36: 0 | J36: 0 | K36: 0 | L36: 0 | M36: 0 | N36: 0 | O36: 0 | P36: 0 | Q36: 0 | R36: 0 | S36: 0 | T36: 0 | U36: 0 | V36: 0 | W36: 0 | X36: #DIV/0! | Y36: #DIV/0! | Z36: 0
A37: 4 | C37: NUSA INDAH | D37: I | E37: 28 | F37: 2 | G37: 0 | H37: 0 | I37: 0 | J37: 0 | K37: 0 | L37: 0 | M37: 0 | N37: 0 | O37: 0 | P37: 0 | Q37: 0 | R37: 0 | S37: 0 | T37: 0 | U37: 0 | V37: 0 | W37: 0 | X37: #DIV/0! | Y37: #DIV/0! | Z37: 0
C38: NUSA INDAH | E38: 28 | F38: 2 | G38: 0 | H38: 0 | I38: 0 | J38: 0 | K38: 0 | L38: 0 | M38: 0 | N38: 0 | O38: 0 | P38: 0 | Q38: 0 | R38: 0 | S38: 0 | T38: 0 | U38: 0 | V38: 0 | W38: 0 | X38: #DIV/0! | Y38: #DIV/0! | Z38: 0
A39: 5 | C39: MAWAR | D39: III | E39: 28 | F39: 4 | G39: 0 | H39: 0 | I39: 0 | J39: 0 | K39: 0 | L39: 0 | M39: 0 | N39: 0 | O39: 0 | P39: 0 | Q39: 0 | R39: 0 | S39: 0 | T39: 0 | U39: 0 | V39: 0 | W39: 0 | X39: #DIV/0! | Y39: #DIV/0! | Z39: 0
C40: MAWAR | E40: 28 | F40: 4 | G40: 0 | H40: 0 | I40: 0 | J40: 0 | K40: 0 | L40: 0 | M40: 0 | N40: 0 | O40: 0 | P40: 0 | Q40: 0 | R40: 0 | S40: 0 | T40: 0 | U40: 0 | V40: 0 | W40: 0 | X40: #DIV/0! | Y40: #DIV/0! | Z40: 0
A41: 6 | C41: BOGENVILE | D41: I | E41: 28 | F41: 1 | G41: 0 | H41: 0 | I41: 0 | J41: 0 | K41: 0 | L41: 0 | M41: 0 | N41: 0 | O41: 0 | P41: 0 | Q41: 0 | R41: 0 | S41: 0 | T41: 0 | U41: 0 | V41: 0 | W41: 0 | X41: #DIV/0! | Y41: #DIV/0! | Z41: 0
C42: BOGENVILE | E42: 28 | F42: 1 | G42: 0 | H42: 0 | I42: 0 | J42: 0 | K42: 0 | L42: 0 | M42: 0 | N42: 0 | O42: 0 | P42: 0 | Q42: 0 | R42: 0 | S42: 0 | T42: 0 | U42: 0 | V42: 0 | W42: 0 | X42: #DIV/0! | Y42: #DIV/0! | Z42: 0
A43: 7 | C43: MELATI ATAS | D43: III | E43: 28 | F43: 4 | G43: 0 | H43: 0 | I43: 0 | J43: 0 | K43: 0 | L43: 0 | M43: 0 | N43: 0 | O43: 0 | P43: 0 | Q43: 0 | R43: 0 | S43: 0 | T43: 0 | U43: 0 | V43: 0 | W43: 0 | X43: #DIV/0! | Y43: #DIV/0! | Z43: 0
C44: MELATI ATAS | E44: 28 | F44: 4 | G44: 0 | H44: 0 | I44: 0 | J44: 0 | K44: 0 | L44: 0 | M44: 0 | N44: 0 | O44: 0 | P44: 0 | Q44: 0 | R44: 0 | S44: 0 | T44: 0 | U44: 0 | V44: 0 | W44: 0 | X44: #DIV/0! | Y44: #DIV/0! | Z44: 0
...

Sheet MAR
A1: DATA PELAYANAN RI RSD Dr.SOEBANDI JEMBER
A2: BULAN : MARET 2026
A3: NO | B3: PELAYANAN | C3: RAWAT INAP | D3: KLAS PERAWATAN | E3: PERIODE | F3: TT (T) | G3: PX AWAL | H3: PX MASUK | I3: PX PINDAHAN | J3: JUMLAH (1+2+3) | K3: PX DI PINDAHKAN | L3: PX KELUAR HIDUP | M3: PX MATI | N3: KURANG 48 JAM | O3: LEBIH 48 JAM | P3: JUMLAH (5+6+7) | Q3: LAMA DI RAWAT | R3: PX KELUAR/MASUK HR SAMA | S3: HARI PERAWATAN | T3: Px AKHIR | U3: KUNJUNGN | V3: O | W3: BOR (O/T) | X3: LOS | Y3: TOI | Z3: BTO
V4: (TT terpakai) | W4: (75%-85%) | X4: (3-12 hari) | Y4: (1-3 hr) | Z4: (30 px)
G6: 1 | H6: 2 | I6: 3 | J6: 4 | K6: 5 | L6: 6 | M6: 7 | N6: 8 | O6: 9 | P6: 10 | Q6: 11 | R6: 12 | S6: 13 | T6: 14 | V6: 15 | W6: 16 | X6: 17 | Y6: 18 | Z6: 19
A7: 1 | B7: INTENSIVE | C7: ICU | D7: I | E7: 31 | F7: 14 | G7: 9 | H7: 15 | I7: 90 | J7: 114 | K7: 90 | L7: 0 | M7: 14 | N7: 1 | O7: 13 | P7: 104 | Q7: 138 | R7: 0 | S7: 329 | T7: 10 | U7: 14 | V7: 10.612903 | W7: 75.806452 | X7: 23.5 | Y7: 7.5 | Z7: 1
C8: ICU | D8: I | E8: 31 | F8: 14 | G8: 9 | H8: 15 | I8: 90 | J8: 114 | K8: 90 | L8: 0 | M8: 14 | N8: 1 | O8: 13 | P8: 104 | Q8: 138 | R8: 0 | S8: 329 | T8: 10 | U8: 14 | V8: 10.612903 | W8: 75.806452 | X8: 23.5 | Y8: 7.5 | Z8: 1
A9: 2 | C9: ICCU | D9: I | E9: 31 | F9: 5 | G9: 3 | H9: 81 | I9: 11 | J9: 95 | K9: 80 | L9: 2 | M9: 8 | N9: 6 | O9: 2 | P9: 90 | Q9: 14 | R9: 0 | S9: 98 | T9: 5 | U9: 10 | V9: 3.1612903 | W9: 63.225806 | X9: 9.8 | Y9: 5.7 | Z9: 2
C10: ICCU | D10: I | E10: 31 | F10: 5 | G10: 3 | H10: 81 | I10: 11 | J10: 95 | K10: 80 | L10: 2 | M10: 8 | N10: 6 | O10: 2 | P10: 90 | Q10: 14 | R10: 0 | S10: 98 | T10: 5 | U10: 10 | V10: 3.1612903 | W10: 63.225806 | X10: 9.8 | Y10: 5.7 | Z10: 2
A11: 3 | C11: PICU | D11: I | E11: 31 | F11: 3 | G11: 1 | H11: 13 | I11: 11 | J11: 25 | K11: 19 | L11: 0 | M11: 3 | N11: 3 | O11: 0 | P11: 22 | Q11: 6 | R11: 0 | S11: 71 | T11: 3 | U11: 3 | V11: 2.2903226 | W11: 76.344086 | X11: 23.666667 | Y11: 7.3333333 | Z11: 1
C12: PICU | D12: I | E12: 31 | F12: 3 | G12: 1 | H12: 13 | I12: 11 | J12: 25 | K12: 19 | L12: 0 | M12: 3 | N12: 3 | O12: 0 | P12: 22 | Q12: 6 | R12: 0 | S12: 71 | T12: 3 | U12: 3 | V12: 2.2903226 | W12: 76.344086 | X12: 23.666667 | Y12: 7.3333333 | Z12: 1
A13: 4 | C13: NICU | D13: I | E13: 31 | F13: 5 | G13: 4 | H13: 8 | I13: 15 | J13: 27 | K13: 19 | L13: 0 | M13: 3 | N13: 2 | O13: 1 | P13: 22 | Q13: 26 | R13: 1 | S13: 128 | T13: 5 | U13: 3 | V13: 4.1290323 | W13: 82.580645 | X13: 42.666667 | Y13: 9 | Z13: 0.6
C14: NICU | D14: I | E14: 31 | F14: 5 | G14: 4 | H14: 8 | I14: 15 | J14: 27 | K14: 19 | L14: 0 | M14: 3 | N14: 2 | O14: 1 | P14: 22 | Q14: 26 | R14: 1 | S14: 128 | T14: 5 | U14: 3 | V14: 4.1290323 | W14: 82.580645 | X14: 42.666667 | Y14: 9 | Z14: 0.6
A15: 5 | C15: ICU MEDICAL | D15: I | E15: 31 | F15: 4 | G15: 4 | H15: 17 | I15: 9 | J15: 30 | K15: 19 | L15: 0 | M15: 10 | N15: 7 | O15: 3 | P15: 29 | Q15: 30 | R15: 1 | S15: 79 | T15: 1 | U15: 10 | V15: 2.5483871 | W15: 63.709677 | X15: 7.9 | Y15: 4.5 | Z15: 2.5
C16: ICU MEDICAL | D16: I | E16: 31 | F16: 4 | G16: 4 | H16: 17 | I16: 9 | J16: 30 | K16: 19 | L16: 0 | M16: 10 | N16: 7 | O16: 3 | P16: 29 | Q16: 30 | R16: 1 | S16: 79 | T16: 1 | U16: 10 | V16: 2.5483871 | W16: 63.709677 | X16: 7.9 | Y16: 4.5 | Z16: 2.5
A17: 6 | C17: RICU ED | D17: I | E17: 31 | F17: 2 | G17: 2 | H17: 11 | I17: 4 | J17: 17 | K17: 9 | L17: 1 | M17: 6 | N17: 3 | O17: 3 | P17: 16 | Q17: 20 | R17: 0 | S17: 48 | T17: 1 | U17: 7 | V17: 1.5483871 | W17: 77.419355 | X17: 6.8571429 | Y17: 2 | Z17: 3.5
C18: RICU ED | E18: 31 | F18: 2 | G18: 2 | H18: 11 | I18: 4 | J18: 17 | K18: 9 | L18: 1 | M18: 6 | N18: 3 | O18: 3 | P18: 16 | Q18: 20 | R18: 0 | S18: 48 | T18: 1 | U18: 7 | V18: 1.5483871 | W18: 77.419355 | X18: 6.8571429 | Y18: 2 | Z18: 3.5
A19: 7 | C19: HCU MELATI BAWAH | D19: II | E19: 31 | F19: 15 | G19: 8 | H19: 81 | I19: 27 | J19: 116 | K19: 18 | L19: 69 | M19: 15 | N19: 7 | O19: 8 | P19: 102 | Q19: 437 | R19: 2 | S19: 375 | T19: 14 | U19: 84 | V19: 12.096774 | W19: 80.645161 | X19: 4.4642857 | Y19: 1.0714286 | Z19: 5.6
C20: HCU MELATI BAWAH | D20: II | E20: 31 | F20: 15 | G20: 8 | H20: 81 | I20: 27 | J20: 116 | K20: 18 | L20: 69 | M20: 15 | N20: 7 | O20: 8 | P20: 102 | Q20: 437 | R20: 2 | S20: 375 | T20: 14 | U20: 84 | V20: 12.096774 | W20: 80.645161 | X20: 4.4642857 | Y20: 1.0714286 | Z20: 5.6
A21: TOTAL INTENSIVE | E21: 31 | F21: 48 | G21: 31 | H21: 226 | I21: 167 | J21: 424 | K21: 254 | L21: 72 | M21: 59 | N21: 29 | O21: 30 | P21: 385 | Q21: 671 | R21: 4 | S21: 1128 | T21: 39 | U21: 131 | V21: 36.387097 | W21: 75.806452 | X21: 8.610687 | Y21: 2.7480916 | Z21: 2.7291667
A24: NO | B24: PELAYANAN | C24: RAWAT INAP | D24: KLAS PERAWATAN | E24: PERIODE | F24: TT (T) | G24: PX AWAL | H24: PX MASUK | I24: PX PINDAHAN | J24: JUMLAH (1+2+3) | K24: PX DI PINDAHKAN | L24: PX KELUAR HIDUP | M24: PX MATI | N24: KURANG 48 JAM | O24: LEBIH 48 JAM | P24: JUMLAH (5+6+7) | Q24: LAMA DI RAWAT | R24: PX KELUAR/MASUK HR SAMA | S24: HARI PERAWATAN | T24: Px AKHIR | U24: KUNJUNGN | V24: O | W24: BOR (O/T) | X24: LOS | Y24: TOI | Z24: BTO
V25: (TT terpakai) | W25: (75%-85%) | X25: (3-12 hari) | Y25: (1-3 hr) | Z25: (30 px)
G27: 1 | H27: 2 | I27: 3 | J27: 4 | K27: 5 | L27: 6 | M27: 7 | N27: 8 | O27: 9 | P27: 10 | Q27: 11 | R27: 12 | S27: 13 | T27: 14 | V27: 15 | W27: 16 | X27: 17 | Y27: 18 | Z27: 19
A28: 1 | B28: ISOLASI | C28: SAKURA | D28: TB MDR II | E28: 31 | F28: 2 | G28: 0 | H28: 3 | I28: 1 | J28: 4 | K28: 1 | L28: 2 | M28: 0 | N28: 0 | O28: 0 | P28: 3 | Q28: 9 | R28: 0 | S28: 18 | T28: 1 | U28: 2 | V28: 0.58064516 | W28: 29.032258 | X28: 9 | Y28: 22 | Z28: 1
C29: SAKURA | D29: TB MDR III | E29: 31 | F29: 3 | G29: 0 | H29: 4 | I29: 1 | J29: 5 | K29: 2 | L29: 1 | M29: 2 | N29: 0 | O29: 2 | P29: 5 | Q29: 16 | R29: 0 | S29: 17 | T29: 0 | U29: 3 | V29: 0.5483871 | W29: 18.27957 | X29: 5.6666667 | Y29: 25.333333 | Z29: 1
C30: SAKURA | D30: TB PARU II | E30: 31 | F30: 2 | G30: 2 | H30: 2 | I30: 0 | J30: 4 | K30: 2 | L30: 1 | M30: 1 | N30: 0 | O30: 1 | P30: 4 | Q30: 9 | R30: 0 | S30: 5 | T30: 0 | U30: 2 | V30: 0.16129032 | W30: 8.0645161 | X30: 2.5 | Y30: 28.5 | Z30: 1
C31: SAKURA | D31: TB PARU III | E31: 31 | F31: 10 | G31: 8 | H31: 48 | I31: 5 | J31: 61 | K31: 1 | L31: 31 | M31: 24 | N31: 12 | O31: 12 | P31: 56 | Q31: 207 | R31: 1 | S31: 166 | T31: 5 | U31: 55 | V31: 5.3548387 | W31: 53.548387 | X31: 3.0181818 | Y31: 2.6181818 | Z31: 5.5
C32: SAKURA | E32: 31 | F32: 17 | G32: 10 | H32: 57 | I32: 7 | J32: 74 | K32: 6 | L32: 35 | M32: 27 | N32: 12 | O32: 15 | P32: 68 | Q32: 241 | R32: 1 | S32: 206 | T32: 6 | U32: 62 | V32: 6.6451613 | W32: 39.089184 | X32: 3.3225806 | Y32: 5.1774194 | Z32: 3.6470588
A33: 2 | C33: CATALYA | D33: ISOLASI | E33: 31 | F33: 6 | G33: 7 | H33: 21 | I33: 4 | J33: 32 | K33: 13 | L33: 19 | M33: 0 | N33: 0 | O33: 0 | P33: 32 | Q33: 60 | R33: 0 | S33: 102 | T33: 0 | U33: 19 | V33: 3.2903226 | W33: 54.83871 | X33: 5.3684211 | Y33: 4.4210526 | Z33: 3.1666667
C34: CATALYA | E34: 31 | F34: 6 | G34: 7 | H34: 21 | I34: 4 | J34: 32 | K34: 13 | L34: 19 | M34: 0 | N34: 0 | O34: 0 | P34: 32 | Q34: 60 | R34: 0 | S34: 102 | T34: 0 | U34: 19 | V34: 3.2903226 | W34: 54.83871 | X34: 5.3684211 | Y34: 4.4210526 | Z34: 3.1666667
A35: 3 | C35: LAVENDER | D35: III | E35: 31 | F35: 4 | G35: 0 | H35: 0 | I35: 0 | J35: 0 | K35: 0 | L35: 0 | M35: 0 | N35: 0 | O35: 0 | P35: 0 | Q35: 0 | R35: 0 | S35: 0 | T35: 0 | U35: 0 | V35: 0 | W35: 0 | X35: #DIV/0! | Y35: #DIV/0! | Z35: 0
C36: LAVENDER | E36: 31 | F36: 4 | G36: 0 | H36: 0 | I36: 0 | J36: 0 | K36: 0 | L36: 0 | M36: 0 | N36: 0 | O36: 0 | P36: 0 | Q36: 0 | R36: 0 | S36: 0 | T36: 0 | U36: 0 | V36: 0 | W36: 0 | X36: #DIV/0! | Y36: #DIV/0! | Z36: 0
A37: 4 | C37: NUSA INDAH | D37: I | E37: 31 | F37: 2 | G37: 0 | H37: 0 | I37: 0 | J37: 0 | K37: 0 | L37: 0 | M37: 0 | N37: 0 | O37: 0 | P37: 0 | Q37: 0 | R37: 0 | S37: 0 | T37: 0 | U37: 0 | V37: 0 | W37: 0 | X37: #DIV/0! | Y37: #DIV/0! | Z37: 0
C38: NUSA INDAH | E38: 31 | F38: 2 | G38: 0 | H38: 0 | I38: 0 | J38: 0 | K38: 0 | L38: 0 | M38: 0 | N38: 0 | O38: 0 | P38: 0 | Q38: 0 | R38: 0 | S38: 0 | T38: 0 | U38: 0 | V38: 0 | W38: 0 | X38: #DIV/0! | Y38: #DIV/0! | Z38: 0
A39: 5 | C39: MAWAR | D39: III | E39: 31 | F39: 4 | G39: 0 | H39: 0 | I39: 0 | J39: 0 | K39: 0 | L39: 0 | M39: 0 | N39: 0 | O39: 0 | P39: 0 | Q39: 0 | R39: 0 | S39: 0 | T39: 0 | U39: 0 | V39: 0 | W39: 0 | X39: #DIV/0! | Y39: #DIV/0! | Z39: 0
C40: MAWAR | E40: 31 | F40: 4 | G40: 0 | H40: 0 | I40: 0 | J40: 0 | K40: 0 | L40: 0 | M40: 0 | N40: 0 | O40: 0 | P40: 0 | Q40: 0 | R40: 0 | S40: 0 | T40: 0 | U40: 0 | V40: 0 | W40: 0 | X40: #DIV/0! | Y40: #DIV/0! | Z40: 0
A41: 6 | C41: BOGENVILE | D41: I | E41: 31 | F41: 1 | G41: 0 | H41: 0 | I41: 0 | J41: 0 | K41: 0 | L41: 0 | M41: 0 | N41: 0 | O41: 0 | P41: 0 | Q41: 0 | R41: 0 | S41: 0 | T41: 0 | U41: 0 | V41: 0 | W41: 0 | X41: #DIV/0! | Y41: #DIV/0! | Z41: 0
C42: BOGENVILE | E42: 31 | F42: 1 | G42: 0 | H42: 0 | I42: 0 | J42: 0 | K42: 0 | L42: 0 | M42: 0 | N42: 0 | O42: 0 | P42: 0 | Q42: 0 | R42: 0 | S42: 0 | T42: 0 | U42: 0 | V42: 0 | W42: 0 | X42: #DIV/0! | Y42: #DIV/0! | Z42: 0
A43: 7 | C43: MELATI ATAS | D43: III | E43: 31 | F43: 4 | G43: 0 | H43: 0 | I43: 0 | J43: 0 | K43: 0 | L43: 0 | M43: 0 | N43: 0 | O43: 0 | P43: 0 | Q43: 0 | R43: 0 | S43: 0 | T43: 0 | U43: 0 | V43: 0 | W43: 0 | X43: #DIV/0! | Y43: #DIV/0! | Z43: 0
C44: MELATI ATAS | E44: 31 | F44: 4 | G44: 0 | H44: 0 | I44: 0 | J44: 0 | K44: 0 | L44: 0 | M44: 0 | N44: 0 | O44: 0 | P44: 0 | Q44: 0 | R44: 0 | S44: 0 | T44: 0 | U44: 0 | V44: 0 | W44: 0 | X44: #DIV/0! | Y44: #DIV/0! | Z44: 0
...

Sheet JUL

Sheet AGS

Sheet SEP

Sheet OKT

Sheet NOV

Sheet DES

Sheet TOTAL JAN-MAR 2026
A1: DATA PELAYANAN RI RSD Dr.SOEBANDI JEMBER
A2: BULAN : JANUARI - FEBRUARI2026
A3: NO | B3: PELAYANAN | C3: RAWAT INAP | D3: KLAS PERAWATAN | E3: PERIODE | F3: TT (T) | G3: PX AWAL | H3: PX MASUK | I3: PX PINDAHAN | J3: JUMLAH (1+2+3) | K3: PX DI PINDAHKAN | L3: PX KELUAR HIDUP | M3: PX MATI | N3: KURANG 48 JAM | O3: LEBIH 48 JAM | P3: JUMLAH (5+6+7) | Q3: LAMA DI RAWAT | R3: PX KELUAR/MASUK HR SAMA | S3: HARI PERAWATAN | T3: Px AKHIR | U3: KUNJUNGN | V3: O | W3: BOR (O/T) | X3: LOS | Y3: TOI | Z3: BTO
V4: (TT terpakai) | W4: (75%-85%) | X4: (3-12 hari) | Y4: (1-3 hr) | Z4: (30 px)
G6: 1 | H6: 2 | I6: 3 | J6: 4 | K6: 5 | L6: 6 | M6: 7 | N6: 8 | O6: 9 | P6: 10 | Q6: 11 | R6: 12 | S6: 13 | T6: 14 | V6: 15 | W6: 16 | X6: 17 | Y6: 18 | Z6: 19
A7: 1 | B7: INTENSIVE | C7: ICU | D7: I | E7: =+JAN!E7+FEB!E7+MAR!E7 -> 90 | F7: =MAR!F7 -> 14 | G7: ='[1]TT Per Ruang'!G96 -> 17 | H7: =+JAN!H7+FEB!H7+MAR!H7 -> 41 | I7: =+JAN!I7+FEB!I7+MAR!I7 -> 274 | J7: 117 | K7: =+JAN!K7+FEB!K7+MAR!K7 -> 277 | L7: =+JAN!L7+FEB!L7+MAR!L7 -> 0 | M7: 18 | N7: =+JAN!N7+FEB!N7+MAR!N7 -> 5 | O7: =+JAN!O7+FEB!O7+MAR!O7 -> 40 | P7: 111 | Q7: =+JAN!Q7+FEB!Q7+MAR!Q7 -> 404 | R7: =+JAN!R7+FEB!R7+MAR!R7 -> 1 | S7: =+JAN!S7+FEB!S7+MAR!S7 -> 932 | T7: =J7-P7 -> 6 | U7: =+L7+M7 -> 18 | V7: =$S7/$E7 -> 10.355556 | W7: =$V7/$F7*100 -> 73.968254 | X7: =$S7/($L7+$M7) -> 51.777778 | Y7: =(($F7-$V7)*$E7)/($L7+$M7) -> 18.222222 | Z7: =($L7+$M7)/$F7 -> 1.2857143
C8: ICU | D8: I | E8: =+JAN!E8+FEB!E8+MAR!E8 -> 90 | F8: =SUM(F7) -> 14 | G8: =SUM(G7) -> 17 | H8: =SUM(H7) -> 41 | I8: =SUM(I7) -> 274 | J8: 117 | K8: =SUM(K7) -> 277 | L8: =SUM(L7) -> 0 | M8: 18 | N8: =SUM(N7) -> 5 | O8: =SUM(O7) -> 40 | P8: 111 | Q8: =SUM(Q7) -> 404 | R8: =SUM(R7) -> 1 | S8: =SUM(S7) -> 932 | T8: =J8-P8 -> 6 | U8: =+L8+M8 -> 18 | V8: =$S8/$E8 -> 10.355556 | W8: =$V8/$F8*100 -> 73.968254 | X8: =$S8/($L8+$M8) -> 51.777778 | Y8: =(($F8-$V8)*$E8)/($L8+$M8) -> 18.222222 | Z8: =($L8+$M8)/$F8 -> 1.2857143
A9: 2 | C9: ICCU | D9: I | E9: =+JAN!E9+FEB!E9+MAR!E9 -> 90 | F9: =MAR!F9 -> 5 | G9: ='[1]TT Per Ruang'!G98 -> 2 | H9: =+JAN!H9+FEB!H9+MAR!H9 -> 221 | I9: =+JAN!I9+FEB!I9+MAR!I9 -> 29 | J9: 83 | K9: =+JAN!K9+FEB!K9+MAR!K9 -> 228 | L9: =+JAN!L9+FEB!L9+MAR!L9 -> 3 | M9: 1 | N9: =+JAN!N9+FEB!N9+MAR!N9 -> 14 | O9: =+JAN!O9+FEB!O9+MAR!O9 -> 2 | P9: 78 | Q9: =+JAN!Q9+FEB!Q9+MAR!Q9 -> 23 | R9: =+JAN!R9+FEB!R9+MAR!R9 -> 5 | S9: =+JAN!S9+FEB!S9+MAR!S9 -> 314 | T9: =J9-P9 -> 5 | U9: =+L9+M9 -> 4 | V9: =$S9/$E9 -> 3.4888889 | W9: =$V9/$F9*100 -> 69.777778 | X9: =$S9/($L9+$M9) -> 78.5 | Y9: =(($F9-$V9)*$E9)/($L9+$M9) -> 34 | Z9: =($L9+$M9)/$F9 -> 0.8
C10: ICCU | D10: I | E10: =+JAN!E10+FEB!E10+MAR!E10 -> 90 | F10: =SUM(F9) -> 5 | G10: =SUM(G9) -> 2 | H10: =SUM(H9) -> 221 | I10: =SUM(I9) -> 29 | J10: 83 | K10: =SUM(K9) -> 228 | L10: =SUM(L9) -> 3 | M10: 1 | N10: =SUM(N9) -> 14 | O10: =SUM(O9) -> 2 | P10: 78 | Q10: =SUM(Q9) -> 23 | R10: =SUM(R9) -> 5 | S10: =SUM(S9) -> 314 | T10: =J10-P10 -> 5 | U10: =+L10+M10 -> 4 | V10: =$S10/$E10 -> 3.4888889 | W10: =$V10/$F10*100 -> 69.777778 | X10: =$S10/($L10+$M10) -> 78.5 | Y10: =(($F10-$V10)*$E10)/($L10+$M10) -> 34 | Z10: =($L10+$M10)/$F10 -> 0.8
A11: 3 | C11: PICU | D11: I | E11: =+JAN!E11+FEB!E11+MAR!E11 -> 90 | F11: =MAR!F11 -> 3 | G11: ='[1]TT Per Ruang'!G100 -> 2 | H11: =+JAN!H11+FEB!H11+MAR!H11 -> 40 | I11: =+JAN!I11+FEB!I11+MAR!I11 -> 27 | J11: 26 | K11: =+JAN!K11+FEB!K11+MAR!K11 -> 55 | L11: =+JAN!L11+FEB!L11+MAR!L11 -> 1 | M11: 3 | N11: =+JAN!N11+FEB!N11+MAR!N11 -> 5 | O11: =+JAN!O11+FEB!O11+MAR!O11 -> 5 | P11: 23 | Q11: =+JAN!Q11+FEB!Q11+MAR!Q11 -> 64 | R11: =+JAN!R11+FEB!R11+MAR!R11 -> 0 | S11: =+JAN!S11+FEB!S11+MAR!S11 -> 186 | T11: =J11-P11 -> 3 | U11: =+L11+M11 -> 4 | V11: =$S11/$E11 -> 2.0666667 | W11: =$V11/$F11*100 -> 68.888889 | X11: =$S11/($L11+$M11) -> 46.5 | Y11: =(($F11-$V11)*$E11)/($L11+$M11) -> 21 | Z11: =($L11+$M11)/$F11 -> 1.3333333
C12: PICU | D12: I | E12: =+JAN!E12+FEB!E12+MAR!E12 -> 90 | F12: =SUM(F11) -> 3 | G12: =SUM(G11) -> 2 | H12: =SUM(H11) -> 40 | I12: =SUM(I11) -> 27 | J12: 26 | K12: =SUM(K11) -> 55 | L12: =SUM(L11) -> 1 | M12: 3 | N12: =SUM(N11) -> 5 | O12: =SUM(O11) -> 5 | P12: 23 | Q12: =SUM(Q11) -> 64 | R12: =SUM(R11) -> 0 | S12: =SUM(S11) -> 186 | T12: =J12-P12 -> 3 | U12: =+L12+M12 -> 4 | V12: =$S12/$E12 -> 2.0666667 | W12: =$V12/$F12*100 -> 68.888889 | X12: =$S12/($L12+$M12) -> 46.5 | Y12: =(($F12-$V12)*$E12)/($L12+$M12) -> 21 | Z12: =($L12+$M12)/$F12 -> 1.3333333
A13: 4 | C13: NICU | D13: I | E13: =+JAN!E13+FEB!E13+MAR!E13 -> 90 | F13: =MAR!F13 -> 5 | G13: ='[1]TT Per Ruang'!G102 -> 5 | H13: =+JAN!H13+FEB!H13+MAR!H13 -> 30 | I13: =+JAN!I13+FEB!I13+MAR!I13 -> 50 | J13: 36 | K13: =+JAN!K13+FEB!K13+MAR!K13 -> 59 | L13: =+JAN!L13+FEB!L13+MAR!L13 -> 1 | M13: 7 | N13: =+JAN!N13+FEB!N13+MAR!N13 -> 9 | O13: =+JAN!O13+FEB!O13+MAR!O13 -> 11 | P13: 31 | Q13: =+JAN!Q13+FEB!Q13+MAR!Q13 -> 127 | R13: =+JAN!R13+FEB!R13+MAR!R13 -> 2 | S13: =+JAN!S13+FEB!S13+MAR!S13 -> 364 | T13: =J13-P13 -> 5 | U13: =+L13+M13 -> 8 | V13: =$S13/$E13 -> 4.0444444 | W13: =$V13/$F13*100 -> 80.888889 | X13: =$S13/($L13+$M13) -> 45.5 | Y13: =(($F13-$V13)*$E13)/($L13+$M13) -> 10.75 | Z13: =($L13+$M13)/$F13 -> 1.6
C14: NICU | D14: I | E14: =+JAN!E14+FEB!E14+MAR!E14 -> 90 | F14: =SUM(F13) -> 5 | G14: =SUM(G13) -> 5 | H14: =SUM(H13) -> 30 | I14: =SUM(I13) -> 50 | J14: 36 | K14: =SUM(K13) -> 59 | L14: =SUM(L13) -> 1 | M14: 7 | N14: =SUM(N13) -> 9 | O14: =SUM(O13) -> 11 | P14: 31 | Q14: =SUM(Q13) -> 127 | R14: =SUM(R13) -> 2 | S14: =SUM(S13) -> 364 | T14: =J14-P14 -> 5 | U14: =+L14+M14 -> 8 | V14: =$S14/$E14 -> 4.0444444 | W14: =$V14/$F14*100 -> 80.888889 | X14: =$S14/($L14+$M14) -> 45.5 | Y14: =(($F14-$V14)*$E14)/($L14+$M14) -> 10.75 | Z14: =($L14+$M14)/$F14 -> 1.6
A15: 5 | C15: ICU MEDICAL | D15: I | E15: =+JAN!E15+FEB!E15+MAR!E15 -> 90 | F15: =MAR!F15 -> 4 | G15: ='[1]TT Per Ruang'!G104 -> 3 | H15: =+JAN!H15+FEB!H15+MAR!H15 -> 79 | I15: =+JAN!I15+FEB!I15+MAR!I15 -> 32 | J15: 51 | K15: =+JAN!K15+FEB!K15+MAR!K15 -> 75 | L15: =+JAN!L15+FEB!L15+MAR!L15 -> 1 | M15: 16 | N15: =+JAN!N15+FEB!N15+MAR!N15 -> 26 | O15: =+JAN!O15+FEB!O15+MAR!O15 -> 11 | P15: 48 | Q15: =+JAN!Q15+FEB!Q15+MAR!Q15 -> 86 | R15: =+JAN!R15+FEB!R15+MAR!R15 -> 7 | S15: =+JAN!S15+FEB!S15+MAR!S15 -> 231 | T15: =J15-P15 -> 3 | U15: =+L15+M15 -> 17 | V15: =$S15/$E15 -> 2.5666667 | W15: =$V15/$F15*100 -> 64.166667 | X15: =$S15/($L15+$M15) -> 13.588235 | Y15: =(($F15-$V15)*$E15)/($L15+$M15) -> 7.5882353 | Z15: =($L15+$M15)/$F15 -> 4.25
C16: ICU MEDICAL | D16: I | E16: =+JAN!E16+FEB!E16+MAR!E16 -> 90 | F16: =SUM(F15) -> 4 | G16: =SUM(G15) -> 3 | H16: =SUM(H15) -> 79 | I16: =SUM(I15) -> 32 | J16: 51 | K16: =SUM(K15) -> 75 | L16: =SUM(L15) -> 1 | M16: 16 | N16: =SUM(N15) -> 26 | O16: =SUM(O15) -> 11 | P16: 48 | Q16: =SUM(Q15) -> 86 | R16: =SUM(R15) -> 7 | S16: =SUM(S15) -> 231 | T16: =J16-P16 -> 3 | U16: =+L16+M16 -> 17 | V16: =$S16/$E16 -> 2.5666667 | W16: =$V16/$F16*100 -> 64.166667 | X16: =$S16/($L16+$M16) -> 13.588235 | Y16: =(($F16-$V16)*$E16)/($L16+$M16) -> 7.5882353 | Z16: =($L16+$M16)/$F16 -> 4.25
A17: 6 | C17: RICU ED | D17: I | E17: =+JAN!E17+FEB!E17+MAR!E17 -> 90 | F17: =MAR!F17 -> 2 | G17: ='[1]TT Per Ruang'!G106 -> 0 | H17: =+JAN!H17+FEB!H17+MAR!H17 -> 26 | I17: =+JAN!I17+FEB!I17+MAR!I17 -> 12 | J17: 12 | K17: =+JAN!K17+FEB!K17+MAR!K17 -> 23 | L17: =+JAN!L17+FEB!L17+MAR!L17 -> 1 | M17: 4 | N17: =+JAN!N17+FEB!N17+MAR!N17 -> 6 | O17: =+JAN!O17+FEB!O17+MAR!O17 -> 7 | P17: 11 | Q17: =+JAN!Q17+FEB!Q17+MAR!Q17 -> 41 | R17: =+JAN!R17+FEB!R17+MAR!R17 -> 2 | S17: =+JAN!S17+FEB!S17+MAR!S17 -> 112 | T17: =J17-P17 -> 1 | U17: =+L17+M17 -> 5 | V17: =$S17/$E17 -> 1.2444444 | W17: =$V17/$F17*100 -> 62.222222 | X17: =$S17/($L17+$M17) -> 22.4 | Y17: =(($F17-$V17)*$E17)/($L17+$M17) -> 13.6 | Z17: =($L17+$M17)/$F17 -> 2.5
C18: RICU ED | E18: =+JAN!E18+FEB!E18+MAR!E18 -> 90 | F18: =SUM(F17) -> 2 | G18: =SUM(G17) -> 0 | H18: =SUM(H17) -> 26 | I18: =SUM(I17) -> 12 | J18: 12 | K18: =SUM(K17) -> 23 | L18: =SUM(L17) -> 1 | M18: 4 | N18: =SUM(N17) -> 6 | O18: =SUM(O17) -> 7 | P18: 11 | Q18: =SUM(Q17) -> 41 | R18: =SUM(R17) -> 2 | S18: =SUM(S17) -> 112 | T18: =J18-P18 -> 1 | U18: =+L18+M18 -> 5 | V18: =$S18/$E18 -> 1.2444444 | W18: =$V18/$F18*100 -> 62.222222 | X18: =$S18/($L18+$M18) -> 22.4 | Y18: =(($F18-$V18)*$E18)/($L18+$M18) -> 13.6 | Z18: =($L18+$M18)/$F18 -> 2.5
A19: 7 | C19: HCU MELATI BAWAH | D19: II | E19: =+JAN!E19+FEB!E19+MAR!E19 -> 90 | F19: =MAR!F19 -> 15 | G19: ='[1]TT Per Ruang'!G20 -> 12 | H19: =+JAN!H19+FEB!H19+MAR!H19 -> 227 | I19: =+JAN!I19+FEB!I19+MAR!I19 -> 86 | J19: 124 | K19: =+JAN!K19+FEB!K19+MAR!K19 -> 58 | L19: =+JAN!L19+FEB!L19+MAR!L19 -> 208 | M19: 19 | N19: =+JAN!N19+FEB!N19+MAR!N19 -> 27 | O19: =+JAN!O19+FEB!O19+MAR!O19 -> 18 | P19: 112 | Q19: =+JAN!Q19+FEB!Q19+MAR!Q19 -> 1058 | R19: =+JAN!R19+FEB!R19+MAR!R19 -> 6 | S19: =+JAN!S19+FEB!S19+MAR!S19 -> 1087 | T19: =J19-P19 -> 12 | U19: =+L19+M19 -> 227 | V19: =$S19/$E19 -> 12.077778 | W19: =$V19/$F19*100 -> 80.518519 | X19: =$S19/($L19+$M19) -> 4.7885463 | Y19: =(($F19-$V19)*$E19)/($L19+$M19) -> 1.1585903 | Z19: =($L19+$M19)/$F19 -> 15.133333
C20: HCU MELATI BAWAH | D20: II | E20: =+JAN!E20+FEB!E20+MAR!E20 -> 90 | F20: =SUM(F19) -> 15 | G20: =SUM(G19) -> 12 | H20: =SUM(H19) -> 227 | I20: =SUM(I19) -> 86 | J20: 124 | K20: =SUM(K19) -> 58 | L20: =SUM(L19) -> 208 | M20: 19 | N20: =SUM(N19) -> 27 | O20: =SUM(O19) -> 18 | P20: 112 | Q20: =SUM(Q19) -> 1058 | R20: =SUM(R19) -> 6 | S20: =SUM(S19) -> 1087 | T20: =J20-P20 -> 12 | U20: =+L20+M20 -> 227 | V20: =$S20/$E20 -> 12.077778 | W20: =$V20/$F20*100 -> 80.518519 | X20: =$S20/($L20+$M20) -> 4.7885463 | Y20: =(($F20-$V20)*$E20)/($L20+$M20) -> 1.1585903 | Z20: =($L20+$M20)/$F20 -> 15.133333
A21: TOTAL INTENSIVE | E21: =+JAN!E21+FEB!E21+MAR!E21 -> 90 | F21: =+F8+F10+F12+F14+F16+F18+F20 -> 48 | G21: =+G8+G10+G12+G14+G16+G18+G20 -> 41 | H21: =+H8+H10+H12+H14+H16+H18+H20 -> 664 | I21: =+I8+I10+I12+I14+I16+I18+I20 -> 510 | J21: 449 | K21: =+K8+K10+K12+K14+K16+K18+K20 -> 775 | L21: =+L8+L10+L12+L14+L16+L18+L20 -> 215 | M21: =+N21+O21 -> 186 | N21: =+N8+N10+N12+N14+N16+N18+N20 -> 92 | O21: =+O8+O10+O12+O14+O16+O18+O20 -> 94 | P21: 414 | Q21: =+Q8+Q10+Q12+Q14+Q16+Q18+Q20 -> 1803 | R21: =+R8+R10+R12+R14+R16+R18+R20 -> 23 | S21: =+S8+S10+S12+S14+S16+S18+S20 -> 3226 | T21: =J21-P21 -> 35 | U21: =+L21+M21 -> 401 | V21: =$S21/$E21 -> 35.844444 | W21: =$V21/$F21*100 -> 74.675926 | X21: =$S21/($L21+$M21) -> 8.0448878 | Y21: =(($F21-$V21)*$E21)/($L21+$M21) -> 2.7281796 | Z21: =($L21+$M21)/$F21 -> 8.3541667
H22: =+JAN!H21+FEB!H21 -> 438
A24: NO | B24: PELAYANAN | C24: RAWAT INAP | D24: KLAS PERAWATAN | E24: PERIODE | F24: TT (T) | G24: PX AWAL | H24: PX MASUK | I24: PX PINDAHAN | J24: JUMLAH (1+2+3) | K24: PX DI PINDAHKAN | L24: PX KELUAR HIDUP | M24: PX MATI | N24: KURANG 48 JAM | O24: LEBIH 48 JAM | P24: JUMLAH (5+6+7) | Q24: LAMA DI RAWAT | R24: PX KELUAR/MASUK HR SAMA | S24: HARI PERAWATAN | T24: Px AKHIR | U24: KUNJUNGN | V24: O | W24: BOR (O/T) | X24: LOS | Y24: TOI | Z24: BTO
V25: (TT terpakai) | W25: (75%-85%) | X25: (3-12 hari) | Y25: (1-3 hr) | Z25: (30 px)
G27: 1 | H27: 2 | I27: 3 | J27: 4 | K27: 5 | L27: 6 | M27: 7 | N27: 8 | O27: 9 | P27: 10 | Q27: 11 | R27: 12 | S27: 13 | T27: 14 | V27: 15 | W27: 16 | X27: 17 | Y27: 18 | Z27: 19
A28: 1 | B28: ISOLASI | C28: SAKURA | D28: TB MDR II | E28: =+JAN!E28+FEB!E28+MAR!E28 -> 90 | F28: =MAR!F28 -> 2 | G28: ='[1]TT Per Ruang'!G47 -> 0 | H28: =+JAN!H28+FEB!H28+MAR!H28 -> 8 | I28: =+JAN!I28+FEB!I28+MAR!I28 -> 2 | J28: 5 | K28: =+JAN!K28+FEB!K28+MAR!K28 -> 2 | L28: =+JAN!L28+FEB!L28+MAR!L28 -> 4 | M28: 3 | N28: =+JAN!N28+FEB!N28+MAR!N28 -> 2 | O28: =+JAN!O28+FEB!O28+MAR!O28 -> 1 | P28: 5 | Q28: =+JAN!Q28+FEB!Q28+MAR!Q28 -> 23 | R28: =+JAN!R28+FEB!R28+MAR!R28 -> 0 | S28: =+JAN!S28+FEB!S28+MAR!S28 -> 27 | T28: =J28-P28 -> 0 | U28: =+L28+M28 -> 7 | V28: =$S28/$E28 -> 0.3 | W28: =$V28/$F28*100 -> 15 | X28: =$S28/($L28+$M28) -> 3.8571429 | Y28: =(($F28-$V28)*$E28)/($L28+$M28) -> 21.857143 | Z28: =($L28+$M28)/$F28 -> 3.5
C29: SAKURA | D29: TB MDR III | E29: =+JAN!E29+FEB!E29+MAR!E29 -> 90 | F29: =MAR!F29 -> 3 | G29: ='[1]TT Per Ruang'!G48 -> 1 | H29: =+JAN!H29+FEB!H29+MAR!H29 -> 17 | I29: =+JAN!I29+FEB!I29+MAR!I29 -> 1 | J29: 10 | K29: =+JAN!K29+FEB!K29+MAR!K29 -> 2 | L29: =+JAN!L29+FEB!L29+MAR!L29 -> 10 | M29: 2 | N29: =+JAN!N29+FEB!N29+MAR!N29 -> 1 | O29: =+JAN!O29+FEB!O29+MAR!O29 -> 6 | P29: 10 | Q29: =+JAN!Q29+FEB!Q29+MAR!Q29 -> 78 | R29: =+JAN!R29+FEB!R29+MAR!R29 -> 0 | S29: =+JAN!S29+FEB!S29+MAR!S29 -> 62 | T29: =J29-P29 -> 0 | U29: =+L29+M29 -> 12 | V29: =$S29/$E29 -> 0.68888889 | W29: =$V29/$F29*100 -> 22.962963 | X29: =$S29/($L29+$M29) -> 5.1666667 | Y29: =(($F29-$V29)*$E29)/($L29+$M29) -> 17.333333 | Z29: =($L29+$M29)/$F29 -> 4
C30: SAKURA | D30: TB PARU II | E30: =+JAN!E30+FEB!E30+MAR!E30 -> 90 | F30: =MAR!F30 -> 2 | G30: ='[1]TT Per Ruang'!G49 -> 0 | H30: =+JAN!H30+FEB!H30+MAR!H30 -> 11 | I30: =+JAN!I30+FEB!I30+MAR!I30 -> 6 | J30: 5 | K30: =+JAN!K30+FEB!K30+MAR!K30 -> 2 | L30: =+JAN!L30+FEB!L30+MAR!L30 -> 10 | M30: 4 | N30: =+JAN!N30+FEB!N30+MAR!N30 -> 3 | O30: =+JAN!O30+FEB!O30+MAR!O30 -> 2 | P30: 5 | Q30: =+JAN!Q30+FEB!Q30+MAR!Q30 -> 90 | R30: =+JAN!R30+FEB!R30+MAR!R30 -> 0 | S30: =+JAN!S30+FEB!S30+MAR!S30 -> 65 | T30: =J30-P30 -> 0 | U30: =+L30+M30 -> 14 | V30: =$S30/$E30 -> 0.72222222 | W30: =$V30/$F30*100 -> 36.111111 | X30: =$S30/($L30+$M30) -> 4.6428571 | Y30: =(($F30-$V30)*$E30)/($L30+$M30) -> 8.2142857 | Z30: =($L30+$M30)/$F30 -> 7
C31: SAKURA | D31: TB PARU III | E31: =+JAN!E31+FEB!E31+MAR!E31 -> 90 | F31: =MAR!F31 -> 10 | G31: ='[1]TT Per Ruang'!G50 -> 2 | H31: =+JAN!H31+FEB!H31+MAR!H31 -> 138 | I31: =+JAN!I31+FEB!I31+MAR!I31 -> 24 | J31: 57 | K31: =+JAN!K31+FEB!K31+MAR!K31 -> 6 | L31: =+JAN!L31+FEB!L31+MAR!L31 -> 100 | M31: 15 | N31: =+JAN!N31+FEB!N31+MAR!N31 -> 25 | O31: =+JAN!O31+FEB!O31+MAR!O31 -> 28 | P31: 52 | Q31: =+JAN!Q31+FEB!Q31+MAR!Q31 -> 663 | R31: =+JAN!R31+FEB!R31+MAR!R31 -> 1 | S31: =+JAN!S31+FEB!S31+MAR!S31 -> 599 | T31: =J31-P31 -> 5 | U31: =+L31+M31 -> 115 | V31: =$S31/$E31 -> 6.6555556 | W31: =$V31/$F31*100 -> 66.555556 | X31: =$S31/($L31+$M31) -> 5.2086957 | Y31: =(($F31-$V31)*$E31)/($L31+$M31) -> 2.6173913 | Z31: =($L31+$M31)/$F31 -> 11.5
C32: SAKURA | E32: =+JAN!E32+FEB!E32+MAR!E32 -> 90 | F32: =SUM(F28:F31) -> 17 | G32: =SUM(G28:G31) -> 3 | H32: =SUM(H28:H31) -> 174 | I32: =SUM(I28:I31) -> 33 | J32: 77 | K32: =SUM(K28:K31) -> 12 | L32: =SUM(L28:L31) -> 124 | M32: 24 | N32: =SUM(N28:N31) -> 31 | O32: =SUM(O28:O31) -> 37 | P32: 72 | Q32: =SUM(Q28:Q31) -> 854 | R32: =SUM(R28:R31) -> 1 | S32: =SUM(S28:S31) -> 753 | T32: =J32-P32 -> 5 | U32: =+L32+M32 -> 148 | V32: =$S32/$E32 -> 8.3666667 | W32: =$V32/$F32*100 -> 49.215686 | X32: =$S32/($L32+$M32) -> 5.0878378 | Y32: =(($F32-$V32)*$E32)/($L32+$M32) -> 5.25 | Z32: =($L32+$M32)/$F32 -> 8.7058824
A33: 2 | C33: CATALYA | D33: ISOLASI | E33: =+JAN!E33+FEB!E33+MAR!E33 -> 90 | F33: =MAR!F33 -> 6 | G33: ='[1]TT Per Ruang'!G38 -> 4 | H33: =+JAN!H33+FEB!H33+MAR!H33 -> 114 | I33: =+JAN!I33+FEB!I33+MAR!I33 -> 22 | J33: 61 | K33: =+JAN!K33+FEB!K33+MAR!K33 -> 29 | L33: =+JAN!L33+FEB!L33+MAR!L33 -> 101 | M33: 3 | N33: =+JAN!N33+FEB!N33+MAR!N33 -> 3 | O33: =+JAN!O33+FEB!O33+MAR!O33 -> 7 | P33: 53 | Q33: =+JAN!Q33+FEB!Q33+MAR!Q33 -> 316 | R33: =+JAN!R33+FEB!R33+MAR!R33 -> 0 | S33: =+JAN!S33+FEB!S33+MAR!S33 -> 458 | T33: =J33-P33 -> 8 | U33: =+L33+M33 -> 104 | V33: =$S33/$E33 -> 5.0888889 | W33: =$V33/$F33*100 -> 84.814815 | X33: =$S33/($L33+$M33) -> 4.4038462 | Y33: =(($F33-$V33)*$E33)/($L33+$M33) -> 0.78846154 | Z33: =($L33+$M33)/$F33 -> 17.333333
C34: CATALYA | E34: =+JAN!E34+FEB!E34+MAR!E34 -> 90 | F34: =SUM(F33) -> 6 | G34: =SUM(G33) -> 4 | H34: =SUM(H33) -> 114 | I34: =SUM(I33) -> 22 | J34: 61 | K34: =SUM(K33) -> 29 | L34: =SUM(L33) -> 101 | M34: 3 | N34: =SUM(N33) -> 3 | O34: =SUM(O33) -> 7 | P34: 53 | Q34: =SUM(Q33) -> 316 | R34: =SUM(R33) -> 0 | S34: =SUM(S33) -> 458 | T34: =J34-P34 -> 8 | U34: =+L34+M34 -> 104 | V34: =$S34/$E34 -> 5.0888889 | W34: =$V34/$F34*100 -> 84.814815 | X34: =$S34/($L34+$M34) -> 4.4038462 | Y34: =(($F34-$V34)*$E34)/($L34+$M34) -> 0.78846154 | Z34: =($L34+$M34)/$F34 -> 17.333333
A35: 3 | C35: LAVENDER | D35: III | E35: =+JAN!E35+FEB!E35+MAR!E35 -> 90 | F35: =MAR!F35 -> 4 | G35: ='[1]TT Per Ruang'!G54 -> 0 | H35: =+JAN!H35+FEB!H35+MAR!H35 -> 0 | I35: =+JAN!I35+FEB!I35+MAR!I35 -> 0 | J35: 0 | K35: =+JAN!K35+FEB!K35+MAR!K35 -> 0 | L35: =+JAN!L35+FEB!L35+MAR!L35 -> 0 | M35: 0 | N35: =+JAN!N35+FEB!N35+MAR!N35 -> 0 | O35: =+JAN!O35+FEB!O35+MAR!O35 -> 0 | P35: 0 | Q35: =+JAN!Q35+FEB!Q35+MAR!Q35 -> 0 | R35: =+JAN!R35+FEB!R35+MAR!R35 -> 0 | S35: =+JAN!S35+FEB!S35+MAR!S35 -> 0 | T35: =J35-P35 -> 0 | U35: =+L35+M35 -> 0 | V35: =$S35/$E35 -> 0 | W35: =$V35/$F35*100 -> 0 | X35: =$S35/($L35+$M35) -> #DIV/0! | Y35: =(($F35-$V35)*$E35)/($L35+$M35) -> #DIV/0! | Z35: =($L35+$M35)/$F35 -> 0
C36: LAVENDER | E36: =+JAN!E36+FEB!E36+MAR!E36 -> 90 | F36: =SUM(F35) -> 4 | G36: =SUM(G35) -> 0 | H36: =SUM(H35) -> 0 | I36: =SUM(I35) -> 0 | J36: 0 | K36: =SUM(K35) -> 0 | L36: =SUM(L35) -> 0 | M36: 0 | N36: =SUM(N35) -> 0 | O36: =SUM(O35) -> 0 | P36: 0 | Q36: =SUM(Q35) -> 0 | R36: =SUM(R35) -> 0 | S36: =SUM(S35) -> 0 | T36: =J36-P36 -> 0 | U36: =+L36+M36 -> 0 | V36: =$S36/$E36 -> 0 | W36: =$V36/$F36*100 -> 0 | X36: =$S36/($L36+$M36) -> #DIV/0! | Y36: =(($F36-$V36)*$E36)/($L36+$M36) -> #DIV/0! | Z36: =($L36+$M36)/$F36 -> 0
A37: 4 | C37: NUSA INDAH | D37: I | E37: =+JAN!E37+FEB!E37+MAR!E37 -> 90 | F37: =MAR!F37 -> 2 | G37: ='[1]TT Per Ruang'!G43 -> 0 | H37: =+JAN!H37+FEB!H37+MAR!H37 -> 0 | I37: =+JAN!I37+FEB!I37+MAR!I37 -> 0 | J37: 0 | K37: =+JAN!K37+FEB!K37+MAR!K37 -> 0 | L37: =+JAN!L37+FEB!L37+MAR!L37 -> 0 | M37: 0 | N37: =+JAN!N37+FEB!N37+MAR!N37 -> 0 | O37: =+JAN!O37+FEB!O37+MAR!O37 -> 0 | P37: 0 | Q37: =+JAN!Q37+FEB!Q37+MAR!Q37 -> 0 | R37: =+JAN!R37+FEB!R37+MAR!R37 -> 0 | S37: =+JAN!S37+FEB!S37+MAR!S37 -> 0 | T37: =J37-P37 -> 0 | U37: =+L37+M37 -> 0 | V37: =$S37/$E37 -> 0 | W37: =$V37/$F37*100 -> 0 | X37: =$S37/($L37+$M37) -> #DIV/0! | Y37: =(($F37-$V37)*$E37)/($L37+$M37) -> #DIV/0! | Z37: =($L37+$M37)/$F37 -> 0
C38: NUSA INDAH | E38: =+JAN!E38+FEB!E38+MAR!E38 -> 90 | F38: =SUM(F37) -> 2 | G38: =SUM(G37) -> 0 | H38: =SUM(H37) -> 0 | I38: =SUM(I37) -> 0 | J38: 0 | K38: =SUM(K37) -> 0 | L38: =SUM(L37) -> 0 | M38: 0 | N38: =SUM(N37) -> 0 | O38: =SUM(O37) -> 0 | P38: 0 | Q38: =SUM(Q37) -> 0 | R38: =SUM(R37) -> 0 | S38: =SUM(S37) -> 0 | T38: =J38-P38 -> 0 | U38: =+L38+M38 -> 0 | V38: =$S38/$E38 -> 0 | W38: =$V38/$F38*100 -> 0 | X38: =$S38/($L38+$M38) -> #DIV/0! | Y38: =(($F38-$V38)*$E38)/($L38+$M38) -> #DIV/0! | Z38: =($L38+$M38)/$F38 -> 0
A39: 5 | C39: MAWAR | D39: III | E39: =+JAN!E39+FEB!E39+MAR!E39 -> 90 | F39: =MAR!F39 -> 4 | G39: ='[1]TT Per Ruang'!G24 -> 0 | H39: =+JAN!H39+FEB!H39+MAR!H39 -> 0 | I39: =+JAN!I39+FEB!I39+MAR!I39 -> 0 | J39: 0 | K39: =+JAN!K39+FEB!K39+MAR!K39 -> 0 | L39: =+JAN!L39+FEB!L39+MAR!L39 -> 0 | M39: 0 | N39: =+JAN!N39+FEB!N39+MAR!N39 -> 0 | O39: =+JAN!O39+FEB!O39+MAR!O39 -> 0 | P39: 0 | Q39: =+JAN!Q39+FEB!Q39+MAR!Q39 -> 0 | R39: =+JAN!R39+FEB!R39+MAR!R39 -> 0 | S39: =+JAN!S39+FEB!S39+MAR!S39 -> 0 | T39: =J39-P39 -> 0 | U39: =+L39+M39 -> 0 | V39: =$S39/$E39 -> 0 | W39: =$V39/$F39*100 -> 0 | X39: =$S39/($L39+$M39) -> #DIV/0! | Y39: =(($F39-$V39)*$E39)/($L39+$M39) -> #DIV/0! | Z39: =($L39+$M39)/$F39 -> 0
C40: MAWAR | E40: =+JAN!E40+FEB!E40+MAR!E40 -> 90 | F40: =SUM(F39) -> 4 | G40: =SUM(G39) -> 0 | H40: =SUM(H39) -> 0 | I40: =SUM(I39) -> 0 | J40: 0 | K40: =SUM(K39) -> 0 | L40: =SUM(L39) -> 0 | M40: 0 | N40: =SUM(N39) -> 0 | O40: =SUM(O39) -> 0 | P40: 0 | Q40: =SUM(Q39) -> 0 | R40: =SUM(R39) -> 0 | S40: =SUM(S39) -> 0 | T40: =J40-P40 -> 0 | U40: =+L40+M40 -> 0 | V40: =$S40/$E40 -> 0 | W40: =$V40/$F40*100 -> 0 | X40: =$S40/($L40+$M40) -> #DIV/0! | Y40: =(($F40-$V40)*$E40)/($L40+$M40) -> #DIV/0! | Z40: =($L40+$M40)/$F40 -> 0
A41: 6 | C41: BOGENVILE | D41: I | E41: =+JAN!E41+FEB!E41+MAR!E41 -> 90 | F41: =MAR!F41 -> 1 | G41: ='[1]TT Per Ruang'!G29 -> 0 | H41: =+JAN!H41+FEB!H41+MAR!H41 -> 0 | I41: =+JAN!I41+FEB!I41+MAR!I41 -> 0 | J41: 0 | K41: =+JAN!K41+FEB!K41+MAR!K41 -> 0 | L41: =+JAN!L41+FEB!L41+MAR!L41 -> 0 | M41: 0 | N41: =+JAN!N41+FEB!N41+MAR!N41 -> 0 | O41: =+JAN!O41+FEB!O41+MAR!O41 -> 0 | P41: 0 | Q41: =+JAN!Q41+FEB!Q41+MAR!Q41 -> 0 | R41: =+JAN!R41+FEB!R41+MAR!R41 -> 0 | S41: =+JAN!S41+FEB!S41+MAR!S41 -> 0 | T41: =J41-P41 -> 0 | U41: =+L41+M41 -> 0 | V41: =$S41/$E41 -> 0 | W41: =$V41/$F41*100 -> 0 | X41: =$S41/($L41+$M41) -> #DIV/0! | Y41: =(($F41-$V41)*$E41)/($L41+$M41) -> #DIV/0! | Z41: =($L41+$M41)/$F41 -> 0
C42: BOGENVILE | E42: =+JAN!E42+FEB!E42+MAR!E42 -> 90 | F42: =SUM(F41) -> 1 | G42: =SUM(G41) -> 0 | H42: =SUM(H41) -> 0 | I42: =SUM(I41) -> 0 | J42: 0 | K42: =SUM(K41) -> 0 | L42: =SUM(L41) -> 0 | M42: 0 | N42: =SUM(N41) -> 0 | O42: =SUM(O41) -> 0 | P42: 0 | Q42: =SUM(Q41) -> 0 | R42: =SUM(R41) -> 0 | S42: =SUM(S41) -> 0 | T42: =J42-P42 -> 0 | U42: =+L42+M42 -> 0 | V42: =$S42/$E42 -> 0 | W42: =$V42/$F42*100 -> 0 | X42: =$S42/($L42+$M42) -> #DIV/0! | Y42: =(($F42-$V42)*$E42)/($L42+$M42) -> #DIV/0! | Z42: =($L42+$M42)/$F42 -> 0
A43: 7 | C43: MELATI ATAS | D43: III | E43: =+JAN!E43+FEB!E43+MAR!E43 -> 90 | F43: =MAR!F43 -> 4 | G43: ='[1]TT Per Ruang'!G18 -> 0 | H43: =+JAN!H43+FEB!H43+MAR!H43 -> 0 | I43: =+JAN!I43+FEB!I43+MAR!I43 -> 0 | J43: 0 | K43: =+JAN!K43+FEB!K43+MAR!K43 -> 0 | L43: =+JAN!L43+FEB!L43+MAR!L43 -> 0 | M43: 0 | N43: =+JAN!N43+FEB!N43+MAR!N43 -> 0 | O43: =+JAN!O43+FEB!O43+MAR!O43 -> 0 | P43: 0 | Q43: =+JAN!Q43+FEB!Q43+MAR!Q43 -> 0 | R43: =+JAN!R43+FEB!R43+MAR!R43 -> 0 | S43: =+JAN!S43+FEB!S43+MAR!S43 -> 0 | T43: =J43-P43 -> 0 | U43: =+L43+M43 -> 0 | V43: =$S43/$E43 -> 0 | W43: =$V43/$F43*100 -> 0 | X43: =$S43/($L43+$M43) -> #DIV/0! | Y43: =(($F43-$V43)*$E43)/($L43+$M43) -> #DIV/0! | Z43: =($L43+$M43)/$F43 -> 0
...

Sheet APR
A1: DATA PELAYANAN RI RSD Dr.SOEBANDI JEMBER
A2: BULAN : APRIL 2026
A3: NO | B3: PELAYANAN | C3: RAWAT INAP | D3: KLAS PERAWATAN | E3: PERIODE | F3: TT (T) | G3: PX AWAL | H3: PX MASUK | I3: PX PINDAHAN | J3: JUMLAH (1+2+3) | K3: PX DI PINDAHKAN | L3: PX KELUAR HIDUP | M3: PX MATI | N3: KURANG 48 JAM | O3: LEBIH 48 JAM | P3: JUMLAH (5+6+7) | Q3: LAMA DI RAWAT | R3: PX KELUAR/MASUK HR SAMA | S3: HARI PERAWATAN | T3: Px AKHIR | U3: KUNJUNGN | V3: O | W3: BOR (O/T) | X3: LOS | Y3: TOI | Z3: BTO
V4: (TT terpakai) | W4: (75%-85%) | X4: (3-12 hari) | Y4: (1-3 hr) | Z4: (30 px)
G6: 1 | H6: 2 | I6: 3 | J6: 4 | K6: 5 | L6: 6 | M6: 7 | N6: 8 | O6: 9 | P6: 10 | Q6: 11 | R6: 12 | S6: 13 | T6: 14 | V6: 15 | W6: 16 | X6: 17 | Y6: 18 | Z6: 19
A7: 1 | B7: INTENSIVE | C7: ICU | D7: I | E7: 30 | F7: 14 | G7: 10 | H7: 11 | I7: 111 | J7: 132 | K7: 103 | L7: 0 | M7: 18 | N7: 5 | O7: 13 | P7: 121 | Q7: 114 | R7: 0 | S7: 305 | T7: 11 | U7: 18 | V7: 10.166667 | W7: 72.619048 | X7: 16.944444 | Y7: 6.3888889 | Z7: 1.2857143
C8: ICU | D8: I | E8: 30 | F8: 14 | G8: 10 | H8: 11 | I8: 111 | J8: 132 | K8: 103 | L8: 0 | M8: 18 | N8: 5 | O8: 13 | P8: 121 | Q8: 114 | R8: 0 | S8: 305 | T8: 11 | U8: 18 | V8: 10.166667 | W8: 72.619048 | X8: 16.944444 | Y8: 6.3888889 | Z8: 1.2857143
A9: 2 | C9: ICCU | D9: I | E9: 30 | F9: 5 | G9: 5 | H9: 64 | I9: 8 | J9: 77 | K9: 65 | L9: 0 | M9: 9 | N9: 8 | O9: 1 | P9: 74 | Q9: 13 | R9: 3 | S9: 105 | T9: 3 | U9: 9 | V9: 3.5 | W9: 70 | X9: 11.666667 | Y9: 5 | Z9: 1.8
C10: ICCU | D10: I | E10: 30 | F10: 5 | G10: 5 | H10: 64 | I10: 8 | J10: 77 | K10: 65 | L10: 0 | M10: 9 | N10: 8 | O10: 1 | P10: 74 | Q10: 13 | R10: 3 | S10: 105 | T10: 3 | U10: 9 | V10: 3.5 | W10: 70 | X10: 11.666667 | Y10: 5 | Z10: 1.8
A11: 3 | C11: PICU | D11: I | E11: 30 | F11: 3 | G11: 3 | H11: 4 | I11: 18 | J11: 25 | K11: 20 | L11: 0 | M11: 4 | N11: 1 | O11: 3 | P11: 24 | Q11: 23 | R11: 0 | S11: 67 | T11: 1 | U11: 4 | V11: 2.2333333 | W11: 74.444444 | X11: 16.75 | Y11: 5.75 | Z11: 1.3333333
C12: PICU | D12: I | E12: 30 | F12: 3 | G12: 3 | H12: 4 | I12: 18 | J12: 25 | K12: 20 | L12: 0 | M12: 4 | N12: 1 | O12: 3 | P12: 24 | Q12: 23 | R12: 0 | S12: 67 | T12: 1 | U12: 4 | V12: 2.2333333 | W12: 74.444444 | X12: 16.75 | Y12: 5.75 | Z12: 1.3333333
A13: 4 | C13: NICU | D13: I | E13: 30 | F13: 5 | G13: 5 | H13: 17 | I13: 18 | J13: 40 | K13: 21 | L13: 0 | M13: 15 | N13: 7 | O13: 8 | P13: 36 | Q13: 93 | R13: 4 | S13: 126 | T13: 4 | U13: 15 | V13: 4.2 | W13: 84 | X13: 8.4 | Y13: 1.6 | Z13: 3
C14: NICU | D14: I | E14: 30 | F14: 5 | G14: 5 | H14: 17 | I14: 18 | J14: 40 | K14: 21 | L14: 0 | M14: 15 | N14: 7 | O14: 8 | P14: 36 | Q14: 93 | R14: 4 | S14: 126 | T14: 4 | U14: 15 | V14: 4.2 | W14: 84 | X14: 8.4 | Y14: 1.6 | Z14: 3
A15: 5 | C15: ICU MEDICAL | D15: I | E15: 30 | F15: 4 | G15: 1 | H15: 21 | I15: 9 | J15: 31 | K15: 20 | L15: 0 | M15: 8 | N15: 5 | O15: 3 | P15: 28 | Q15: 39 | R15: 3 | S15: 71 | T15: 3 | U15: 8 | V15: 2.3666667 | W15: 59.166667 | X15: 8.875 | Y15: 6.125 | Z15: 2
C16: ICU MEDICAL | D16: I | E16: 30 | F16: 4 | G16: 1 | H16: 21 | I16: 9 | J16: 31 | K16: 20 | L16: 0 | M16: 8 | N16: 5 | O16: 3 | P16: 28 | Q16: 39 | R16: 3 | S16: 71 | T16: 3 | U16: 8 | V16: 2.3666667 | W16: 59.166667 | X16: 8.875 | Y16: 6.125 | Z16: 2
A17: 6 | C17: RICU ED | D17: I | E17: 30 | F17: 2 | G17: 1 | H17: 10 | I17: 4 | J17: 15 | K17: 8 | L17: 0 | M17: 6 | N17: 2 | O17: 4 | P17: 14 | Q17: 20 | R17: 0 | S17: 36 | T17: 1 | U17: 6 | V17: 1.2 | W17: 60 | X17: 6 | Y17: 4 | Z17: 3
C18: RICU ED | E18: 30 | F18: 2 | G18: 1 | H18: 10 | I18: 4 | J18: 15 | K18: 8 | L18: 0 | M18: 6 | N18: 2 | O18: 4 | P18: 14 | Q18: 20 | R18: 0 | S18: 36 | T18: 1 | U18: 6 | V18: 1.2 | W18: 60 | X18: 6 | Y18: 4 | Z18: 3
A19: 7 | C19: HCU MELATI BAWAH | D19: II | E19: 30 | F19: 15 | G19: 14 | H19: 97 | I19: 26 | J19: 137 | K19: 21 | L19: 86 | M19: 16 | N19: 10 | O19: 6 | P19: 123 | Q19: 624 | R19: 1 | S19: 419 | T19: 14 | U19: 102 | V19: 13.966667 | W19: 93.111111 | X19: 4.1078431 | Y19: 0.30392157 | Z19: 6.8
C20: HCU MELATI BAWAH | D20: II | E20: 30 | F20: 15 | G20: 14 | H20: 97 | I20: 26 | J20: 137 | K20: 21 | L20: 86 | M20: 16 | N20: 10 | O20: 6 | P20: 123 | Q20: 624 | R20: 1 | S20: 419 | T20: 14 | U20: 102 | V20: 13.966667 | W20: 93.111111 | X20: 4.1078431 | Y20: 0.30392157 | Z20: 6.8
A21: TOTAL INTENSIVE | E21: 30 | F21: 48 | G21: 39 | H21: 224 | I21: 194 | J21: 457 | K21: 258 | L21: 86 | M21: 76 | N21: 38 | O21: 38 | P21: 420 | Q21: 926 | R21: 11 | S21: 1129 | T21: 37 | U21: 162 | V21: 37.633333 | W21: 78.402778 | X21: 6.9691358 | Y21: 1.9197531 | Z21: 3.375
A24: NO | B24: PELAYANAN | C24: RAWAT INAP | D24: KLAS PERAWATAN | E24: PERIODE | F24: TT (T) | G24: PX AWAL | H24: PX MASUK | I24: PX PINDAHAN | J24: JUMLAH (1+2+3) | K24: PX DI PINDAHKAN | L24: PX KELUAR HIDUP | M24: PX MATI | N24: KURANG 48 JAM | O24: LEBIH 48 JAM | P24: JUMLAH (5+6+7) | Q24: LAMA DI RAWAT | R24: PX KELUAR/MASUK HR SAMA | S24: HARI PERAWATAN | T24: Px AKHIR | U24: KUNJUNGN | V24: O | W24: BOR (O/T) | X24: LOS | Y24: TOI | Z24: BTO
V25: (TT terpakai) | W25: (75%-85%) | X25: (3-12 hari) | Y25: (1-3 hr) | Z25: (30 px)
G27: 1 | H27: 2 | I27: 3 | J27: 4 | K27: 5 | L27: 6 | M27: 7 | N27: 8 | O27: 9 | P27: 10 | Q27: 11 | R27: 12 | S27: 13 | T27: 14 | V27: 15 | W27: 16 | X27: 17 | Y27: 18 | Z27: 19
A28: 1 | B28: ISOLASI | C28: SAKURA | D28: TB MDR II | E28: 30 | F28: 2 | G28: 1 | H28: 0 | I28: 1 | J28: 2 | K28: 0 | L28: 2 | M28: 0 | N28: 0 | O28: 0 | P28: 2 | Q28: 9 | R28: 0 | S28: 1 | T28: 0 | U28: 2 | V28: 0.033333333 | W28: 1.6666667 | X28: 0.5 | Y28: 29.5 | Z28: 1
C29: SAKURA | D29: TB MDR III | E29: 30 | F29: 3 | G29: 0 | H29: 13 | I29: 1 | J29: 14 | K29: 2 | L29: 6 | M29: 5 | N29: 3 | O29: 2 | P29: 13 | Q29: 34 | R29: 0 | S29: 35 | T29: 1 | U29: 11 | V29: 1.1666667 | W29: 38.888889 | X29: 3.1818182 | Y29: 5 | Z29: 3.6666667
C30: SAKURA | D30: TB PARU II | E30: 30 | F30: 2 | G30: 0 | H30: 5 | I30: 1 | J30: 6 | K30: 1 | L30: 1 | M30: 3 | N30: 1 | O30: 2 | P30: 5 | Q30: 18 | R30: 0 | S30: 19 | T30: 1 | U30: 4 | V30: 0.63333333 | W30: 31.666667 | X30: 4.75 | Y30: 10.25 | Z30: 2
C31: SAKURA | D31: TB PARU III | E31: 30 | F31: 10 | G31: 5 | H31: 56 | I31: 7 | J31: 68 | K31: 6 | L31: 45 | M31: 8 | N31: 3 | O31: 5 | P31: 59 | Q31: 249 | R31: 2 | S31: 250 | T31: 9 | U31: 53 | V31: 8.3333333 | W31: 83.333333 | X31: 4.7169811 | Y31: 0.94339623 | Z31: 5.3
C32: SAKURA | E32: 30 | F32: 17 | G32: 6 | H32: 74 | I32: 10 | J32: 90 | K32: 9 | L32: 54 | M32: 16 | N32: 7 | O32: 9 | P32: 79 | Q32: 310 | R32: 2 | S32: 305 | T32: 11 | U32: 70 | V32: 10.166667 | W32: 59.803922 | X32: 4.3571429 | Y32: 2.9285714 | Z32: 4.1176471
A33: 2 | C33: CATALYA | D33: ISOLASI | E33: 30 | F33: 6 | G33: 0 | H33: 0 | I33: 0 | J33: 0 | K33: 0 | L33: 0 | M33: 0 | N33: 0 | O33: 0 | P33: 0 | Q33: 0 | R33: 0 | S33: 0 | T33: 0 | U33: 0 | V33: 0 | W33: 0 | X33: #DIV/0! | Y33: #DIV/0! | Z33: 0
C34: CATALYA | E34: 30 | F34: 6 | G34: 0 | H34: 0 | I34: 0 | J34: 0 | K34: 0 | L34: 0 | M34: 0 | N34: 0 | O34: 0 | P34: 0 | Q34: 0 | R34: 0 | S34: 0 | T34: 0 | U34: 0 | V34: 0 | W34: 0 | X34: #DIV/0! | Y34: #DIV/0! | Z34: 0
A35: 3 | C35: LAVENDER | D35: III | E35: 30 | F35: 4 | G35: 0 | H35: 0 | I35: 0 | J35: 0 | K35: 0 | L35: 0 | M35: 0 | N35: 0 | O35: 0 | P35: 0 | Q35: 0 | R35: 0 | S35: 0 | T35: 0 | U35: 0 | V35: 0 | W35: 0 | X35: #DIV/0! | Y35: #DIV/0! | Z35: 0
C36: LAVENDER | E36: 30 | F36: 4 | G36: 0 | H36: 0 | I36: 0 | J36: 0 | K36: 0 | L36: 0 | M36: 0 | N36: 0 | O36: 0 | P36: 0 | Q36: 0 | R36: 0 | S36: 0 | T36: 0 | U36: 0 | V36: 0 | W36: 0 | X36: #DIV/0! | Y36: #DIV/0! | Z36: 0
A37: 4 | C37: NUSA INDAH | D37: I | E37: 30 | F37: 2 | G37: 0 | H37: 0 | I37: 0 | J37: 0 | K37: 0 | L37: 0 | M37: 0 | N37: 0 | O37: 0 | P37: 0 | Q37: 0 | R37: 0 | S37: 0 | T37: 0 | U37: 0 | V37: 0 | W37: 0 | X37: #DIV/0! | Y37: #DIV/0! | Z37: 0
C38: NUSA INDAH | E38: 30 | F38: 2 | G38: 0 | H38: 0 | I38: 0 | J38: 0 | K38: 0 | L38: 0 | M38: 0 | N38: 0 | O38: 0 | P38: 0 | Q38: 0 | R38: 0 | S38: 0 | T38: 0 | U38: 0 | V38: 0 | W38: 0 | X38: #DIV/0! | Y38: #DIV/0! | Z38: 0
A39: 5 | C39: MAWAR | D39: III | E39: 30 | F39: 4 | G39: 0 | H39: 0 | I39: 0 | J39: 0 | K39: 0 | L39: 0 | M39: 0 | N39: 0 | O39: 0 | P39: 0 | Q39: 0 | R39: 0 | S39: 0 | T39: 0 | U39: 0 | V39: 0 | W39: 0 | X39: #DIV/0! | Y39: #DIV/0! | Z39: 0
C40: MAWAR | E40: 30 | F40: 4 | G40: 0 | H40: 0 | I40: 0 | J40: 0 | K40: 0 | L40: 0 | M40: 0 | N40: 0 | O40: 0 | P40: 0 | Q40: 0 | R40: 0 | S40: 0 | T40: 0 | U40: 0 | V40: 0 | W40: 0 | X40: #DIV/0! | Y40: #DIV/0! | Z40: 0
A41: 6 | C41: BOGENVILE | D41: I | E41: 30 | F41: 1 | G41: 0 | H41: 0 | I41: 0 | J41: 0 | K41: 0 | L41: 0 | M41: 0 | N41: 0 | O41: 0 | P41: 0 | Q41: 0 | R41: 0 | S41: 0 | T41: 0 | U41: 0 | V41: 0 | W41: 0 | X41: #DIV/0! | Y41: #DIV/0! | Z41: 0
C42: BOGENVILE | E42: 30 | F42: 1 | G42: 0 | H42: 0 | I42: 0 | J42: 0 | K42: 0 | L42: 0 | M42: 0 | N42: 0 | O42: 0 | P42: 0 | Q42: 0 | R42: 0 | S42: 0 | T42: 0 | U42: 0 | V42: 0 | W42: 0 | X42: #DIV/0! | Y42: #DIV/0! | Z42: 0
A43: 7 | C43: MELATI ATAS | D43: III | E43: 30 | F43: 4 | G43: 0 | H43: 0 | I43: 0 | J43: 0 | K43: 0 | L43: 0 | M43: 0 | N43: 0 | O43: 0 | P43: 0 | Q43: 0 | R43: 0 | S43: 0 | T43: 0 | U43: 0 | V43: 0 | W43: 0 | X43: #DIV/0! | Y43: #DIV/0! | Z43: 0
